Workbook

Sheet Production Summary
A1: Metric | B1: Value
A2: Artifact Type | B2: BEST_FINAL_AFTER_BREAKS_SCHEDULE
A3: Selection Basis | B3: Recommended operational Pareto schedule; maximum primary-target loss is 1 only when floor attainment, severity, concentration, or deficit depth materially improves
A4: Run ID | B4: 89879546ecb920f2d4754765
A5: Input SHA256 | B5: fdadbb6445c619958cb41fe069e50a62064ddd74bc04be1cdc944d5703525296
A6: Contract SHA256 | B6: c41dc93bbd6cdb57003cbb31e0f6bca588040be2d2082a4fcc89d7d662f21936
A7: Engine SHA256 | B7: db7c99c29f2cc3f0d4f8026a6330e3570b975a0efb40c17bdafac29fa8952ea4
A8: Engine Version | B8: L6.3.2.3-R1.2.0-B-ENGINE-MATURITY-RC4.4.8-PHASE-B-CLOSURE-RC1
A9: Final Status | B9: PASS_WITH_COVERAGE_TRADEOFF
A10: Input Workbook | B10: /content/wfm_queue/JOB-20260730-0024-0A5928/UNIVERSAL_WFM_PRODUCTION_INPUT_TEMPLATE_L6_3_2_3_R1 - NMG.xlsx
A11: Requirement Sheet | B11: FT Wise 30 Min
A12: Shrinkage Sheet | B12: Shrinkage 30 Min
A13: Canonical Coverage Truth | B13: Requirement and shrinkage sources are interval-aware; seed and final candidates are recomputed under the current workbook contract
A14: Interval Minutes | B14: 30
A15: Roster Count | B15: 17
A16: Legal Shift Count | B16: 10
A17: Target Ratio | B17: 0.9
A18: Floor Ratio | B18: 0.8
A19: Floor Mode | B19: protected
A20: Hard Floor Ratio | B20: Not hard
A21: Hard Floor Tolerance
A22: Hard Floor Source | B22: Protected floor only
A23: Break Absolute Minimum Gap Minutes | B23: 0
A24: Break Preferred Gap Minutes | B24: 0
A25: Break Normal Maximum Gap Minutes | B25: 150
A26: Flexible Break Compression Count | B26: 0
A27: Break Gaps Beyond Normal Maximum | B27: 0
A28: Allowed Shift Start Window | B28: Unrestricted
A29: Shift Start Step Minutes | B29: 1
A30: Blank Requirement Mode | B30: allow
A31: Blank Requirement Rule
A32: Demand Fit Guard Mode | B32: yes
A33: Demand Fit Guard Effective | B33: TRUE
A34: Before Target Hits | B34: 174
A35: After Target Hits | B35: 172
A36: Before Floor Hits | B36: 182
A37: After Floor Hits | B37: 179
A38: Before Hard Floor Hits | B38: 0
A39: After Hard Floor Hits | B39: 0
A40: Directional Skill Parsing | B40: Source language capabilities are inverted to determine eligible source associates for each required language/group
...

Sheet RC7 Contract Audit
A1: RC7 Contract Audit
A2: Field | B2: Expected | C2: Parsed | D2: Status
A3: roster_count | B3: 17 | C3: 17 | D3: PASS
A4: instructed_headcount | B4: 17 | C4: 17 | D4: PASS
A5: program_name | B5: NMG SPEN | C5: NMG SPEN | D5: PASS
A6: interval_minutes | B6: 30 | C6: 30 | D6: PASS
A7: requirement_sheet | B7: FT Wise 30 Min | C7: FT Wise 30 Min | D7: PASS
A8: shrinkage_sheet | B8: Shrinkage 30 Min | C8: Shrinkage 30 Min | D8: PASS
A9: target_ratio | B9: 0.9 | C9: 0.9 | D9: PASS
A10: floor_ratio | B10: 0.8 | C10: 0.8 | D10: PASS
A11: floor_mode | B11: protected | C11: protected | D11: PASS
A12: target_priority_confirmed | B12: True | C12: True | D12: PASS
A13: allow_no_break_exceptions | B13: False | C13: False | D13: PASS
... A27: Parser warnings | B27: 0 | C27: 0 | D27: PASS
A28: Input SHA-256 before audit sheet | B28: 4b1a1eefb7b6a508d0ceac271c4f916c510608d700147f84d5eee12e0b3e5b4c | D28: INFO

Sheet Schedule
A1: Schedule — Roster Input
A2: Enter each associate once. Leave Sun–Sat blank; the engine writes the final schedule into these columns.
A3: Slot | B3: Emp ID | C3: Email | D3: SF Name | E3: TL | F3: Language | G3: Sun | H3: Mon | I3: Tue | J3: Wed | K3: Thu | L3: Fri | M3: Sat | N3: Roster Notes
A4: 1 | B4: 504298 | C4: Adam Assal | D4: Fady Assal | E4: Amany Zaher | F4: English | G4: OFF | H4: 17:00 - 02:00 | I4: 23:00 - 08:00 | J4: 23:00 - 08:00 | K4: 23:00 - 08:00 | L4: 21:00 - 06:00 | M4: OFF
A5: 2 | B5: 580363 | C5: Dean Osama | D5: Mohamed Osama | E5: Amany Zaher | F5: English | G5: 19:00 - 04:00 | H5: OFF | I5: OFF | J5: 18:00 - 03:00 | K5: 18:00 - 03:00 | L5: 19:00 - 04:00 | M5: 20:00 - 05:00
A6: 3 | B6: 735647 | C6: Saja Nour | D6: Saja Nour | E6: Amany Zaher | F6: English | G6: 20:00 - 05:00 | H6: 20:00 - 05:00 | I6: OFF | J6: OFF | K6: 15:00 - 00:00 | L6: 17:00 - 02:00 | M6: 17:00 - 02:00
A7: 4 | B7: 559396 | C7: Mayar Ehab | D7: Mayar Aboali | E7: Amany Zaher | F7: English | G7: 22:00 - 07:00 | H7: 23:00 - 08:00 | I7: OFF | J7: OFF | K7: 19:00 - 04:00 | L7: 19:00 - 04:00 | M7: 23:00 - 08:00
A8: 5 | B8: 744403 | C8: Mo bahnasy | D8: Mohamed Bahnasy | E8: Amany Zaher | F8: English | G8: 16:00 - 01:00 | H8: 14:00 - 23:00 | I8: 14:00 - 23:00 | J8: OFF | K8: OFF | L8: 18:00 - 03:00 | M8: 16:00 - 01:00
A9: 6 | B9: 735434 | C9: Jessie Mohamed | D9: Khloud Mohamed | E9: Amany Zaher | F9: English | G9: OFF | H9: OFF | I9: 18:00 - 03:00 | J9: 17:00 - 02:00 | K9: 17:00 - 02:00 | L9: 14:00 - 23:00 | M9: 14:00 - 23:00
A10: 7 | B10: 736009 | C10: Ava Ragab | D10: Azza Adel | E10: Amany Zaher | F10: English | G10: OFF | H10: OFF | I10: 19:00 - 04:00 | J10: 16:00 - 01:00 | K10: 17:00 - 02:00 | L10: 17:00 - 02:00 | M10: 17:00 - 02:00
A11: 8 | B11: 735592 | C11: Mia Ramdan | D11: Omnia Ewies | E11: Amany Zaher | F11: English | G11: 16:00 - 01:00 | H11: 20:00 - 05:00 | I11: 23:00 - 08:00 | J11: OFF | K11: OFF | L11: 16:00 - 01:00 | M11: 16:00 - 01:00
A12: 9 | B12: 661404 | C12: Noura Saber | D12: Noura Saber | E12: Amany Zaher | F12: English | G12: 17:00 - 02:00 | H12: 20:00 - 05:00 | I12: OFF | J12: OFF | K12: 17:00 - 02:00 | L12: 20:00 - 05:00 | M12: 20:00 - 05:00
A13: 10 | B13: 735360 | C13: Sam Sobhy | D13: Sameh Sabry | E13: Amany Zaher | F13: English | G13: 18:00 - 03:00 | H13: 18:00 - 03:00 | I13: OFF | J13: OFF | K13: 18:00 - 03:00 | L13: 22:00 - 07:00 | M13: 19:00 - 04:00
A14: 11 | B14: 744400 | C14: Ares Mahmoud | D14: Zeyad Eledeissy | E14: Amany Zaher | F14: English | G14: OFF | H14: OFF | I14: 19:00 - 04:00 | J14: 16:00 - 01:00 | K14: 14:00 - 23:00 | L14: 16:00 - 01:00 | M14: 16:00 - 01:00
A15: 12 | B15: 574476 | C15: Octvia Shahd | D15: Shahd Bakry | E15: Amany Zaher | F15: English | G15: 21:00 - 06:00 | H15: OFF | I15: OFF | J15: 14:00 - 23:00 | K15: 23:00 - 08:00 | L15: 23:00 - 08:00 | M15: 23:00 - 08:00
... A20: 17 | B20: 744394 | C20: Asmaa Ayman | D20: Asmaa Eldokhmesy | E20: Amany Zaher | F20: Spanish | G20: 17:00 - 02:00 | H20: 22:00 - 07:00 | I20: OFF | J20: OFF | K20: 14:00 - 23:00 | L20: 14:00 - 23:00 | M20: 17:00 - 02:00
A21: 18
A22: 19
A23: 20
A24: 21
A25: 22
A26: 23
A27: 24
A28: 25
A29: 26
A30: 27
A31: 28
A32: 29
... A203: 200

Sheet Break Schedule
A1: Associate | B1: Day | C1: Shift | D1: Break Type | E1: Start | F1: Duration Minutes | G1: Status
A2: Fady Assal | B2: Mon | C2: 17:00 - 02:00 | D2: Break 1 | E2: 21:15 | F2: 15 | G2: Scheduled
A3: Fady Assal | B3: Mon | C3: 17:00 - 02:00 | D3: Lunch | E3: 21:30 | F3: 30 | G3: Scheduled
A4: Fady Assal | B4: Mon | C4: 17:00 - 02:00 | D4: Break 2 | E4: 22:00 | F4: 15 | G4: Scheduled
A5: Fady Assal | B5: Tue | C5: 23:00 - 08:00 | D5: Break 1 | E5: 04:45 | F5: 15 | G5: Scheduled
A6: Fady Assal | B6: Tue | C6: 23:00 - 08:00 | D6: Lunch | E6: 05:15 | F6: 30 | G6: Scheduled
A7: Fady Assal | B7: Tue | C7: 23:00 - 08:00 | D7: Break 2 | E7: 05:45 | F7: 15 | G7: Scheduled
A8: Fady Assal | B8: Wed | C8: 23:00 - 08:00 | D8: Break 1 | E8: 04:45 | F8: 15 | G8: Scheduled
A9: Fady Assal | B9: Wed | C9: 23:00 - 08:00 | D9: Lunch | E9: 05:15 | F9: 30 | G9: Scheduled
A10: Fady Assal | B10: Wed | C10: 23:00 - 08:00 | D10: Break 2 | E10: 05:45 | F10: 15 | G10: Scheduled
A11: Fady Assal | B11: Thu | C11: 23:00 - 08:00 | D11: Break 1 | E11: 01:30 | F11: 15 | G11: Scheduled
A12: Fady Assal | B12: Thu | C12: 23:00 - 08:00 | D12: Lunch | E12: 02:00 | F12: 30 | G12: Scheduled
A13: Fady Assal | B13: Thu | C13: 23:00 - 08:00 | D13: Break 2 | E13: 02:30 | F13: 15 | G13: Scheduled
... A256: Asmaa Eldokhmesy | B256: Sat | C256: 17:00 - 02:00 | D256: Break 2 | E256: 22:00 | F256: 15 | G256: Scheduled

Sheet Break Spacing Audit
A1: Associate | B1: Day | C1: Shift | D1: From Segment | E1: To Segment | F1: Actual Gap Minutes | G1: Preferred Gap Minutes | H1: Absolute Minimum Minutes | I1: Normal Maximum Minutes | J1: Deviation Minutes | K1: Classification | L1: Approval Required
A2: Fady Assal | B2: Mon | C2: 17:00 - 02:00 | D2: Break 1 | E2: Lunch | F2: 0 | G2: 0 | H2: 0 | I2: 150 | J2: 0 | K2: PREFERRED | L2: NO
A3: Fady Assal | B3: Mon | C3: 17:00 - 02:00 | D3: Lunch | E3: Break 2 | F3: 0 | G3: 0 | H3: 0 | I3: 150 | J3: 0 | K3: PREFERRED | L3: NO
A4: Fady Assal | B4: Tue | C4: 23:00 - 08:00 | D4: Break 1 | E4: Lunch | F4: 15 | G4: 0 | H4: 0 | I4: 150 | J4: 15 | K4: FLEXIBLE_EXTENSION | L4: NO
A5: Fady Assal | B5: Tue | C5: 23:00 - 08:00 | D5: Lunch | E5: Break 2 | F5: 0 | G5: 0 | H5: 0 | I5: 150 | J5: 0 | K5: PREFERRED | L5: NO
A6: Fady Assal | B6: Wed | C6: 23:00 - 08:00 | D6: Break 1 | E6: Lunch | F6: 15 | G6: 0 | H6: 0 | I6: 150 | J6: 15 | K6: FLEXIBLE_EXTENSION | L6: NO
A7: Fady Assal | B7: Wed | C7: 23:00 - 08:00 | D7: Lunch | E7: Break 2 | F7: 0 | G7: 0 | H7: 0 | I7: 150 | J7: 0 | K7: PREFERRED | L7: NO
A8: Fady Assal | B8: Thu | C8: 23:00 - 08:00 | D8: Break 1 | E8: Lunch | F8: 15 | G8: 0 | H8: 0 | I8: 150 | J8: 15 | K8: FLEXIBLE_EXTENSION | L8: NO
A9: Fady Assal | B9: Thu | C9: 23:00 - 08:00 | D9: Lunch | E9: Break 2 | F9: 0 | G9: 0 | H9: 0 | I9: 150 | J9: 0 | K9: PREFERRED | L9: NO
A10: Fady Assal | B10: Fri | C10: 21:00 - 06:00 | D10: Break 1 | E10: Lunch | F10: 0 | G10: 0 | H10: 0 | I10: 150 | J10: 0 | K10: PREFERRED | L10: NO
A11: Fady Assal | B11: Fri | C11: 21:00 - 06:00 | D11: Lunch | E11: Break 2 | F11: 30 | G11: 0 | H11: 0 | I11: 150 | J11: 30 | K11: FLEXIBLE_EXTENSION | L11: NO
A12: Mohamed Osama | B12: Sun | C12: 19:00 - 04:00 | D12: Break 1 | E12: Lunch | F12: 15 | G12: 0 | H12: 0 | I12: 150 | J12: 15 | K12: FLEXIBLE_EXTENSION | L12: NO
A13: Mohamed Osama | B13: Sun | C13: 19:00 - 04:00 | D13: Lunch | E13: Break 2 | F13: 0 | G13: 0 | H13: 0 | I13: 150 | J13: 0 | K13: PREFERRED | L13: NO
... A171: Asmaa Eldokhmesy | B171: Sat | C171: 17:00 - 02:00 | D171: Lunch | E171: Break 2 | F171: 0 | G171: 0 | H171: 0 | I171: 150 | J171: 0 | K171: PREFERRED | L171: NO

Sheet FT Wise After Breaks
A1: Day | B1: Interval | C1: Required FTE | D1: Staffed Effective FTE | E1: Coverage %
A2: Sun | B2: 00:00 | C2: 7.9 | D2: 7.875 | E2: 0.996835
A3: Sun | B3: 00:30 | C3: 7.6 | D3: 7.875 | E3: 1.036184
A4: Sun | B4: 01:00 | C4: 7.3 | D4: 7 | E4: 0.958904
A5: Sun | B5: 01:30 | C5: 6.4 | D5: 7 | E5: 1.09375
A6: Sun | B6: 02:00 | C6: 3.9 | D6: 3.428571 | E6: 0.879121
A7: Sun | B7: 02:30 | C7: 3.5 | D7: 3.428571 | E7: 0.979592
A8: Sun | B8: 03:00 | C8: 2.7 | D8: 2.25 | E8: 0.833333
A9: Sun | B9: 03:30 | C9: 2.3 | D9: 2.25 | E9: 0.978261
A10: Sun | B10: 04:00 | C10: 1.9 | D10: 1.5 | E10: 0.789474
A11: Sun | B11: 04:30 | C11: 1.6 | D11: 1.5 | E11: 0.9375
A12: Sun | B12: 05:00 | C12: 1.4 | D12: 1 | E12: 0.714286
A13: Sun | B13: 05:30 | C13: 1.2 | D13: 1 | E13: 0.833333
... A253: Sat | B253: 23:30 | C253: 8.2 | D253: 8.75 | E253: 1.067073

Sheet Coverage Before Breaks
A1: Day | B1: Interval | C1: Required FTE | D1: Staffed Effective FTE | E1: Coverage %
A2: Sun | B2: 00:00 | C2: 7.9 | D2: 7.875 | E2: 0.996835
A3: Sun | B3: 00:30 | C3: 7.6 | D3: 7.875 | E3: 1.036184
A4: Sun | B4: 01:00 | C4: 7.3 | D4: 7 | E4: 0.958904
A5: Sun | B5: 01:30 | C5: 6.4 | D5: 7 | E5: 1.09375
A6: Sun | B6: 02:00 | C6: 3.9 | D6: 3.428571 | E6: 0.879121
A7: Sun | B7: 02:30 | C7: 3.5 | D7: 3.428571 | E7: 0.979592
A8: Sun | B8: 03:00 | C8: 2.7 | D8: 2.25 | E8: 0.833333
A9: Sun | B9: 03:30 | C9: 2.3 | D9: 2.25 | E9: 0.978261
A10: Sun | B10: 04:00 | C10: 1.9 | D10: 1.5 | E10: 0.789474
A11: Sun | B11: 04:30 | C11: 1.6 | D11: 1.5 | E11: 0.9375
A12: Sun | B12: 05:00 | C12: 1.4 | D12: 1 | E12: 0.714286
A13: Sun | B13: 05:30 | C13: 1.2 | D13: 1 | E13: 0.833333
... A253: Sat | B253: 23:30 | C253: 8.2 | D253: 10.5 | E253: 1.280488

Sheet Interval Coverage Audit
A1: Day | B1: Interval | C1: Required FTE | D1: Before Effective FTE | E1: Before % | F1: After Effective FTE | G1: After % | H1: Before Raw Minimum | I1: After Raw Minimum | J1: Floor Status
A2: Sun | B2: 00:00 | C2: 7.9 | D2: 7.875 | E2: 0.996835 | F2: 7.875 | G2: 0.996835 | H2: 9 | I2: 9 | J2: PASS
A3: Sun | B3: 00:30 | C3: 7.6 | D3: 7.875 | E3: 1.036184 | F3: 7.875 | G3: 1.036184 | H3: 9 | I3: 9 | J3: PASS
A4: Sun | B4: 01:00 | C4: 7.3 | D4: 7 | E4: 0.958904 | F4: 7 | G4: 0.958904 | H4: 8 | I4: 8 | J4: PASS
A5: Sun | B5: 01:30 | C5: 6.4 | D5: 7 | E5: 1.09375 | F5: 7 | G5: 1.09375 | H5: 8 | I5: 8 | J5: PASS
A6: Sun | B6: 02:00 | C6: 3.9 | D6: 3.428571 | E6: 0.879121 | F6: 3.428571 | G6: 0.879121 | H6: 4 | I6: 4 | J6: PASS
A7: Sun | B7: 02:30 | C7: 3.5 | D7: 3.428571 | E7: 0.979592 | F7: 3.428571 | G7: 0.979592 | H7: 4 | I7: 4 | J7: PASS
A8: Sun | B8: 03:00 | C8: 2.7 | D8: 2.25 | E8: 0.833333 | F8: 2.25 | G8: 0.833333 | H8: 3 | I8: 3 | J8: PASS
A9: Sun | B9: 03:30 | C9: 2.3 | D9: 2.25 | E9: 0.978261 | F9: 2.25 | G9: 0.978261 | H9: 3 | I9: 3 | J9: PASS
A10: Sun | B10: 04:00 | C10: 1.9 | D10: 1.5 | E10: 0.789474 | F10: 1.5 | G10: 0.789474 | H10: 3 | I10: 3 | J10: BELOW FLOOR
A11: Sun | B11: 04:30 | C11: 1.6 | D11: 1.5 | E11: 0.9375 | F11: 1.5 | G11: 0.9375 | H11: 3 | I11: 3 | J11: PASS
A12: Sun | B12: 05:00 | C12: 1.4 | D12: 1 | E12: 0.714286 | F12: 1 | G12: 0.714286 | H12: 1 | I12: 1 | J12: BELOW FLOOR
A13: Sun | B13: 05:30 | C13: 1.2 | D13: 1 | E13: 0.833333 | F13: 1 | G13: 0.833333 | H13: 1 | I13: 1 | J13: PASS
... A253: Sat | B253: 23:30 | C253: 8.2 | D253: 10.5 | E253: 1.280488 | F253: 8.75 | G253: 1.067073 | H253: 12 | I253: 10 | J253: PASS

Sheet Overage Audit
A1: Day | B1: Interval | C1: Required | D1: Shrinkage | E1: Minimum Raw For Target | F1: Before Effective | G1: Before % | H1: Before Target Overage | I1: Before Avoidable Overage | J1: After Effective | K1: After % | L1: After Target Overage | M1: After Avoidable Overage | N1: Soft Overage | O1: Severe Overage | P1: Extreme Overage | Q1: Operational Classification
A2: Sun | B2: 00:00 | C2: 7.9 | D2: 0.125 | E2: 9 | F2: 7.875 | G2: 0.996835 | H2: 0.765 | I2: 0 | J2: 7.875 | K2: 0.996835 | L2: 0.765 | M2: 0 | N2: FALSE | O2: FALSE | P2: FALSE | Q2: UNAVOIDABLE INTEGER ROUNDING
A3: Sun | B3: 00:30 | C3: 7.6 | D3: 0.125 | E3: 8 | F3: 7.875 | G3: 1.036184 | H3: 1.035 | I3: 0.875 | J3: 7.875 | K3: 1.036184 | L3: 1.035 | M3: 0.875 | N3: FALSE | O3: FALSE | P3: FALSE | Q3: TRANSFERABLE / REVIEW
A4: Sun | B4: 01:00 | C4: 7.3 | D4: 0.125 | E4: 8 | F4: 7 | G4: 0.958904 | H4: 0.43 | I4: 0 | J4: 7 | K4: 0.958904 | L4: 0.43 | M4: 0 | N4: FALSE | O4: FALSE | P4: FALSE | Q4: UNAVOIDABLE INTEGER ROUNDING
A5: Sun | B5: 01:30 | C5: 6.4 | D5: 0.125 | E5: 7 | F5: 7 | G5: 1.09375 | H5: 1.24 | I5: 0.875 | J5: 7 | K5: 1.09375 | L5: 1.24 | M5: 0.875 | N5: FALSE | O5: FALSE | P5: FALSE | Q5: TRANSFERABLE / REVIEW
A6: Sun | B6: 02:00 | C6: 3.9 | D6: 0.142857 | E6: 5 | F6: 3.428571 | G6: 0.879121 | H6: 0 | I6: 0 | J6: 3.428571 | K6: 0.879121 | L6: 0 | M6: 0 | N6: FALSE | O6: FALSE | P6: FALSE | Q6: AT OR BELOW TARGET
A7: Sun | B7: 02:30 | C7: 3.5 | D7: 0.142857 | E7: 4 | F7: 3.428571 | G7: 0.979592 | H7: 0.278571 | I7: 0 | J7: 3.428571 | K7: 0.979592 | L7: 0.278571 | M7: 0 | N7: FALSE | O7: FALSE | P7: FALSE | Q7: UNAVOIDABLE INTEGER ROUNDING
A8: Sun | B8: 03:00 | C8: 2.7 | D8: 0.25 | E8: 4 | F8: 2.25 | G8: 0.833333 | H8: 0 | I8: 0 | J8: 2.25 | K8: 0.833333 | L8: 0 | M8: 0 | N8: FALSE | O8: FALSE | P8: FALSE | Q8: AT OR BELOW TARGET
A9: Sun | B9: 03:30 | C9: 2.3 | D9: 0.25 | E9: 3 | F9: 2.25 | G9: 0.978261 | H9: 0.18 | I9: 0 | J9: 2.25 | K9: 0.978261 | L9: 0.18 | M9: 0 | N9: FALSE | O9: FALSE | P9: FALSE | Q9: UNAVOIDABLE INTEGER ROUNDING
A10: Sun | B10: 04:00 | C10: 1.9 | D10: 0.5 | E10: 4 | F10: 1.5 | G10: 0.789474 | H10: 0 | I10: 0 | J10: 1.5 | K10: 0.789474 | L10: 0 | M10: 0 | N10: FALSE | O10: FALSE | P10: FALSE | Q10: AT OR BELOW TARGET
A11: Sun | B11: 04:30 | C11: 1.6 | D11: 0.5 | E11: 3 | F11: 1.5 | G11: 0.9375 | H11: 0.06 | I11: 0 | J11: 1.5 | K11: 0.9375 | L11: 0.06 | M11: 0 | N11: FALSE | O11: FALSE | P11: FALSE | Q11: UNAVOIDABLE INTEGER ROUNDING
A12: Sun | B12: 05:00 | C12: 1.4 | D12: 0 | E12: 2 | F12: 1 | G12: 0.714286 | H12: 0 | I12: 0 | J12: 1 | K12: 0.714286 | L12: 0 | M12: 0 | N12: FALSE | O12: FALSE | P12: FALSE | Q12: AT OR BELOW TARGET
A13: Sun | B13: 05:30 | C13: 1.2 | D13: 0 | E13: 2 | F13: 1 | G13: 0.833333 | H13: 0 | I13: 0 | J13: 1 | K13: 0.833333 | L13: 0 | M13: 0 | N13: FALSE | O13: FALSE | P13: FALSE | Q13: AT OR BELOW TARGET
... A253: Sat | B253: 23:30 | C253: 8.2 | D253: 0.125 | E253: 9 | F253: 10.5 | G253: 1.280488 | H253: 3.12 | I253: 2.625 | J253: 8.75 | K253: 1.067073 | L253: 1.37 | M253: 0.875 | N253: FALSE | O253: FALSE | P253: FALSE | Q253: TRANSFERABLE / REVIEW

Sheet Next Sunday Carry-Out Audit
A1: Day | B1: Interval | C1: Protected Quarters | D1: Required FTE | E1: Shrinkage | F1: Before Effective FTE | G1: Before % | H1: After Effective FTE | I1: After % | J1: Before Raw Minimum | K1: Before Raw Maximum | L1: After Raw Minimum | M1: After Raw Maximum | N1: Active Demand | O1: Target Status | P1: Floor Status | Q1: Blank Staffing Status | R1: Contributing Associates | S1: Associates on Break
A2: Next Sun | B2: 00:00 | C2: 2 | D2: 7.9 | E2: 0.125 | F2: 10.5 | G2: 1.329114 | H2: 9.625 | I2: 1.218354 | J2: 12 | K2: 12 | L2: 11 | M2: 11 | N2: YES | O2: PASS | P2: PASS | Q2: NOT APPLICABLE | R2: Amr Elgamal, Asmaa Eldokhmesy, Azza Adel, Mayar Aboali, Mohamed Bahnasy, Mohamed Osama, Noura Saber, Omnia Ewies, Saja Nour, Sameh Sabry, Shahd Bakry, Zeyad Eledeissy | S2: Mohamed Osama, Sameh Sabry
A3: Next Sun | B3: 00:30 | C3: 2 | D3: 7.6 | E3: 0.125 | F3: 10.5 | G3: 1.381579 | H3: 9.625 | I3: 1.266447 | J3: 12 | K3: 12 | L3: 11 | M3: 11 | N3: YES | O3: PASS | P3: PASS | Q3: NOT APPLICABLE | R3: Amr Elgamal, Asmaa Eldokhmesy, Azza Adel, Mayar Aboali, Mohamed Bahnasy, Mohamed Osama, Noura Saber, Omnia Ewies, Saja Nour, Sameh Sabry, Shahd Bakry, Zeyad Eledeissy | S3: Mohamed Osama, Sameh Sabry
A4: Next Sun | B4: 01:00 | C4: 2 | D4: 7.3 | E4: 0.125 | F4: 7.875 | G4: 1.078767 | H4: 7 | I4: 0.958904 | J4: 9 | K4: 9 | L4: 8 | M4: 8 | N4: YES | O4: PASS | P4: PASS | Q4: NOT APPLICABLE | R4: Amr Elgamal, Asmaa Eldokhmesy, Azza Adel, Mayar Aboali, Mohamed Osama, Noura Saber, Saja Nour, Sameh Sabry, Shahd Bakry | S4: Noura Saber
A5: Next Sun | B5: 01:30 | C5: 2 | D5: 6.4 | E5: 0.125 | F5: 7.875 | G5: 1.230469 | H5: 6.5625 | I5: 1.025391 | J5: 9 | K5: 9 | L5: 7 | M5: 8 | N5: YES | O5: PASS | P5: PASS | Q5: NOT APPLICABLE | R5: Amr Elgamal, Asmaa Eldokhmesy, Azza Adel, Mayar Aboali, Mohamed Osama, Noura Saber, Saja Nour, Sameh Sabry, Shahd Bakry | S5: Mohamed Osama, Noura Saber
A6: Next Sun | B6: 02:00 | C6: 2 | D6: 3.9 | E6: 0.142857 | F6: 5.142857 | G6: 1.318681 | H6: 4.714286 | I6: 1.208791 | J6: 6 | K6: 6 | L6: 5 | M6: 6 | N6: YES | O6: PASS | P6: PASS | Q6: NOT APPLICABLE | R6: Amr Elgamal, Mayar Aboali, Mohamed Osama, Noura Saber, Sameh Sabry, Shahd Bakry | S6: Mayar Aboali
A7: Next Sun | B7: 02:30 | C7: 2 | D7: 3.5 | E7: 0.142857 | F7: 5.142857 | G7: 1.469388 | H7: 4.285714 | I7: 1.22449 | J7: 6 | K7: 6 | L7: 5 | M7: 5 | N7: YES | O7: PASS | P7: PASS | Q7: NOT APPLICABLE | R7: Amr Elgamal, Mayar Aboali, Mohamed Osama, Noura Saber, Sameh Sabry, Shahd Bakry | S7: Mayar Aboali
A8: Next Sun | B8: 03:00 | C8: 2 | D8: 2.7 | E8: 0.25 | F8: 4.5 | G8: 1.666667 | H8: 3.75 | I8: 1.388889 | J8: 6 | K8: 6 | L8: 5 | M8: 5 | N8: YES | O8: PASS | P8: PASS | Q8: NOT APPLICABLE | R8: Amr Elgamal, Mayar Aboali, Mohamed Osama, Noura Saber, Sameh Sabry, Shahd Bakry | S8: Mayar Aboali, Shahd Bakry
A9: Next Sun | B9: 03:30 | C9: 2 | D9: 2.3 | E9: 0.25 | F9: 4.5 | G9: 1.956522 | H9: 3.75 | I9: 1.630435 | J9: 6 | K9: 6 | L9: 5 | M9: 5 | N9: YES | O9: PASS | P9: PASS | Q9: NOT APPLICABLE | R9: Amr Elgamal, Mayar Aboali, Mohamed Osama, Noura Saber, Sameh Sabry, Shahd Bakry | S9: Shahd Bakry
A10: Next Sun | B10: 04:00 | C10: 2 | D10: 1.9 | E10: 0.5 | F10: 2 | G10: 1.052632 | H10: 1.75 | I10: 0.921053 | J10: 4 | K10: 4 | L10: 3 | M10: 4 | N10: YES | O10: PASS | P10: PASS | Q10: NOT APPLICABLE | R10: Mayar Aboali, Mohamed Osama, Noura Saber, Shahd Bakry | S10: Shahd Bakry
A11: Next Sun | B11: 04:30 | C11: 2 | D11: 1.6 | E11: 0.5 | F11: 2 | G11: 1.25 | H11: 2 | I11: 1.25 | J11: 4 | K11: 4 | L11: 4 | M11: 4 | N11: YES | O11: PASS | P11: PASS | Q11: NOT APPLICABLE | R11: Mayar Aboali, Mohamed Osama, Noura Saber, Shahd Bakry
A12: Next Sun | B12: 05:00 | C12: 2 | D12: 1.4 | E12: 0 | F12: 2 | G12: 1.428571 | H12: 2 | I12: 1.428571 | J12: 2 | K12: 2 | L12: 2 | M12: 2 | N12: YES | O12: PASS | P12: PASS | Q12: NOT APPLICABLE | R12: Mayar Aboali, Shahd Bakry
A13: Next Sun | B13: 05:30 | C13: 2 | D13: 1.2 | E13: 0 | F13: 2 | G13: 1.666667 | H13: 2 | I13: 1.666667 | J13: 2 | K13: 2 | L13: 2 | M13: 2 | N13: YES | O13: PASS | P13: PASS | Q13: NOT APPLICABLE | R13: Mayar Aboali, Shahd Bakry
A14: Next Sun | B14: 06:00 | C14: 2 | D14: 1 | E14: 0 | F14: 2 | G14: 2 | H14: 2 | I14: 2 | J14: 2 | K14: 2 | L14: 2 | M14: 2 | N14: YES | O14: PASS | P14: PASS | Q14: NOT APPLICABLE | R14: Mayar Aboali, Shahd Bakry
A15: Next Sun | B15: 06:30 | C15: 2 | D15: 1 | E15: 0 | F15: 2 | G15: 2 | H15: 2 | I15: 2 | J15: 2 | K15: 2 | L15: 2 | M15: 2 | N15: YES | O15: PASS | P15: PASS | Q15: NOT APPLICABLE | R15: Mayar Aboali, Shahd Bakry
A16: Next Sun | B16: 07:00 | C16: 2 | D16: 0.3 | E16: 0 | F16: 2 | G16: 6.666667 | H16: 2 | I16: 6.666667 | J16: 2 | K16: 2 | L16: 2 | M16: 2 | N16: YES | O16: PASS | P16: PASS | Q16: NOT APPLICABLE | R16: Mayar Aboali, Shahd Bakry
A17: Next Sun | B17: 07:30 | C17: 2 | D17: 0.3 | E17: 0 | F17: 2 | G17: 6.666667 | H17: 2 | I17: 6.666667 | J17: 2 | K17: 2 | L17: 2 | M17: 2 | N17: YES | O17: PASS | P17: PASS | Q17: NOT APPLICABLE | R17: Mayar Aboali, Shahd Bakry

Sheet Canonical Contract
A1: Contract Field | B1: Canonical Value
A2: Engine Version | B2: L6.3.2.3-R1.2.0-B-ENGINE-MATURITY-RC4.4.8-PHASE-B-CLOSURE-RC1
A3: Named Roster Count | B3: 17
A4: Instructed Headcount | B4: 0
A5: Headcount Mismatch Allowed | B5: FALSE
A6: Interval Minutes | B6: 30
A7: Requirement Sheet | B7: FT Wise 30 Min
A8: Shrinkage Sheet | B8: Shrinkage 30 Min
A9: Program Name | B9: Not specified
A10: Target Ratio | B10: 0.9
A11: Target Priority Confirmed | B11: FALSE
A12: Configured Floor Ratio | B12: 0.8
A13: Overage Control Enabled | B13: TRUE
A14: Overage Soft Cap | B14: 1.1
A15: Overage Severe Cap | B15: 1.2
A16: Overage Extreme Cap | B16: 1.4
A17: Overage Penalty Weight | B17: 40
A18: Minimum Best Before Target
A19: Minimum Final Before Target
A20: Quality Benchmark Tolerance | B20: 0
A21: Floor Mode | B21: protected
A22: Hard Floor Ratio | B22: Not hard
A23: Hard Floor Source | B23: Protected floor only
A24: Allowed Shift Durations Minutes | B24: 540
A25: Allowed Shift Start Window | B25: Unrestricted
A26: Shift Start Step Minutes | B26: 1
A27: Legal Shift Count | B27: 10
A28: 11H / 3OFF Enabled | B28: FALSE
A29: Blank Requirement Mode | B29: allow
A30: Blank Requirement Text
A31: Demand Fit Guard Mode | B31: yes
A32: Demand Fit Guard Effective | B32: TRUE
A33: Opening Guard Enabled | B33: FALSE
A34: Opening Minimum | B34: 2
A35: Opening Intervals | B35: 2
A36: Break Window Source | B36: instructions
A37: No-Break Exceptions Allowed | B37: FALSE
A38: Maximum No-Break Exceptions | B38: 0

Sheet No-Break Exceptions
A1: Associate | B1: Day | C1: Shift | D1: Language/Skill | E1: Blocking Rules / Windows | F1: Exception Proof | G1: Forced-Break Probe | H1: Alternative Exception Count | I1: Mandatory Comment | J1: Permission Source | K1: Review Status
E2: No exceptions | J2: Explicit runner disable | K2: PASS

Sheet Validation Log
A1: Check | B1: Status | C1: Associate | D1: Details
A2: Overall | B2: PASS_WITH_COVERAGE_TRADEOFF

Sheet Rest Gap Audit
A1: Associate | B1: From Day | C1: To Day | D1: From Shift | E1: To Shift | F1: Rest Hours | G1: Status
A2: Fady Assal | B2: Mon | C2: Tue | D2: 17:00 - 02:00 | E2: 23:00 - 08:00 | F2: 21 | G2: PASS
A3: Fady Assal | B3: Tue | C3: Wed | D3: 23:00 - 08:00 | E3: 23:00 - 08:00 | F3: 15 | G3: PASS
A4: Fady Assal | B4: Wed | C4: Thu | D4: 23:00 - 08:00 | E4: 23:00 - 08:00 | F4: 15 | G4: PASS
A5: Fady Assal | B5: Thu | C5: Fri | D5: 23:00 - 08:00 | E5: 21:00 - 06:00 | F5: 13 | G5: PASS
A6: Mohamed Osama | B6: Wed | C6: Thu | D6: 18:00 - 03:00 | E6: 18:00 - 03:00 | F6: 15 | G6: PASS
A7: Mohamed Osama | B7: Thu | C7: Fri | D7: 18:00 - 03:00 | E7: 19:00 - 04:00 | F7: 16 | G7: PASS
A8: Mohamed Osama | B8: Fri | C8: Sat | D8: 19:00 - 04:00 | E8: 20:00 - 05:00 | F8: 16 | G8: PASS
A9: Saja Nour | B9: Sun | C9: Mon | D9: 20:00 - 05:00 | E9: 20:00 - 05:00 | F9: 15 | G9: PASS
A10: Saja Nour | B10: Thu | C10: Fri | D10: 15:00 - 00:00 | E10: 17:00 - 02:00 | F10: 17 | G10: PASS
A11: Saja Nour | B11: Fri | C11: Sat | D11: 17:00 - 02:00 | E11: 17:00 - 02:00 | F11: 15 | G11: PASS
A12: Mayar Aboali | B12: Sun | C12: Mon | D12: 22:00 - 07:00 | E12: 23:00 - 08:00 | F12: 16 | G12: PASS
A13: Mayar Aboali | B13: Thu | C13: Fri | D13: 19:00 - 04:00 | E13: 19:00 - 04:00 | F13: 15 | G13: PASS
... A59: Asmaa Eldokhmesy | B59: Fri | C59: Sat | D59: 14:00 - 23:00 | E59: 17:00 - 02:00 | F59: 18 | G59: PASS

Sheet Language Skill Audit
A1: Day | B1: Interval | C1: Coverage Group | D1: Required Languages | E1: Eligible Source Languages | F1: Minimum | G1: Actual | H1: Status
A2: Sun | B2: 00:00 | C2: English | D2: english | E2: english, spanish | F2: 1 | G2: >=1 | H2: PASS
A3: Sun | B3: 00:00 | C3: Spanish | D3: spanish | E3: spanish | F3: 1 | G3: >=1 | H3: PASS
A4: Sun | B4: 00:30 | C4: English | D4: english | E4: english, spanish | F4: 1 | G4: >=1 | H4: PASS
A5: Sun | B5: 00:30 | C5: Spanish | D5: spanish | E5: spanish | F5: 1 | G5: >=1 | H5: PASS
A6: Sun | B6: 01:00 | C6: English | D6: english | E6: english, spanish | F6: 1 | G6: >=1 | H6: PASS
A7: Sun | B7: 01:00 | C7: Spanish | D7: spanish | E7: spanish | F7: 1 | G7: >=1 | H7: PASS
A8: Sun | B8: 01:30 | C8: English | D8: english | E8: english, spanish | F8: 1 | G8: >=1 | H8: PASS
A9: Sun | B9: 01:30 | C9: Spanish | D9: spanish | E9: spanish | F9: 1 | G9: >=1 | H9: PASS
A10: Sun | B10: 02:00 | C10: English | D10: english | E10: english, spanish | F10: 1 | G10: >=1 | H10: PASS
A11: Sun | B11: 02:30 | C11: English | D11: english | E11: english, spanish | F11: 1 | G11: >=1 | H11: PASS
A12: Sun | B12: 03:00 | C12: English | D12: english | E12: english, spanish | F12: 1 | G12: >=1 | H12: PASS
A13: Sun | B13: 03:30 | C13: English | D13: english | E13: english, spanish | F13: 1 | G13: >=1 | H13: PASS
... A365: Sat | B365: 23:30 | C365: Spanish | D365: spanish | E365: spanish | F365: 1 | G365: >=1 | H365: PASS

Sheet Language Setup
A1: Language / Skill Setup
A2: Directional rule: each source language can cover itself plus the comma-separated languages in Can Cover Languages.
A4: Language | B4: Coverage Start | C4: Coverage End | D4: Can Cover Languages | E4: Active? | F4: Coverage Group | G4: Minimum Per Interval
A5: English | B5: 13:00 | C5: 07:00 | D5: English | E5: Yes | F5: English | G5: 1
A6: Spanish | B6: 17:00 | C6: 02:00 | D6: Spanish, English | E6: Yes | F6: Spanish | G6: 1

Sheet Preference
A1: Preference / OFF / Leave Requests
A2: Enter only associates with requests. OFF is hard when Hard OFF Preferences = Yes; shift values are soft preferences.
A4: Associate Name | B4: Sun | C4: Mon | D4: Tue | E4: Wed | F4: Thu | G4: Fri | H4: Sat | I4: Notes

Sheet Instructions
A1: Instructions — RC8.6.6 Business Contract
A2: Edit only the yellow Value cells. Dropdowns block invalid text. Technical solver defaults are stored on protected hidden sheets.
A4: Section | B4: Instruction | C4: Value | D4: What this controls
A5: Case Setup | B5: Program Name | C5: NMG SPEN | D5: Optional business/program label; never changes engine behavior.
A6: Case Setup | B6: Interval Minutes | C6: 30 | D6: Select the interval size used by requirements and shrinkage.
A7: Case Setup | B7: Requirements Source | C7: FT Wise 30 Min | D7: Choose the requirement sheet that contains the active demand grid.
A8: Case Setup | B8: Shrinkage Source | C8: Shrinkage 30 Min | D8: Choose the shrinkage sheet matching the selected interval.
A9: Coverage | B9: Target | C9: 0.9 | D9: Primary after-break coverage target. 90% means after90 is the primary KPI.
A10: Coverage | B10: Target Priority Confirmed | C10: Yes | D10: Required confirmation when Target is 100%.
A11: Coverage | B11: Minimum Per Interval | C11: 0.8 | D11: Protected coverage floor used for safety and tradeoff review.
A12: Coverage | B12: Hard Floor Solver Constraint Enabled | C12: No | D12: Yes makes the floor a hard feasibility rule; No keeps it protected.
A13: Coverage | B13: Blank Interval Staffing Rule | C13: No new staffing in blank intervals | D13: Controls whether blank demand periods may receive new current-week staffing.
A14: Shift & OFF | B14: Allowed Shift Durations Hours | C14: 9 | D14: Allowed paid shift durations from the Shift Library.
A15: Shift & OFF | B15: Use 11H/3OFF | C15: No | D15: Enable only when the business contract allows 11-hour / 3-OFF patterns.
A16: Shift & OFF | B16: Strict OFF Count | C16: Yes | D16: Requires the expected weekly OFF count for the selected shift pattern.
A17: Shift & OFF | B17: Separate OFF Days | C17: No | D17: No prefers the normal consecutive-OFF structure; enable only for an approved exception policy.
A18: Shift & OFF | B18: Rest Gap Hours | C18: 12 | D18: Minimum rest between adjacent shifts, including Saturday to Sunday.
A19: Shift & OFF | B19: Count of Different Shifts Per week | C19: 3 | D19: Maximum distinct shift labels an associate may receive in one week.
A20: Requests | B20: Fixed Request Use | C20: No | D20: Enable exact/flexible nesting requests from Fixed Request.
A21: Requests | B21: Hard OFF Preferences | C21: Yes | D21: Treat hard OFF requests as hard constraints.
A22: Requests | B22: Leave Enabled | C22: Yes | D22: Honor leave entries in the workbook.
A23: Requests | B23: Use Preferences | C23: Yes | D23: Use soft shift/OFF preferences as lower-priority objectives.
A24: Opening Guard | B24: Opening Guard Enabled | C24: No | D24: Enable a minimum staffing requirement at opening/reopening intervals.
A25: Opening Guard | B25: Opening Minimum FTE | C25: 2 | D25: Minimum opening/reopening FTE when the guard is enabled.
A26: Opening Guard | B26: Opening Guard Intervals | C26: 2 | D26: Number of opening/reopening intervals protected by the guard.
A27: Breaks | B27: Short Break Count | C27: 2 | D27: Number of short breaks per working shift.
A28: Breaks | B28: Short Break Duration Minutes | C28: 15 | D28: Duration of each short break.
A29: Breaks | B29: Lunch Count | C29: 1 | D29: Number of lunch breaks per working shift.
A30: Breaks | B30: Lunch Duration Minutes | C30: 30 | D30: Duration of each lunch break.
A31: Breaks | B31: Break Preferred Gap Minutes | C31: 120 | D31: Preferred spacing between break segments.
A32: Breaks | B32: Break Absolute Minimum Gap Minutes | C32: 60 | D32: Hard legal minimum. RC8.6 ready examples use 60; preferred spacing remains a weighted quality target.
A33: Breaks | B33: Break Normal Maximum Gap Minutes | C33: 150 | D33: Normal upper spacing target before extended spacing is recorded.
A34: Breaks | B34: Allow Back-to-Back Breaks | C34: No | D34: Explicit override only; normally keep No.
A35: Exception Policy | B35: Critical Coverage No-Break Exception Enabled | C35: No | D35: Allows audited no-break associate-days only as a last resort.
A36: Exception Policy | B36: Critical Coverage No-Break Max Associate-Days | C36: 0 | D36: Maximum approved no-break associate-days; never raised automatically.
A37: Release Quality | B37: Production Quality Gate Mode | C37: Fail | D37: Fail blocks release on configured coverage-quality caps; Warn keeps a hard-valid schedule with warnings.

Sheet Engine Defaults
A1: Instruction | B1: Value | C1: Purpose
A2: section | B2: Instruction | C2: Preserved case-specific RC7 contract/default; hidden in RC8 because it is not a normal business entry field.
A3: instruction | B3: Value | C3: Preserved case-specific RC7 contract/default; hidden in RC8 because it is not a normal business entry field.
A4: case setup | B4: Shrinkage Source | C4: Preserved case-specific RC7 contract/default; hidden in RC8 because it is not a normal business entry field.
A5: coverage | B5: Target Priority Confirmed | C5: Preserved case-specific RC7 contract/default; hidden in RC8 because it is not a normal business entry field.
A6: shift off | B6: Count of Different Shifts Per week | C6: Preserved case-specific RC7 contract/default; hidden in RC8 because it is not a normal business entry field.
A7: requests | B7: Use Preferences | C7: Preserved case-specific RC7 contract/default; hidden in RC8 because it is not a normal business entry field.
A8: opening guard | B8: Opening Guard Intervals | C8: Preserved case-specific RC7 contract/default; hidden in RC8 because it is not a normal business entry field.
A9: demand fit | B9: Demand Fit Maximum Blank Span Minutes | C9: Preserved case-specific RC7 contract/default; hidden in RC8 because it is not a normal business entry field.
A10: demand fit guard enabled | B10: Yes | C10: Preserved case-specific RC7 contract/default; hidden in RC8 because it is not a normal business entry field.
A11: demand fit minimum active minutes | B11: 180 | C11: Preserved case-specific RC7 contract/default; hidden in RC8 because it is not a normal business entry field.
A12: demand fit minimum active ratio | B12: 0.45 | C12: Preserved case-specific RC7 contract/default; hidden in RC8 because it is not a normal business entry field.
A13: demand fit maximum blank span minutes | B13: 0 | C13: Preserved case-specific RC7 contract/default; hidden in RC8 because it is not a normal business entry field.
A14: breaks | B14: Maximum Concurrent Breaks | C14: Preserved case-specific RC7 contract/default; hidden in RC8 because it is not a normal business entry field.
A15: exception policy | B15: Critical Coverage No-Break Max Associate-Days | C15: Preserved case-specific RC7 contract/default; hidden in RC8 because it is not a normal business entry field.
A16: break windows | B16: Break 2 Latest Minutes From Shift Start | C16: Preserved case-specific RC7 contract/default; hidden in RC8 because it is not a normal business entry field.
A17: minimum gap between breaks minutes | B17: 0 | C17: Preserved case-specific RC7 contract/default; hidden in RC8 because it is not a normal business entry field.
A18: count of associates | B18: 17 | C18: Preserved case-specific RC7 contract/default; hidden in RC8 because it is not a normal business entry field.
A19: identity | B19: Allow Headcount Mismatch | C19: Preserved case-specific RC7 contract/default; hidden in RC8 because it is not a normal business entry field.
A20: rc7 input contract version | B20: L6.3.2.3-R1.3.0-C-C4-PHASE-C-FINAL-CONTRACT-SEMANTICS-RC7 | C20: Preserved case-specific RC7 contract/default; hidden in RC8 because it is not a normal business entry field.
A21: allow headcount mismatch | B21: No | C21: Preserved case-specific RC7 contract/default; hidden in RC8 because it is not a normal business entry field.
A22: maximum concurrent break ratio | B22: 0.3 | C22: Preserved case-specific RC7 contract/default; hidden in RC8 because it is not a normal business entry field.
A23: maximum concurrent breaks | B23: 4 | C23: Preserved case-specific RC7 contract/default; hidden in RC8 because it is not a normal business entry field.
A24: quality semantics | B24: Skill Allocation Gate Mode | C24: Preserved case-specific RC7 contract/default; hidden in RC8 because it is not a normal business entry field.
A25: break concurrency gate mode | B25: Warn | C25: Preserved case-specific RC7 contract/default; hidden in RC8 because it is not a normal business entry field.
A26: coverage quality | B26: Production Quality Gate Mode | C26: Preserved case-specific RC7 contract/default; hidden in RC8 because it is not a normal business entry field.
A27: production maximum floor gap ratio | B27: 0.1 | C27: Preserved case-specific RC7 contract/default; hidden in RC8 because it is not a normal business entry field.
A28: production maximum severe gap ratio | B28: 0.05 | C28: Preserved case-specific RC7 contract/default; hidden in RC8 because it is not a normal business entry field.
A29: production maximum consecutive floor gaps | B29: 3 | C29: Preserved case-specific RC7 contract/default; hidden in RC8 because it is not a normal business entry field.
A30: language skill | B30: Qualified Language Break Certificate Waiver Penalty | C30: Preserved case-specific RC7 contract/default; hidden in RC8 because it is not a normal business entry field.
A31: language operational reserve enabled | B31: Yes | C31: Preserved case-specific RC7 contract/default; hidden in RC8 because it is not a normal business entry field.
A32: language operational reserve extra fte | B32: 1 | C32: Preserved case-specific RC7 contract/default; hidden in RC8 because it is not a normal business entry field.
A33: language reserve gate mode | B33: Warn | C33: Preserved case-specific RC7 contract/default; hidden in RC8 because it is not a normal business entry field.
A34: language maximum minimum only ratio | B34: 0.25 | C34: Preserved case-specific RC7 contract/default; hidden in RC8 because it is not a normal business entry field.
A35: qualified language break certificate enabled | B35: Yes | C35: Preserved case-specific RC7 contract/default; hidden in RC8 because it is not a normal business entry field.
A36: qualified language break certificate pattern limit | B36: 1260 | C36: Preserved case-specific RC7 contract/default; hidden in RC8 because it is not a normal business entry field.
A37: qualified language break certificate maximum cells | B37: 8 | C37: Preserved case-specific RC7 contract/default; hidden in RC8 because it is not a normal business entry field.
A38: qualified language break certificate shift span minutes | B38: 360 | C38: Preserved case-specific RC7 contract/default; hidden in RC8 because it is not a normal business entry field.
A39: qualified language break certificate waiver penalty | B39: 50000000 | C39: Preserved case-specific RC7 contract/default; hidden in RC8 because it is not a normal business entry field.
A40: week boundary | B40: Next Sunday Maximum Adjacent Raw Change | C40: Preserved case-specific RC7 contract/default; hidden in RC8 because it is not a normal business entry field.
...

Sheet Candidate Leaderboard
A1: Skeleton Profile | B1: Break Profile | C1: Objective Mode | D1: CP Status | E1: Pattern Width | F1: Exception Count | G1: After Target | H1: After Floor | I1: After Hard Floor | J1: After100 | K1: After90 | L1: After80 | M1: Before Target | N1: Before Floor | O1: Before Hard Floor | P1: Before100 | Q1: Before90 | R1: Before80 | S1: Floor Gaps | T1: Hard Floor Gaps | U1: Next Sunday After Target | V1: Next Sunday After Floor | W1: Next Sunday Floor Gaps | X1: Next Sunday Zero Quarters | Y1: Next Sunday Language Gaps | Z1: Next Sunday Opening Gaps | AA1: Next Sunday Blank Staffed Quarters | AB1: Severe Floor Gaps | AC1: Max Floor Run | AD1: Floor Deficit Sum | AE1: Target Deficit Sum | AF1: Target Losses From Breaks | AG1: Floor Losses From Breaks | AH1: Before Target Overage | AI1: After Target Overage | AJ1: Before Avoidable Overage | AK1: After Avoidable Overage | AL1: Before Severe Overage | AM1: After Severe Overage | AN1: Before Extreme Overage | AO1: After Extreme Overage | AP1: Objective | AQ1: Selected Role | AR1: Selected
A2: post_break_generalized_repair_0_6 | B2: fully_compliant_coverage_rebalance | C2: coverage_rebalance | D2: FEASIBLE | E2: 115 | F2: 0 | G2: 172 | H2: 179 | I2: 0 | J2: 126 | K2: 172 | L2: 179 | M2: 174 | N2: 182 | O2: 0 | P2: 162 | Q2: 174 | R2: 182 | S2: 73 | T2: 0 | U2: 16 | V2: 16 | W2: 0 | X2: 0 | Y2: 0 | Z2: 0 | AA2: 0 | AB2: 61 | AC2: 16 | AD2: 18.179032 | AE2: 25.998758 | AF2: 2 | AG2: 3 | AH2: 229.96357 | AI2: 137.10524 | AJ2: 168.70595 | AK2: 83.560119 | AL2: 102 | AM2: 68 | AN2: 70 | AO2: 58 | AP2: 2777523752 | AQ2: MAX_TARGET_CANDIDATE | AR2: YES
A3: post_break_generalized_repair_0_4 | B3: fully_compliant_coverage_rebalance | C3: coverage_rebalance | D3: FEASIBLE | E3: 115 | F3: 0 | G3: 169 | H3: 183 | I3: 0 | J3: 123 | K3: 169 | L3: 183 | M3: 172 | N3: 183 | O3: 0 | P3: 155 | Q3: 172 | R3: 183 | S3: 69 | T3: 0 | U3: 16 | V3: 16 | W3: 0 | X3: 0 | Y3: 0 | Z3: 0 | AA3: 0 | AB3: 62 | AC3: 16 | AD3: 18.885441 | AE3: 26.570235 | AF3: 3 | AG3: 0 | AH3: 229.27357 | AI3: 135.09607 | AJ3: 169.03095 | AK3: 82.676786 | AL3: 98 | AM3: 66 | AN3: 67 | AO3: 57 | AP3: 2754943688
A4: post_break_generalized_repair_0_4 | B4: fully_compliant_lexicographic_target | C4: lexicographic_target | D4: FEASIBLE | E4: 115 | F4: 0 | G4: 169 | H4: 183 | I4: 0 | J4: 121 | K4: 169 | L4: 183 | M4: 172 | N4: 183 | O4: 0 | P4: 155 | Q4: 172 | R4: 183 | S4: 69 | T4: 0 | U4: 16 | V4: 16 | W4: 0 | X4: 0 | Y4: 0 | Z4: 0 | AA4: 0 | AB4: 64 | AC4: 16 | AD4: 18.860352 | AE4: 26.545146 | AF4: 3 | AG4: 0 | AH4: 229.27357 | AI4: 135.96214 | AJ4: 169.03095 | AK4: 83.542857 | AL4: 98 | AM4: 66 | AN4: 67 | AO4: 57 | AP4: 82694653156
A5: post_break_generalized_repair_0_4 | B5: fully_compliant_target_priority | C5: target_priority | D5: FEASIBLE | E5: 115 | F5: 0 | G5: 168 | H5: 183 | I5: 0 | J5: 124 | K5: 168 | L5: 183 | M5: 172 | N5: 183 | O5: 0 | P5: 155 | Q5: 172 | R5: 183 | S5: 69 | T5: 0 | U5: 16 | V5: 16 | W5: 0 | X5: 0 | Y5: 0 | Z5: 0 | AA5: 0 | AB5: 63 | AC5: 16 | AD5: 18.890907 | AE5: 26.668662 | AF5: 4 | AG5: 0 | AH5: 229.27357 | AI5: 136.97024 | AJ5: 169.03095 | AK5: 85.334524 | AL5: 98 | AM5: 66 | AN5: 67 | AO5: 57 | AP5: 2134116470
A6: post_break_generalized_repair_0_2 | B6: fully_compliant_target_priority | C6: target_priority | D6: FEASIBLE | E6: 115 | F6: 0 | G6: 165 | H6: 180 | I6: 0 | J6: 123 | K6: 165 | L6: 180 | M6: 167 | N6: 182 | O6: 0 | P6: 149 | Q6: 167 | R6: 182 | S6: 72 | T6: 0 | U6: 16 | V6: 16 | W6: 0 | X6: 0 | Y6: 0 | Z6: 0 | AA6: 0 | AB6: 67 | AC6: 16 | AD6: 19.296224 | AE6: 27.32932 | AF6: 2 | AG6: 2 | AH6: 232.13786 | AI6: 140.76595 | AJ6: 174.24524 | AK6: 89.3125 | AL6: 99 | AM6: 66 | AN6: 71 | AO6: 57 | AP6: 2222909220
A7: phase_b_coordinated_repair_3_1 | B7: fully_compliant_coverage_rebalance | C7: coverage_rebalance | D7: FEASIBLE | E7: 115 | F7: 0 | G7: 161 | H7: 178 | I7: 0 | J7: 117 | K7: 161 | L7: 178 | M7: 164 | N7: 178 | O7: 0 | P7: 144 | Q7: 164 | R7: 178 | S7: 74 | T7: 0 | U7: 16 | V7: 16 | W7: 0 | X7: 0 | Y7: 0 | Z7: 0 | AA7: 0 | AB7: 65 | AC7: 16 | AD7: 19.642001 | AE7: 27.990028 | AF7: 3 | AG7: 0 | AH7: 222.90357 | AI7: 133.56774 | AJ7: 166.78095 | AK7: 85.155357 | AL7: 92 | AM7: 62 | AN7: 66 | AO7: 52 | AP7: 3034446924
A8: phase_b_coordinated_repair_2_1 | B8: fully_compliant_coverage_rebalance | C8: coverage_rebalance | D8: FEASIBLE | E8: 115 | F8: 0 | G8: 161 | H8: 178 | I8: 0 | J8: 117 | K8: 161 | L8: 178 | M8: 164 | N8: 178 | O8: 0 | P8: 144 | Q8: 164 | R8: 178 | S8: 74 | T8: 0 | U8: 16 | V8: 16 | W8: 0 | X8: 0 | Y8: 0 | Z8: 0 | AA8: 0 | AB8: 66 | AC8: 16 | AD8: 19.640383 | AE8: 27.988409 | AF8: 3 | AG8: 0 | AH8: 222.90357 | AI8: 134.93024 | AJ8: 166.78095 | AK8: 86.517857 | AL8: 92 | AM8: 62 | AN8: 66 | AO8: 52 | AP8: 3033892696
A9: hard_feasibility_probe | B9: fully_compliant_target_priority | C9: target_priority | D9: FEASIBLE | E9: 115 | F9: 0 | G9: 156 | H9: 172 | I9: 0 | J9: 112 | K9: 156 | L9: 172 | M9: 158 | N9: 173 | O9: 0 | P9: 135 | Q9: 158 | R9: 173 | S9: 80 | T9: 0 | U9: 16 | V9: 16 | W9: 0 | X9: 0 | Y9: 0 | Z9: 0 | AA9: 0 | AB9: 66 | AC9: 16 | AD9: 19.261061 | AE9: 28.291966 | AF9: 2 | AG9: 1 | AH9: 215.94857 | AI9: 133.0969 | AJ9: 162.65595 | AK9: 86.43869 | AL9: 84 | AM9: 56 | AN9: 60 | AO9: 48 | AP9: 2350777534
A10: hard_feasibility_probe | B10: fully_compliant_diagnostic_fallback | C10: diagnostic_zero_exception_fallback | D10: OPTIMAL | E10: 115 | F10: 0 | G10: 141 | H10: 161 | I10: 0 | J10: 112 | K10: 141 | L10: 161 | M10: 158 | N10: 173 | O10: 0 | P10: 135 | Q10: 158 | R10: 173 | S10: 91 | T10: 0 | U10: 16 | V10: 16 | W10: 0 | X10: 0 | Y10: 0 | Z10: 0 | AA10: 0 | AB10: 69 | AC10: 16 | AD10: 20.19428 | AE10: 30.355849 | AF10: 17 | AG10: 12 | AH10: 215.94857 | AI10: 151.50833 | AJ10: 162.65595 | AK10: 104.00476 | AL10: 84 | AM10: 69 | AN10: 60 | AO10: 56 | AP10: 5205

Sheet Target Tradeoff Audit
A1: Skeleton | B1: Break Profile | C1: Objective Mode | D1: Width | E1: Target Ratio | F1: After Target | G1: After Floor | H1: After100 | I1: After90 | J1: After80 | K1: Floor Loss vs Best | L1: Target Gain vs Floor Anchor | M1: Severe Floor Gaps | N1: Max Floor Run | O1: Maximum Floor Deficit | P1: Tradeoff Cap | Q1: Risk OK | R1: Accepted
A2: hard_feasibility_probe | B2: fully_compliant_target_priority | C2: target_priority | D2: 115 | E2: 0.9 | F2: 156 | G2: 172 | H2: 112 | I2: 156 | J2: 172 | K2: 11 | L2: -13 | M2: 66 | N2: 16 | O2: 0.6 | P2: severity_only | Q2: TRUE | R2: TRUE
A3: hard_feasibility_probe | B3: fully_compliant_diagnostic_fallback | C3: diagnostic_zero_exception_fallback | D3: 115 | E3: 0.9 | F3: 141 | G3: 161 | H3: 112 | I3: 141 | J3: 161 | K3: 22 | L3: -28 | M3: 69 | N3: 16 | O3: 0.59166667 | P3: severity_only | Q3: TRUE | R3: TRUE
A4: phase_b_coordinated_repair_2_1 | B4: fully_compliant_coverage_rebalance | C4: coverage_rebalance | D4: 115 | E4: 0.9 | F4: 161 | G4: 178 | H4: 117 | I4: 161 | J4: 178 | K4: 5 | L4: -8 | M4: 66 | N4: 16 | O4: 0.66486486 | P4: severity_only | Q4: TRUE | R4: TRUE
A5: phase_b_coordinated_repair_3_1 | B5: fully_compliant_coverage_rebalance | C5: coverage_rebalance | D5: 115 | E5: 0.9 | F5: 161 | G5: 178 | H5: 117 | I5: 161 | J5: 178 | K5: 5 | L5: -8 | M5: 65 | N5: 16 | O5: 0.66486486 | P5: severity_only | Q5: TRUE | R5: TRUE
A6: post_break_generalized_repair_0_2 | B6: fully_compliant_target_priority | C6: target_priority | D6: 115 | E6: 0.9 | F6: 165 | G6: 180 | H6: 123 | I6: 165 | J6: 180 | K6: 3 | L6: -4 | M6: 67 | N6: 16 | O6: 0.66486486 | P6: severity_only | Q6: TRUE | R6: TRUE
A7: post_break_generalized_repair_0_4 | B7: fully_compliant_target_priority | C7: target_priority | D7: 115 | E7: 0.9 | F7: 168 | G7: 183 | H7: 124 | I7: 168 | J7: 183 | K7: 0 | L7: -1 | M7: 63 | N7: 16 | O7: 0.66486486 | P7: severity_only | Q7: TRUE | R7: TRUE
A8: post_break_generalized_repair_0_6 | B8: fully_compliant_coverage_rebalance | C8: coverage_rebalance | D8: 115 | E8: 0.9 | F8: 172 | G8: 179 | H8: 126 | I8: 172 | J8: 179 | K8: 4 | L8: 3 | M8: 61 | N8: 16 | O8: 0.60769231 | P8: severity_only | Q8: TRUE | R8: TRUE
A9: post_break_generalized_repair_0_4 | B9: fully_compliant_lexicographic_target | C9: lexicographic_target | D9: 115 | E9: 0.9 | F9: 169 | G9: 183 | H9: 121 | I9: 169 | J9: 183 | K9: 0 | L9: 0 | M9: 64 | N9: 16 | O9: 0.66486486 | P9: severity_only | Q9: TRUE | R9: TRUE
A10: post_break_generalized_repair_0_4 | B10: fully_compliant_coverage_rebalance | C10: coverage_rebalance | D10: 115 | E10: 0.9 | F10: 169 | G10: 183 | H10: 123 | I10: 169 | J10: 183 | K10: 0 | L10: 0 | M10: 62 | N10: 16 | O10: 0.66486486 | P10: severity_only | Q10: TRUE | R10: TRUE

Sheet Feasibility Report
A1: Category | B1: Item | C1: Value / Slack | D1: Details
A2: Capacity | B2: roster_count | C2: 17
A3: Capacity | B3: legal_shift_count | C3: 10
A4: Capacity | B4: interval_minutes | C4: 30
A5: Capacity | B5: active_intervals | C5: 252
A6: Capacity | B6: leave_days | C6: 0
A7: Capacity | B7: estimated_working_shifts | C7: 85
A8: Capacity | B8: productive_hours_available | C8: 680
A9: Capacity | B9: target_hours_lower_bound | C9: 710.51593
A10: Capacity | B10: floor_hours_lower_bound | C10: 631.56971
A11: Capacity | B11: hard_floor_hours_lower_bound | C11: 0
A12: Capacity | B12: productive_minus_target_lower_bound | C12: -30.515929
A13: Capacity | B13: productive_minus_floor_lower_bound | C13: 48.430286
A14: Capacity | B14: productive_minus_hard_floor_lower_bound | C14: 680
A15: Directional Capability | B15: english | C15: english | D15: Source associate language can cover these target languages
A16: Directional Capability | B16: spanish | C16: english, spanish | D16: Source associate language can cover these target languages
A17: Language Window | B17: Sun English | C17: 118 | D17: required=['english'] eligible_sources=['english', 'spanish'] available=17 window=18.0h minimum=1 status=OK; Fady Assal, Mohamed Osama, Saja Nour, Mayar Aboali, Mohamed Bahnasy, Khloud Mohamed, Azza Adel, Omnia Ewies, Noura Saber, Sameh Sabry, Zeyad Eledeissy, Shahd Bakry, Waseem Mohamed, Emad Abdelqader, Jana Amer, Amr Elgamal, Asmaa Eldokhmesy
A18: Language Window | B18: Sun Spanish | C18: 31 | D18: required=['spanish'] eligible_sources=['spanish'] available=5 window=9.0h minimum=1 status=OK; Waseem Mohamed, Emad Abdelqader, Jana Amer, Amr Elgamal, Asmaa Eldokhmesy
A19: Language Window | B19: Mon English | C19: 118 | D19: required=['english'] eligible_sources=['english', 'spanish'] available=17 window=18.0h minimum=1 status=OK; Fady Assal, Mohamed Osama, Saja Nour, Mayar Aboali, Mohamed Bahnasy, Khloud Mohamed, Azza Adel, Omnia Ewies, Noura Saber, Sameh Sabry, Zeyad Eledeissy, Shahd Bakry, Waseem Mohamed, Emad Abdelqader, Jana Amer, Amr Elgamal, Asmaa Eldokhmesy
A20: Language Window | B20: Mon Spanish | C20: 31 | D20: required=['spanish'] eligible_sources=['spanish'] available=5 window=9.0h minimum=1 status=OK; Waseem Mohamed, Emad Abdelqader, Jana Amer, Amr Elgamal, Asmaa Eldokhmesy
A21: Language Window | B21: Tue English | C21: 118 | D21: required=['english'] eligible_sources=['english', 'spanish'] available=17 window=18.0h minimum=1 status=OK; Fady Assal, Mohamed Osama, Saja Nour, Mayar Aboali, Mohamed Bahnasy, Khloud Mohamed, Azza Adel, Omnia Ewies, Noura Saber, Sameh Sabry, Zeyad Eledeissy, Shahd Bakry, Waseem Mohamed, Emad Abdelqader, Jana Amer, Amr Elgamal, Asmaa Eldokhmesy
A22: Language Window | B22: Tue Spanish | C22: 31 | D22: required=['spanish'] eligible_sources=['spanish'] available=5 window=9.0h minimum=1 status=OK; Waseem Mohamed, Emad Abdelqader, Jana Amer, Amr Elgamal, Asmaa Eldokhmesy
A23: Language Window | B23: Wed English | C23: 118 | D23: required=['english'] eligible_sources=['english', 'spanish'] available=17 window=18.0h minimum=1 status=OK; Fady Assal, Mohamed Osama, Saja Nour, Mayar Aboali, Mohamed Bahnasy, Khloud Mohamed, Azza Adel, Omnia Ewies, Noura Saber, Sameh Sabry, Zeyad Eledeissy, Shahd Bakry, Waseem Mohamed, Emad Abdelqader, Jana Amer, Amr Elgamal, Asmaa Eldokhmesy
A24: Language Window | B24: Wed Spanish | C24: 31 | D24: required=['spanish'] eligible_sources=['spanish'] available=5 window=9.0h minimum=1 status=OK; Waseem Mohamed, Emad Abdelqader, Jana Amer, Amr Elgamal, Asmaa Eldokhmesy
A25: Language Window | B25: Thu English | C25: 118 | D25: required=['english'] eligible_sources=['english', 'spanish'] available=17 window=18.0h minimum=1 status=OK; Fady Assal, Mohamed Osama, Saja Nour, Mayar Aboali, Mohamed Bahnasy, Khloud Mohamed, Azza Adel, Omnia Ewies, Noura Saber, Sameh Sabry, Zeyad Eledeissy, Shahd Bakry, Waseem Mohamed, Emad Abdelqader, Jana Amer, Amr Elgamal, Asmaa Eldokhmesy
A26: Language Window | B26: Thu Spanish | C26: 31 | D26: required=['spanish'] eligible_sources=['spanish'] available=5 window=9.0h minimum=1 status=OK; Waseem Mohamed, Emad Abdelqader, Jana Amer, Amr Elgamal, Asmaa Eldokhmesy
A27: Language Window | B27: Fri English | C27: 118 | D27: required=['english'] eligible_sources=['english', 'spanish'] available=17 window=18.0h minimum=1 status=OK; Fady Assal, Mohamed Osama, Saja Nour, Mayar Aboali, Mohamed Bahnasy, Khloud Mohamed, Azza Adel, Omnia Ewies, Noura Saber, Sameh Sabry, Zeyad Eledeissy, Shahd Bakry, Waseem Mohamed, Emad Abdelqader, Jana Amer, Amr Elgamal, Asmaa Eldokhmesy
A28: Language Window | B28: Fri Spanish | C28: 31 | D28: required=['spanish'] eligible_sources=['spanish'] available=5 window=9.0h minimum=1 status=OK; Waseem Mohamed, Emad Abdelqader, Jana Amer, Amr Elgamal, Asmaa Eldokhmesy
... A46: Break Resilience Weekly | B46: Spanish | C46: 0 | D46: status=PASS active_days=7 required_worker_days=14 available_upper_bound=25 eligible=Amr Elgamal, Asmaa Eldokhmesy, Emad Abdelqader, Jana Amer, Waseem Mohamed

Sheet Blank Interval Audit
A1: Day | B1: Interval | C1: Current-Week Before Raw Min | D1: Current-Week Before Raw Max | E1: Current-Week After Raw Min | F1: Current-Week After Raw Max | G1: Prior Carry-In Raw Min | H1: Prior Carry-In Raw Max | I1: Total After Raw Min | J1: Total After Raw Max | K1: Total After Raw Average | L1: Contract Mode | M1: Rule | N1: Status
C2: 0 | D2: 0 | E2: 0 | F2: 0 | G2: 0 | H2: 0 | I2: 0 | J2: 0 | K2: 0 | L2: allow | N2: PASS

Sheet Shift Demand Fit Audit
A1: Associate | B1: Day | C1: Shift | D1: Shift Start | E1: Start Contract | F1: Active Minutes | G1: Active Ratio | H1: Max Blank Minutes | I1: Guard Mode | J1: Guard Enabled | K1: Demand Fit Status | L1: Overall Status
A2: Fady Assal | B2: Mon | C2: 17:00 - 02:00 | D2: 17:00 | E2: PASS | F2: 540 | G2: 1 | H2: 0 | I2: yes | J2: TRUE | K2: PASS | L2: PASS
A3: Fady Assal | B3: Tue | C3: 23:00 - 08:00 | D3: 23:00 | E3: PASS | F3: 540 | G3: 1 | H3: 0 | I3: yes | J3: TRUE | K3: PASS | L3: PASS
A4: Fady Assal | B4: Wed | C4: 23:00 - 08:00 | D4: 23:00 | E4: PASS | F4: 540 | G4: 1 | H4: 0 | I4: yes | J4: TRUE | K4: PASS | L4: PASS
A5: Fady Assal | B5: Thu | C5: 23:00 - 08:00 | D5: 23:00 | E5: PASS | F5: 540 | G5: 1 | H5: 0 | I5: yes | J5: TRUE | K5: PASS | L5: PASS
A6: Fady Assal | B6: Fri | C6: 21:00 - 06:00 | D6: 21:00 | E6: PASS | F6: 540 | G6: 1 | H6: 0 | I6: yes | J6: TRUE | K6: PASS | L6: PASS
A7: Mohamed Osama | B7: Sun | C7: 19:00 - 04:00 | D7: 19:00 | E7: PASS | F7: 540 | G7: 1 | H7: 0 | I7: yes | J7: TRUE | K7: PASS | L7: PASS
A8: Mohamed Osama | B8: Wed | C8: 18:00 - 03:00 | D8: 18:00 | E8: PASS | F8: 540 | G8: 1 | H8: 0 | I8: yes | J8: TRUE | K8: PASS | L8: PASS
A9: Mohamed Osama | B9: Thu | C9: 18:00 - 03:00 | D9: 18:00 | E9: PASS | F9: 540 | G9: 1 | H9: 0 | I9: yes | J9: TRUE | K9: PASS | L9: PASS
A10: Mohamed Osama | B10: Fri | C10: 19:00 - 04:00 | D10: 19:00 | E10: PASS | F10: 540 | G10: 1 | H10: 0 | I10: yes | J10: TRUE | K10: PASS | L10: PASS
A11: Mohamed Osama | B11: Sat | C11: 20:00 - 05:00 | D11: 20:00 | E11: PASS | F11: 540 | G11: 1 | H11: 0 | I11: yes | J11: TRUE | K11: PASS | L11: PASS
A12: Saja Nour | B12: Sun | C12: 20:00 - 05:00 | D12: 20:00 | E12: PASS | F12: 540 | G12: 1 | H12: 0 | I12: yes | J12: TRUE | K12: PASS | L12: PASS
A13: Saja Nour | B13: Mon | C13: 20:00 - 05:00 | D13: 20:00 | E13: PASS | F13: 540 | G13: 1 | H13: 0 | I13: yes | J13: TRUE | K13: PASS | L13: PASS
... A86: Asmaa Eldokhmesy | B86: Sat | C86: 17:00 - 02:00 | D86: 17:00 | E86: PASS | F86: 540 | G86: 1 | H86: 0 | I86: yes | J86: TRUE | K86: PASS | L86: PASS

Sheet Overnight Audit
A1: Associate | B1: Start Day | C1: Next Day | D1: Shift | E1: Next-Day Active Minutes | F1: Next-Day Blank Minutes | G1: Status
A2: Fady Assal | B2: Mon | C2: Tue | D2: 17:00 - 02:00 | E2: 120 | F2: 0 | G2: PASS
A3: Fady Assal | B3: Tue | C3: Wed | D3: 23:00 - 08:00 | E3: 480 | F3: 0 | G3: PASS
A4: Fady Assal | B4: Wed | C4: Thu | D4: 23:00 - 08:00 | E4: 480 | F4: 0 | G4: PASS
A5: Fady Assal | B5: Thu | C5: Fri | D5: 23:00 - 08:00 | E5: 480 | F5: 0 | G5: PASS
A6: Fady Assal | B6: Fri | C6: Sat | D6: 21:00 - 06:00 | E6: 360 | F6: 0 | G6: PASS
A7: Mohamed Osama | B7: Sun | C7: Mon | D7: 19:00 - 04:00 | E7: 240 | F7: 0 | G7: PASS
A8: Mohamed Osama | B8: Wed | C8: Thu | D8: 18:00 - 03:00 | E8: 180 | F8: 0 | G8: PASS
A9: Mohamed Osama | B9: Thu | C9: Fri | D9: 18:00 - 03:00 | E9: 180 | F9: 0 | G9: PASS
A10: Mohamed Osama | B10: Fri | C10: Sat | D10: 19:00 - 04:00 | E10: 240 | F10: 0 | G10: PASS
A11: Mohamed Osama | B11: Sat | C11: Next Sun | D11: 20:00 - 05:00 | E11: 300 | F11: 0 | G11: PASS
A12: Saja Nour | B12: Sun | C12: Mon | D12: 20:00 - 05:00 | E12: 300 | F12: 0 | G12: PASS
A13: Saja Nour | B13: Mon | C13: Tue | D13: 20:00 - 05:00 | E13: 300 | F13: 0 | G13: PASS
... A71: Asmaa Eldokhmesy | B71: Sat | C71: Next Sun | D71: 17:00 - 02:00 | E71: 120 | F71: 0 | G71: PASS

Sheet Cyclic Sunday Audit
A1: Associate | B1: Previous Saturday | C1: Sunday Shift | D1: Carry-In Minutes | E1: Rest Status
A2: Fady Assal | B2: 23:00 - 08:00 | D2: 480 | E2: NOT_APPLICABLE
A3: Mohamed Osama | B3: 17:00 - 02:00 | C3: 19:00 - 04:00 | D3: 120 | E3: PASS
A4: Saja Nour | B4: 20:00 - 05:00 | C4: 20:00 - 05:00 | D4: 300 | E4: PASS
A5: Mayar Aboali | B5: 14:00 - 23:00 | C5: 22:00 - 07:00 | D5: 0 | E5: PASS
A6: Mohamed Bahnasy | B6: OFF | C6: 16:00 - 01:00 | D6: 0 | E6: PASS
A7: Khloud Mohamed | B7: 20:00 - 05:00 | D7: 300 | E7: NOT_APPLICABLE
A8: Azza Adel | B8: OFF | D8: 0 | E8: NOT_APPLICABLE
A9: Omnia Ewies | B9: 16:00 - 01:00 | C9: 16:00 - 01:00 | D9: 60 | E9: PASS
A10: Noura Saber | B10: OFF | C10: 17:00 - 02:00 | D10: 0 | E10: PASS
A11: Sameh Sabry | B11: 18:00 - 03:00 | C11: 18:00 - 03:00 | D11: 180 | E11: PASS
A12: Zeyad Eledeissy | B12: OFF | D12: 0 | E12: NOT_APPLICABLE
A13: Shahd Bakry | B13: 15:00 - 00:00 | C13: 21:00 - 06:00 | D13: 0 | E13: PASS
A14: Waseem Mohamed | B14: 17:00 - 02:00 | C14: 23:00 - 08:00 | D14: 120 | E14: PASS
A15: Emad Abdelqader | B15: 17:00 - 02:00 | C15: 14:00 - 23:00 | D15: 120 | E15: PASS
A16: Jana Amer | B16: 17:00 - 02:00 | C16: 14:00 - 23:00 | D16: 120 | E16: PASS
A17: Amr Elgamal | B17: OFF | D17: 0 | E17: NOT_APPLICABLE
A18: Asmaa Eldokhmesy | B18: OFF | C18: 17:00 - 02:00 | D18: 0 | E18: PASS

Sheet 00 START HERE
A1: Universal WFM Scheduler — RC8 Clean Input Template
A2: Business-safe input workbook. Complete the yellow Instructions values and roster/demand sheets; dropdowns prevent common contract typos. Engine tuning stays hidden.
A3: Prepared RC8 example: NMG_SPEN_PHASE_B_REPLAY. Client/program text is descriptive only and never branches engine logic.
A4: 5-step setup
A5: 1 | B5: Instructions | C5: Choose interval/source sheets, target/floor, blank-demand policy, shift/OFF rules, and break policy using dropdowns. | E5: Input color guide
A6: 2 | B6: Schedule | C6: Enter each associate once: ID, email, name, TL, and language. Leave Sun–Sat blank. | E6: Yellow | F6: User input / dropdown
A7: 3 | B7: Requirements & Shrinkage | C7: Paste required HC into the selected FT Wise sheet. Closed intervals stay blank. Enter shrinkage in the matching sheet. | E7: Grey | F7: Reference, formula, or engine output area
A8: 4 | B8: Optional Requests | C8: Use Preference, Fixed Request, Language Setup, and Previous week scheduled only when applicable. | E8: Blue | F8: Section header / guidance
A9: 5 | B9: Validate & Run | C9: Open Input Checks. Resolve CHECK/MISSING items, then upload this workbook using the universal Colab runner. | E9: Green | F9: Ready / PASS
E10: Red | F10: Missing or inconsistent input
A12: Fixed engine protections — no manual solver tuning required
A13: • Final production decision is based on after-break coverage; BEST BEFORE remains a protected review artifact and recovery anchor.
A14: • Blank-demand policy is explicit. “No new staffing” is enforced in shift filtering, CP-SAT, repair, and final validation.
A15: • Overnight demand is interpreted cyclically, so 14:00–08:00 is not mistaken for 24/7.
A16: • Language/skill coverage is directional: source language → languages it can cover.
A17: • Rest, OFF/leave/fixed/nesting, opening, Next Sunday, hard floors, and approved exception caps remain authoritative.
A18: RC8.4 correction | B18: NMG examples use Separate OFF Days = No so 9H/2OFF schedules prefer valid consecutive OFF pairs; separate OFF remains possible only when explicitly enabled by business instruction.
E19: Readiness snapshot
E20: Check | F20: Current status | G20: Go to
E21: Instruction sources aligned | F21: ='Input Checks'!B5 | G21: Instructions
E22: Roster ready | F22: ='Input Checks'!B7 | G22: Schedule
E23: Requirements loaded | F23: ='Input Checks'!B10 | G23: FT Wise selected source
E24: Allowed shifts loaded | F24: ='Input Checks'!B11 | G24: Shift Library
