Workbook

Sheet Read Me First
A1: RC9.2.2 | Schedule Control Center
A2: BEST_FINAL_AFTER_BREAKS_SCHEDULE • PREPARED OUTPUT - not operational until the independent validation seal and production package exist • RC9.2.2-OUTPUT-UX-RC2
A4: Schedule Status | C4: Interval Grid | F4: After Target | G4: After Floor
A5: GO WITH MONITORING | C5: 30 minutes | F5: 245 / 264 (92.8%) | G5: 254 / 264 (96.2%)
A8: Coverage Attainment
A9: Threshold | B9: Before breaks | C9: After breaks | D9: Change
A10: 100% | B10: 247 | C10: 245 | D10: -2
A11: 90% | B11: 250 | C11: 247 | D11: -3
A12: 80% | B12: 254 | C12: 254 | D12: 0
A13: Target | B13: 247 | C13: 245 | D13: -2
A14: Floor | B14: 254 | C14: 254 | D14: 0
A16: Risk & Exception Snapshot
A17: Check | B17: Count | C17: Status | D17: Operational note | F17: Run Configuration
A18: Hard validation failures | B18: 0 | C18: PASS | D18: Must be zero | F18: Roster count | G18: 33
A19: Floor gaps | B19: 10 | C19: WARN | D19: Review concentration and severity | F19: Legal shift count | G19: 24
A20: Zero-staffed active intervals | B20: 0 | C20: PASS | D20: Must be zero | F20: Target ratio | G20: 1
A21: Language gaps | B21: 0 | C21: PASS | D21: Must be zero | F21: Floor ratio | G21: 0.8
A22: Opening gaps | B22: 0 | C22: PASS | D22: Must be zero | F22: After target overage FTE | G22: 647.77922
A23: No-break exceptions | B23: 0 | C23: PASS | D23: Review any approved exception | F23: After avoidable overage FTE | G23: 590.14167
A24: Blank staffed intervals | B24: 0 | C24: PASS | D24: Must be zero | F24: Final engine status | G24: PASS_WITH_QUALITY_WARNINGS
A25: Break concurrency violations | B25: 1 | C25: WARN | D25: Monitor if non-zero | F25: Production quality gate | G25: WARN
A28: How to use this workbook
A29: 1 | B29: Schedule = the week to publish; OFF and leave cells are colour-coded. Break Plan shows each person's shift and breaks per day.
A30: 2 | B30: Break Schedule lists every break; investigate WARN/REVIEW rows before release.
A31: 3 | B31: FT Wise After Breaks = interval coverage, colour-coded (red below 80%, amber below 90%).
A32: 4 | B32: Production Summary and Validation Log hold every measure. The audit and input tabs are hidden, not deleted: right-click any tab > Unhide.
A33: 5 | B33: This result uses a 30-minute grid. The engine supports both 30- and 60-minute workbooks.

Sheet Schedule
A1: Schedule — Roster Input
A2: Slot | B2: Emp ID | C2: Email | D2: SF Name | E2: TL | F2: Language | G2: Sun | H2: Mon | I2: Tue | J2: Wed | K2: Thu | L2: Fri | M2: Sat | N2: Roster Notes
A3: 1 | B3: 726146 | C3: aabdelghani-ecw@cricut.com | D3: Abdelrahman Abdelghani | E3: Habiba Farag | F3: English | G3: 16:00 - 01:00 | H3: 16:00 - 01:00 | I3: 16:00 - 01:00 | J3: OFF | K3: 16:00 - 01:00 | L3: 17:00 - 02:00 | M3: OFF
A4: =A3+1 | B4: 631577 | C4: kaboaly-ecw@cricut.com | D4: Kamal Aboaly | E4: Habiba Farag | F4: English | G4: 18:00 - 03:00 | H4: OFF | I4: 02:00 - 11:00 | J4: 18:00 - 03:00 | K4: 18:00 - 03:00 | L4: 17:00 - 02:00 | M4: OFF
A5: =A4+1 | B5: 723687 | C5: nabdelrehiem-ecw@cricut.com | D5: Nadine Abdelrehiem | E5: Habiba Farag | F5: English | G5: 18:00 - 03:00 | H5: 18:00 - 03:00 | I5: 16:00 - 01:00 | J5: OFF | K5: 18:00 - 03:00 | L5: 17:00 - 02:00 | M5: OFF
A6: =A5+1 | B6: 618777 | C6: ramir-ecw@cricut.com | D6: Rowan Amir | E6: Habiba Farag | F6: English | G6: 16:00 - 01:00 | H6: 16:00 - 01:00 | I6: 16:00 - 01:00 | J6: 16:00 - 01:00 | K6: OFF | L6: 17:00 - 02:00 | M6: OFF
A7: =A6+1 | B7: 703856 | C7: salatar-ecw@cricut.com | D7: Seif Alatar | E7: Habiba Farag | F7: English | G7: 18:00 - 03:00 | H7: 16:00 - 01:00 | I7: 16:00 - 01:00 | J7: OFF | K7: 18:00 - 03:00 | L7: 17:00 - 02:00 | M7: OFF
A8: =A7+1 | B8: 723445 | C8: abdelrahmanahmed-ecw@cricut.com | D8: Abdelrahman Ahmed | E8: Hania Zahran | F8: English | G8: 18:00 - 03:00 | H8: 16:00 - 01:00 | I8: 16:00 - 01:00 | J8: 18:00 - 03:00 | K8: OFF | L8: 17:00 - 02:00 | M8: OFF
A9: =A8+1 | B9: 703868 | C9: aabdelmotaleb-ecw@cricut.com | D9: Adham Abdelmotaleb | E9: Hania Zahran | F9: English | G9: 18:00 - 03:00 | H9: 18:00 - 03:00 | I9: 16:00 - 01:00 | J9: 18:00 - 03:00 | K9: 18:00 - 03:00 | L9: OFF | M9: OFF
A10: =A9+1 | B10: 723447 | C10: asalouma-ecw@cricut.com | D10: Ahmed Salouma | E10: Hania Zahran | F10: English | G10: 18:00 - 03:00 | H10: 16:00 - 01:00 | I10: 16:00 - 01:00 | J10: OFF | K10: 18:00 - 03:00 | L10: 17:00 - 02:00 | M10: OFF
A11: =A10+1 | B11: 705852 | C11: maramabdelrahman-ecw@cricut.com | D11: Maram Abdelrahman | E11: Hania Zahran | F11: English | G11: 16:00 - 01:00 | H11: 16:00 - 01:00 | I11: 16:00 - 01:00 | J11: 18:00 - 03:00 | K11: 18:00 - 03:00 | L11: OFF | M11: OFF
A12: =A11+1 | B12: 610846 | C12: mmohamed-ecw@cricut.com | D12: Mariem Mohamed | E12: Hania Zahran | F12: English | G12: Leave | H12: Leave | I12: Leave | J12: Leave | K12: Leave | L12: OFF | M12: OFF
A13: =A12+1 | B13: 404668 | C13: melkhouly-ecw@cricut.com | D13: Mohamed Elkhouly | E13: Hania Zahran | F13: English | G13: 18:00 - 03:00 | H13: OFF | I13: 16:00 - 01:00 | J13: 18:00 - 03:00 | K13: 18:00 - 03:00 | L13: 17:00 - 02:00 | M13: OFF
A14: =A13+1 | B14: 695463 | C14: aelbamby-ecw@cricut.com | D14: Aya Elbamby | E14: Mohamed Shalaby | F14: English | G14: 01:00 - 10:00 | H14: 19:00 - 04:00 | I14: 19:00 - 04:00 | J14: 19:00 - 04:00 | K14: OFF | L14: 17:00 - 02:00 | M14: OFF
A15: =A14+1 | B15: 703862 | C15: bsweidan-ecw@cricut.com | D15: Basmala Sweidan | E15: Mohamed Shalaby | F15: English | G15: 00:00 - 09:00 | H15: 00:00 - 09:00 | I15: 00:00 - 09:00 | J15: 18:00 - 03:00 | K15: 18:00 - 03:00 | L15: OFF | M15: OFF
... A35: =A34+1 | B35: 615114 | C35: abdelrahmans-ecw@cricut.com | D35: Abdelrahman Saad | E35: Mohamed Shalaby | F35: International | G35: 11:00 - 20:00 | H35: 11:00 - 20:00 | I35: 11:00 - 20:00 | J35: 11:00 - 20:00 | K35: 11:00 - 20:00 | L35: OFF | M35: OFF

Sheet Break Plan
A1: Break Plan - each person's shift and breaks, day by day
A2: B1 / B2 = short breaks, L = lunch. Built from the Schedule and Break Schedule tabs of this workbook.
A3: Associate | B3: Language | C3: Sun | D3: Mon | E3: Tue | F3: Wed | G3: Thu | H3: Fri | I3: Sat
A4: Abdelrahman Abdelghani | B4: English | C4: 16:00 - 01:00 B1 18:00 | L 21:00 | B2 00:00 | D4: 16:00 - 01:00 B1 18:00 | L 20:45 | B2 00:00 | E4: 16:00 - 01:00 B1 21:00 | L 22:30 | B2 00:00 | F4: OFF | G4: 16:00 - 01:00 B1 18:15 | L 20:15 | B2 23:15 | H4: 17:00 - 02:00 B1 17:45 | L 19:30 | B2 21:00 | I4: OFF
A5: Kamal Aboaly | B5: English | C5: 18:00 - 03:00 B1 23:00 | L 00:15 | B2 01:45 | D5: OFF | E5: 02:00 - 11:00 B1 03:45 | L 06:30 | B2 09:15 | F5: 18:00 - 03:00 B1 23:00 | L 00:15 | B2 01:45 | G5: 18:00 - 03:00 B1 19:45 | L 22:45 | B2 01:30 | H5: 17:00 - 02:00 B1 18:00 | L 19:15 | B2 20:45 | I5: OFF
A6: Nadine Abdelrehiem | B6: English | C6: 18:00 - 03:00 B1 23:00 | L 00:15 | B2 01:45 | D6: 18:00 - 03:00 B1 18:45 | L 20:00 | B2 21:45 | E6: 16:00 - 01:00 B1 17:00 | L 18:15 | B2 19:45 | F6: OFF | G6: 18:00 - 03:00 B1 18:45 | L 20:00 | B2 21:45 | H6: 17:00 - 02:00 B1 19:15 | L 22:15 | B2 01:00 | I6: OFF
A7: Rowan Amir | B7: English | C7: 16:00 - 01:00 B1 18:00 | L 21:00 | B2 00:00 | D7: 16:00 - 01:00 B1 17:45 | L 20:30 | B2 00:00 | E7: 16:00 - 01:00 B1 17:45 | L 20:45 | B2 23:45 | F7: 16:00 - 01:00 B1 17:00 | L 18:15 | B2 19:45 | G7: OFF | H7: 17:00 - 02:00 B1 22:00 | L 23:15 | B2 00:45 | I7: OFF
A8: Seif Alatar | B8: English | C8: 18:00 - 03:00 B1 23:00 | L 00:15 | B2 01:45 | D8: 16:00 - 01:00 B1 17:30 | L 20:00 | B2 22:45 | E8: 16:00 - 01:00 B1 17:30 | L 20:00 | B2 23:15 | F8: OFF | G8: 18:00 - 03:00 B1 18:45 | L 20:15 | B2 21:45 | H8: 17:00 - 02:00 B1 19:15 | L 22:15 | B2 01:00 | I8: OFF
A9: Abdelrahman Ahmed | B9: English | C9: 18:00 - 03:00 B1 23:00 | L 00:15 | B2 01:45 | D9: 16:00 - 01:00 B1 17:00 | L 18:15 | B2 19:45 | E9: 16:00 - 01:00 B1 17:45 | L 20:30 | B2 23:30 | F9: 18:00 - 03:00 B1 23:00 | L 00:15 | B2 01:45 | G9: OFF | H9: 17:00 - 02:00 B1 18:15 | L 21:00 | B2 00:15 | I9: OFF
A10: Adham Abdelmotaleb | B10: English | C10: 18:00 - 03:00 B1 19:30 | L 22:30 | B2 01:30 | D10: 18:00 - 03:00 B1 19:45 | L 22:30 | B2 01:15 | E10: 16:00 - 01:00 B1 17:30 | L 20:15 | B2 23:15 | F10: 18:00 - 03:00 B1 19:00 | L 22:30 | B2 01:30 | G10: 18:00 - 03:00 B1 19:45 | L 22:45 | B2 01:45 | H10: OFF | I10: OFF
A11: Ahmed Salouma | B11: English | C11: 18:00 - 03:00 B1 18:45 | L 22:00 | B2 01:00 | D11: 16:00 - 01:00 B1 17:00 | L 18:15 | B2 19:45 | E11: 16:00 - 01:00 B1 21:15 | L 22:30 | B2 00:00 | F11: OFF | G11: 18:00 - 03:00 B1 19:45 | L 22:45 | B2 01:15 | H11: 17:00 - 02:00 B1 22:00 | L 23:15 | B2 00:45 | I11: OFF
A12: Maram Abdelrahman | B12: English | C12: 16:00 - 01:00 B1 18:15 | L 21:00 | B2 23:15 | D12: 16:00 - 01:00 B1 18:00 | L 20:45 | B2 00:00 | E12: 16:00 - 01:00 B1 17:15 | L 19:45 | B2 23:00 | F12: 18:00 - 03:00 B1 20:00 | L 22:30 | B2 01:15 | G12: 18:00 - 03:00 B1 18:45 | L 20:00 | B2 21:45 | H12: OFF | I12: OFF
A13: Mariem Mohamed | B13: English | C13: Leave | D13: Leave | E13: Leave | F13: Leave | G13: Leave | H13: OFF | I13: OFF
A14: Mohamed Elkhouly | B14: English | C14: 18:00 - 03:00 B1 19:45 | L 22:30 | B2 01:15 | D14: OFF | E14: 16:00 - 01:00 B1 17:00 | L 19:30 | B2 22:45 | F14: 18:00 - 03:00 B1 23:00 | L 00:15 | B2 01:45 | G14: 18:00 - 03:00 B1 19:45 | L 22:45 | B2 01:45 | H14: 17:00 - 02:00 B1 18:15 | L 21:30 | B2 00:30 | I14: OFF
... A36: Abdelrahman Saad | B36: International | C36: 11:00 - 20:00 B1 13:15 | L 16:00 | B2 18:30 | D36: 11:00 - 20:00 B1 12:00 | L 15:00 | B2 18:00 | E36: 11:00 - 20:00 B1 11:45 | L 15:30 | B2 19:00 | F36: 11:00 - 20:00 B1 11:45 | L 14:15 | B2 17:15 | G36: 11:00 - 20:00 B1 11:45 | L 13:00 | B2 14:30 | H36: OFF | I36: OFF

Sheet Break Schedule
A1: Associate | B1: Day | C1: Shift | D1: Break Type | E1: Start | F1: Duration Minutes | G1: Status
A2: Abdelrahman Abdelghani | B2: Sun | C2: 16:00 - 01:00 | D2: Break 1 | E2: 18:00 | F2: 15 | G2: Scheduled
A3: Abdelrahman Abdelghani | B3: Sun | C3: 16:00 - 01:00 | D3: Lunch | E3: 21:00 | F3: 30 | G3: Scheduled
A4: Abdelrahman Abdelghani | B4: Sun | C4: 16:00 - 01:00 | D4: Break 2 | E4: 00:00 | F4: 15 | G4: Scheduled
A5: Abdelrahman Abdelghani | B5: Mon | C5: 16:00 - 01:00 | D5: Break 1 | E5: 18:00 | F5: 15 | G5: Scheduled
A6: Abdelrahman Abdelghani | B6: Mon | C6: 16:00 - 01:00 | D6: Lunch | E6: 20:45 | F6: 30 | G6: Scheduled
A7: Abdelrahman Abdelghani | B7: Mon | C7: 16:00 - 01:00 | D7: Break 2 | E7: 00:00 | F7: 15 | G7: Scheduled
A8: Abdelrahman Abdelghani | B8: Tue | C8: 16:00 - 01:00 | D8: Break 1 | E8: 21:00 | F8: 15 | G8: Scheduled
A9: Abdelrahman Abdelghani | B9: Tue | C9: 16:00 - 01:00 | D9: Lunch | E9: 22:30 | F9: 30 | G9: Scheduled
A10: Abdelrahman Abdelghani | B10: Tue | C10: 16:00 - 01:00 | D10: Break 2 | E10: 00:00 | F10: 15 | G10: Scheduled
A11: Abdelrahman Abdelghani | B11: Thu | C11: 16:00 - 01:00 | D11: Break 1 | E11: 18:15 | F11: 15 | G11: Scheduled
A12: Abdelrahman Abdelghani | B12: Thu | C12: 16:00 - 01:00 | D12: Lunch | E12: 20:15 | F12: 30 | G12: Scheduled
A13: Abdelrahman Abdelghani | B13: Thu | C13: 16:00 - 01:00 | D13: Break 2 | E13: 23:15 | F13: 15 | G13: Scheduled
... A478: Abdelrahman Saad | B478: Thu | C478: 11:00 - 20:00 | D478: Break 2 | E478: 14:30 | F478: 15 | G478: Scheduled

Sheet FT Wise After Breaks
A1: Day | B1: Interval | C1: Required FTE | D1: Staffed Effective FTE | E1: Coverage %
A2: Sun | B2: 00:00 | C2: 2 | D2: 2.1 | E2: 1.05
A3: Sun | B3: 00:30 | C3: 2 | D3: 2.1 | E3: 1.05
A4: Sun | B4: 01:00 | C4: 2 | D4: 2.45 | E4: 1.225
A5: Sun | B5: 01:30 | C5: 2 | D5: 2.8 | E5: 1.4
A6: Sun | B6: 02:00 | C6: 2 | D6: 2.8 | E6: 1.4
A7: Sun | B7: 02:30 | C7: 3 | D7: 3.2 | E7: 1.066667
A8: Sun | B8: 03:00 | C8: 2 | D8: 4.5 | E8: 2.25
A9: Sun | B9: 03:30 | C9: 2 | D9: 4.5 | E9: 2.25
A10: Sun | B10: 04:00 | C10: 3 | D10: 5 | E10: 1.666667
A11: Sun | B11: 04:30 | C11: 2 | D11: 5.5 | E11: 2.75
A12: Sun | B12: 05:00 | C12: 2 | D12: 7 | E12: 3.5
A13: Sun | B13: 05:30 | C13: 2 | D13: 7 | E13: 3.5
... A265: Sat | B265: 01:30 | C265: 6 | D265: 11.266667 | E265: 1.877778

Sheet Coverage Before Breaks
A1: Day | B1: Interval | C1: Required FTE | D1: Staffed Effective FTE | E1: Coverage %
A2: Sun | B2: 00:00 | C2: 2 | D2: 2.1 | E2: 1.05
A3: Sun | B3: 00:30 | C3: 2 | D3: 2.1 | E3: 1.05
A4: Sun | B4: 01:00 | C4: 2 | D4: 2.8 | E4: 1.4
A5: Sun | B5: 01:30 | C5: 2 | D5: 2.8 | E5: 1.4
A6: Sun | B6: 02:00 | C6: 2 | D6: 3.2 | E6: 1.6
A7: Sun | B7: 02:30 | C7: 3 | D7: 3.2 | E7: 1.066667
A8: Sun | B8: 03:00 | C8: 2 | D8: 5 | E8: 2.5
A9: Sun | B9: 03:30 | C9: 2 | D9: 5 | E9: 2.5
A10: Sun | B10: 04:00 | C10: 3 | D10: 6 | E10: 2
A11: Sun | B11: 04:30 | C11: 2 | D11: 6 | E11: 3
A12: Sun | B12: 05:00 | C12: 2 | D12: 8 | E12: 4
A13: Sun | B13: 05:30 | C13: 2 | D13: 8 | E13: 4
... A265: Sat | B265: 01:30 | C265: 6 | D265: 11.266667 | E265: 1.877778

Sheet Production Summary
A1: Metric | B1: Value
A2: Artifact Type | B2: BEST_FINAL_AFTER_BREAKS_SCHEDULE
A3: Selection Basis | B3: Recommended operational Pareto schedule; maximum primary-target loss is 1 only when floor attainment, severity, concentration, or deficit depth materially improves
A4: Run ID | B4: 58828e57e5d8ef2b94678934
A5: Input SHA256 | B5: 9de3b7a6af68eb851ff4bcd65966e95d6fd92c7869751562d321451d2e3a2cbd
A6: Contract SHA256 | B6: 3039acda3011fe4b85f3dcf5b9a19098b13357276f8238b4b8bd29bb183dc688
A7: Engine SHA256 | B7: 9f91e56c95e4dac257903e3b5ff5dd56ec8b29c879aee6c6a36c25baa0428b2a
A8: Engine Version | B8: L6.3.2.8-RC9.2.2-PRODUCTION-HARDENED-RC6
A9: Final Status | B9: PASS_WITH_QUALITY_WARNINGS
A10: Input Workbook | B10: /tmp/claude-0/-home-user-Default/57e8acb4-ab5e-5113-8a50-dec0489e4e6a/scratchpad/e2e/runs/E2E_VOICE_FRIENDLY_9000/input_snapshot/Cricut_Voice_LANGUAGE_HOURS_FRIENDLY.xlsx
A11: Requirement Sheet | B11: FT Wise 30 Min
A12: Shrinkage Sheet | B12: Shrinkage 30 Min
A13: Canonical Coverage Truth | B13: Requirement and shrinkage sources are interval-aware; seed and final candidates are recomputed under the current workbook contract
A14: Interval Minutes | B14: 30
A15: Roster Count | B15: 33
A16: Legal Shift Count | B16: 24
A17: Target Ratio | B17: 1
A18: Floor Ratio | B18: 0.8
A19: Floor Mode | B19: protected
A20: Hard Floor Ratio | B20: Not hard
A21: Hard Floor Tolerance
A22: Hard Floor Source | B22: Protected floor only
A23: Break Absolute Minimum Gap Minutes | B23: 60
A24: Break Preferred Gap Minutes | B24: 150
A25: Break Normal Maximum Gap Minutes | B25: 210
A26: Flexible Break Compression Count | B26: 167
A27: Break Gaps Beyond Normal Maximum | B27: 0
A28: Allowed Shift Start Window | B28: Unrestricted
A29: Shift Start Step Minutes | B29: 1
A30: Blank Requirement Mode | B30: hard_no_current_week_staffing
A31: Blank Requirement Rule | B31: No new staffing in blank intervals
A32: Demand Fit Guard Mode | B32: auto
A33: Demand Fit Guard Effective | B33: TRUE
A34: Before Target Hits | B34: 247
A35: After Target Hits | B35: 245
A36: Before Floor Hits | B36: 254
A37: After Floor Hits | B37: 254
A38: Before Hard Floor Hits | B38: 0
A39: After Hard Floor Hits | B39: 0
A40: Directional Skill Parsing | B40: Source language capabilities are inverted to determine eligible source associates for each required language/group
...

Sheet Validation Log
A1: Check | B1: Status | C1: Associate | D1: Details
A2: Overall | B2: PASS_WITH_QUALITY_WARNINGS
A3: Parser Warning | B3: WARN | D3: EXACT_FIXED_ROW_NESTING_GROUP_IGNORED: Jhonny Mascarenhas contains exact day requests; flexible nesting group '1' was cleared to prevent contradictory group equality.
A4: Parser Warning | B4: WARN | D4: EXACT_FIXED_ROW_NESTING_GROUP_IGNORED: Meraj Shaikh contains exact day requests; flexible nesting group '1' was cleared to prevent contradictory group equality.
A5: Parser Warning | B5: WARN | D5: EXACT_FIXED_ROW_NESTING_GROUP_IGNORED: Jojie Lovino contains exact day requests; flexible nesting group '1' was cleared to prevent contradictory group equality.
A6: Parser Warning | B6: WARN | D6: EXACT_FIXED_ROW_NESTING_GROUP_IGNORED: Sharmaine Magtoto contains exact day requests; flexible nesting group '1' was cleared to prevent contradictory group equality.
A7: Parser Warning | B7: WARN | D7: EXACT_FIXED_ROW_NESTING_GROUP_IGNORED: Abdullah Khashab contains exact day requests; flexible nesting group '1' was cleared to prevent contradictory group equality.
A8: Parser Warning | B8: WARN | D8: EXACT_FIXED_ROW_NESTING_GROUP_IGNORED: Maryam AbdulWahab contains exact day requests; flexible nesting group '1' was cleared to prevent contradictory group equality.
A9: Parser Warning | B9: WARN | D9: EXACT_FIXED_ROW_NESTING_GROUP_IGNORED: Zyad Mahrous contains exact day requests; flexible nesting group '1' was cleared to prevent contradictory group equality.
A10: Parser Warning | B10: WARN | D10: EXACT_FIXED_ROW_NESTING_GROUP_IGNORED: Abdelrahman Saad contains exact day requests; flexible nesting group '1' was cleared to prevent contradictory group equality.
A11: Parser Warning | B11: WARN | D11: EXACT_FIXED_ROW_NESTING_GROUP_IGNORED: Shahd Mohamed contains exact day requests; flexible nesting group '2' was cleared to prevent contradictory group equality.
A12: Parser Warning | B12: WARN | D12: EXACT_FIXED_ROW_NESTING_GROUP_IGNORED: Youssef Hagag contains exact day requests; flexible nesting group '2' was cleared to prevent contradictory group equality.
A13: Parser Warning | B13: WARN | D13: EXACT_FIXED_ROW_NESTING_GROUP_IGNORED: Ahmed Habib contains exact day requests; flexible nesting group '2' was cleared to prevent contradictory group equality.
A14: Parser Warning | B14: WARN | D14: EXACT_FIXED_ROW_NESTING_GROUP_IGNORED: Fatima Ahmed contains exact day requests; flexible nesting group '2' was cleared to prevent contradictory group equality.
... A17: Parser Warning | B17: WARN | D17: EXACT_FIXED_ROW_NESTING_GROUP_IGNORED: Rana Negm contains exact day requests; flexible nesting group '2' was cleared to prevent contradictory group equality.

Sheet No-Break Exceptions
A1: Associate | B1: Day | C1: Shift | D1: Language/Skill | E1: Blocking Rules / Windows | F1: Exception Proof | G1: Forced-Break Probe | H1: Alternative Exception Count | I1: Mandatory Comment | J1: Permission Source | K1: Review Status
E2: No exceptions | J2: Disabled | K2: PASS

Sheet Break Spacing Audit
A1: Associate | B1: Day | C1: Shift | D1: From Segment | E1: To Segment | F1: Actual Gap Minutes | G1: Preferred Gap Minutes | H1: Absolute Minimum Minutes | I1: Normal Maximum Minutes | J1: Deviation Minutes | K1: Classification | L1: Approval Required
A2: Abdelrahman Abdelghani | B2: Sun | C2: 16:00 - 01:00 | D2: Break 1 | E2: Lunch | F2: 165 | G2: 150 | H2: 60 | I2: 210 | J2: 15 | K2: FLEXIBLE_EXTENSION | L2: NO
A3: Abdelrahman Abdelghani | B3: Sun | C3: 16:00 - 01:00 | D3: Lunch | E3: Break 2 | F3: 150 | G3: 150 | H3: 60 | I3: 210 | J3: 0 | K3: PREFERRED | L3: NO
A4: Abdelrahman Abdelghani | B4: Mon | C4: 16:00 - 01:00 | D4: Break 1 | E4: Lunch | F4: 150 | G4: 150 | H4: 60 | I4: 210 | J4: 0 | K4: PREFERRED | L4: NO
A5: Abdelrahman Abdelghani | B5: Mon | C5: 16:00 - 01:00 | D5: Lunch | E5: Break 2 | F5: 165 | G5: 150 | H5: 60 | I5: 210 | J5: 15 | K5: FLEXIBLE_EXTENSION | L5: NO
A6: Abdelrahman Abdelghani | B6: Tue | C6: 16:00 - 01:00 | D6: Break 1 | E6: Lunch | F6: 75 | G6: 150 | H6: 60 | I6: 210 | J6: -75 | K6: FLEXIBLE_COMPRESSION | L6: NO
A7: Abdelrahman Abdelghani | B7: Tue | C7: 16:00 - 01:00 | D7: Lunch | E7: Break 2 | F7: 60 | G7: 150 | H7: 60 | I7: 210 | J7: -90 | K7: FLEXIBLE_COMPRESSION | L7: NO
A8: Abdelrahman Abdelghani | B8: Thu | C8: 16:00 - 01:00 | D8: Break 1 | E8: Lunch | F8: 105 | G8: 150 | H8: 60 | I8: 210 | J8: -45 | K8: FLEXIBLE_COMPRESSION | L8: NO
A9: Abdelrahman Abdelghani | B9: Thu | C9: 16:00 - 01:00 | D9: Lunch | E9: Break 2 | F9: 150 | G9: 150 | H9: 60 | I9: 210 | J9: 0 | K9: PREFERRED | L9: NO
A10: Abdelrahman Abdelghani | B10: Fri | C10: 17:00 - 02:00 | D10: Break 1 | E10: Lunch | F10: 90 | G10: 150 | H10: 60 | I10: 210 | J10: -60 | K10: FLEXIBLE_COMPRESSION | L10: NO
A11: Abdelrahman Abdelghani | B11: Fri | C11: 17:00 - 02:00 | D11: Lunch | E11: Break 2 | F11: 60 | G11: 150 | H11: 60 | I11: 210 | J11: -90 | K11: FLEXIBLE_COMPRESSION | L11: NO
A12: Kamal Aboaly | B12: Sun | C12: 18:00 - 03:00 | D12: Break 1 | E12: Lunch | F12: 60 | G12: 150 | H12: 60 | I12: 210 | J12: -90 | K12: FLEXIBLE_COMPRESSION | L12: NO
A13: Kamal Aboaly | B13: Sun | C13: 18:00 - 03:00 | D13: Lunch | E13: Break 2 | F13: 60 | G13: 150 | H13: 60 | I13: 210 | J13: -90 | K13: FLEXIBLE_COMPRESSION | L13: NO
... A319: Abdelrahman Saad | B319: Thu | C319: 11:00 - 20:00 | D319: Lunch | E319: Break 2 | F319: 60 | G319: 150 | H319: 60 | I319: 210 | J319: -90 | K319: FLEXIBLE_COMPRESSION | L319: NO

Sheet Interval Coverage Audit
A1: Day | B1: Interval | C1: Required FTE | D1: Before Effective FTE | E1: Before % | F1: After Effective FTE | G1: After % | H1: Before Raw Minimum | I1: After Raw Minimum | J1: Floor Status
A2: Sun | B2: 00:00 | C2: 2 | D2: 2.1 | E2: 1.05 | F2: 2.1 | G2: 1.05 | H2: 3 | I2: 3 | J2: PASS
A3: Sun | B3: 00:30 | C3: 2 | D3: 2.1 | E3: 1.05 | F3: 2.1 | G3: 1.05 | H3: 3 | I3: 3 | J3: PASS
A4: Sun | B4: 01:00 | C4: 2 | D4: 2.8 | E4: 1.4 | F4: 2.45 | G4: 1.225 | H4: 4 | I4: 3 | J4: PASS
A5: Sun | B5: 01:30 | C5: 2 | D5: 2.8 | E5: 1.4 | F5: 2.8 | G5: 1.4 | H5: 4 | I5: 4 | J5: PASS
A6: Sun | B6: 02:00 | C6: 2 | D6: 3.2 | E6: 1.6 | F6: 2.8 | G6: 1.4 | H6: 4 | I6: 3 | J6: PASS
A7: Sun | B7: 02:30 | C7: 3 | D7: 3.2 | E7: 1.066667 | F7: 3.2 | G7: 1.066667 | H7: 4 | I7: 4 | J7: PASS
A8: Sun | B8: 03:00 | C8: 2 | D8: 5 | E8: 2.5 | F8: 4.5 | G8: 2.25 | H8: 5 | I8: 4 | J8: PASS
A9: Sun | B9: 03:30 | C9: 2 | D9: 5 | E9: 2.5 | F9: 4.5 | G9: 2.25 | H9: 5 | I9: 4 | J9: PASS
A10: Sun | B10: 04:00 | C10: 3 | D10: 6 | E10: 2 | F10: 5 | G10: 1.666667 | H10: 6 | I10: 5 | J10: PASS
A11: Sun | B11: 04:30 | C11: 2 | D11: 6 | E11: 3 | F11: 5.5 | G11: 2.75 | H11: 6 | I11: 5 | J11: PASS
A12: Sun | B12: 05:00 | C12: 2 | D12: 8 | E12: 4 | F12: 7 | G12: 3.5 | H12: 8 | I12: 7 | J12: PASS
A13: Sun | B13: 05:30 | C13: 2 | D13: 8 | E13: 4 | F13: 7 | G13: 3.5 | H13: 8 | I13: 7 | J13: PASS
... A265: Sat | B265: 01:30 | C265: 6 | D265: 11.266667 | E265: 1.877778 | F265: 11.266667 | G265: 1.877778 | H265: 13 | I265: 13 | J265: PASS

Sheet Overage Audit
A1: Day | B1: Interval | C1: Required | D1: Shrinkage | E1: Minimum Raw For Target | F1: Unavoidable Effective At Target | G1: Soft Effective Threshold | H1: Severe Effective Threshold | I1: Extreme Effective Threshold | J1: Before Effective | K1: Before % | L1: Before Target Overage | M1: Before Avoidable Overage | N1: After Effective | O1: After % | P1: After Target Overage | Q1: After Avoidable Overage | R1: Indivisible Staffing Only | S1: Soft Overage | T1: Severe Overage | U1: Extreme Overage | V1: Operational Classification
A2: Sun | B2: 00:00 | C2: 2 | D2: 0.3 | E2: 3 | F2: 2.1 | G2: 2.2 | H2: 2.4 | I2: 2.8 | J2: 2.1 | K2: 1.05 | L2: 0.1 | M2: 0 | N2: 2.1 | O2: 1.05 | P2: 0.1 | Q2: 0 | R2: TRUE | S2: FALSE | T2: FALSE | U2: FALSE | V2: INDIVISIBLE WHOLE-ASSOCIATE STAFFING
A3: Sun | B3: 00:30 | C3: 2 | D3: 0.3 | E3: 3 | F3: 2.1 | G3: 2.2 | H3: 2.4 | I3: 2.8 | J3: 2.1 | K3: 1.05 | L3: 0.1 | M3: 0 | N3: 2.1 | O3: 1.05 | P3: 0.1 | Q3: 0 | R3: TRUE | S3: FALSE | T3: FALSE | U3: FALSE | V3: INDIVISIBLE WHOLE-ASSOCIATE STAFFING
A4: Sun | B4: 01:00 | C4: 2 | D4: 0.3 | E4: 3 | F4: 2.1 | G4: 2.2 | H4: 2.4 | I4: 2.8 | J4: 2.8 | K4: 1.4 | L4: 0.8 | M4: 0.7 | N4: 2.45 | O4: 1.225 | P4: 0.45 | Q4: 0.35 | R4: FALSE | S4: TRUE | T4: TRUE | U4: FALSE | V4: TRANSFERABLE / REVIEW
A5: Sun | B5: 01:30 | C5: 2 | D5: 0.3 | E5: 3 | F5: 2.1 | G5: 2.2 | H5: 2.4 | I5: 2.8 | J5: 2.8 | K5: 1.4 | L5: 0.8 | M5: 0.7 | N5: 2.8 | O5: 1.4 | P5: 0.8 | Q5: 0.7 | R5: FALSE | S5: TRUE | T5: TRUE | U5: FALSE | V5: TRANSFERABLE / REVIEW
A6: Sun | B6: 02:00 | C6: 2 | D6: 0.2 | E6: 3 | F6: 2.4 | G6: 2.4 | H6: 2.4 | I6: 2.8 | J6: 3.2 | K6: 1.6 | L6: 1.2 | M6: 0.8 | N6: 2.8 | O6: 1.4 | P6: 0.8 | Q6: 0.4 | R6: FALSE | S6: TRUE | T6: TRUE | U6: FALSE | V6: TRANSFERABLE / REVIEW
A7: Sun | B7: 02:30 | C7: 3 | D7: 0.2 | E7: 4 | F7: 3.2 | G7: 3.3 | H7: 3.6 | I7: 4.2 | J7: 3.2 | K7: 1.066667 | L7: 0.2 | M7: 0 | N7: 3.2 | O7: 1.066667 | P7: 0.2 | Q7: 0 | R7: TRUE | S7: FALSE | T7: FALSE | U7: FALSE | V7: INDIVISIBLE WHOLE-ASSOCIATE STAFFING
A8: Sun | B8: 03:00 | C8: 2 | D8: 0 | E8: 2 | F8: 2 | G8: 2.2 | H8: 2.4 | I8: 2.8 | J8: 5 | K8: 2.5 | L8: 3 | M8: 3 | N8: 4.5 | O8: 2.25 | P8: 2.5 | Q8: 2.5 | R8: FALSE | S8: TRUE | T8: TRUE | U8: TRUE | V8: TRANSFERABLE / REVIEW
A9: Sun | B9: 03:30 | C9: 2 | D9: 0 | E9: 2 | F9: 2 | G9: 2.2 | H9: 2.4 | I9: 2.8 | J9: 5 | K9: 2.5 | L9: 3 | M9: 3 | N9: 4.5 | O9: 2.25 | P9: 2.5 | Q9: 2.5 | R9: FALSE | S9: TRUE | T9: TRUE | U9: TRUE | V9: TRANSFERABLE / REVIEW
A10: Sun | B10: 04:00 | C10: 3 | D10: 0 | E10: 3 | F10: 3 | G10: 3.3 | H10: 3.6 | I10: 4.2 | J10: 6 | K10: 2 | L10: 3 | M10: 3 | N10: 5 | O10: 1.666667 | P10: 2 | Q10: 2 | R10: FALSE | S10: TRUE | T10: TRUE | U10: TRUE | V10: TRANSFERABLE / REVIEW
A11: Sun | B11: 04:30 | C11: 2 | D11: 0 | E11: 2 | F11: 2 | G11: 2.2 | H11: 2.4 | I11: 2.8 | J11: 6 | K11: 3 | L11: 4 | M11: 4 | N11: 5.5 | O11: 2.75 | P11: 3.5 | Q11: 3.5 | R11: FALSE | S11: TRUE | T11: TRUE | U11: TRUE | V11: TRANSFERABLE / REVIEW
A12: Sun | B12: 05:00 | C12: 2 | D12: 0 | E12: 2 | F12: 2 | G12: 2.2 | H12: 2.4 | I12: 2.8 | J12: 8 | K12: 4 | L12: 6 | M12: 6 | N12: 7 | O12: 3.5 | P12: 5 | Q12: 5 | R12: FALSE | S12: TRUE | T12: TRUE | U12: TRUE | V12: TRANSFERABLE / REVIEW
A13: Sun | B13: 05:30 | C13: 2 | D13: 0 | E13: 2 | F13: 2 | G13: 2.2 | H13: 2.4 | I13: 2.8 | J13: 8 | K13: 4 | L13: 6 | M13: 6 | N13: 7 | O13: 3.5 | P13: 5 | Q13: 5 | R13: FALSE | S13: TRUE | T13: TRUE | U13: TRUE | V13: TRANSFERABLE / REVIEW
... A265: Sat | B265: 01:30 | C265: 6 | D265: 0.133333 | E265: 7 | F265: 6.066667 | G265: 6.6 | H265: 7.2 | I265: 8.4 | J265: 11.266667 | K265: 1.877778 | L265: 5.266667 | M265: 5.2 | N265: 11.266667 | O265: 1.877778 | P265: 5.266667 | Q265: 5.2 | R265: FALSE | S265: TRUE | T265: TRUE | U265: TRUE | V265: TRANSFERABLE / REVIEW

Sheet Next Sunday Carry-Out Audit
A1: Day | B1: Interval | C1: Protected Quarters | D1: Required FTE | E1: Shrinkage | F1: Before Effective FTE | G1: Before % | H1: After Effective FTE | I1: After % | J1: Before Raw Minimum | K1: Before Raw Maximum | L1: After Raw Minimum | M1: After Raw Maximum | N1: Active Demand | O1: Target Status | P1: Floor Status | Q1: Blank Staffing Status | R1: Contributing Associates | S1: Associates on Break
A2: Next Sun | B2: 00:00 | C2: 2 | D2: 2 | E2: 0.3 | F2: 2.1 | G2: 1.05 | H2: 2.1 | I2: 1.05 | J2: 3 | K2: 3 | L2: 3 | M2: 3 | N2: YES | O2: PASS | P2: PASS | Q2: NOT APPLICABLE | R2: Basmala Sweidan, Youssef Omara, Zyad Mahrous
A3: Next Sun | B3: 00:30 | C3: 2 | D3: 2 | E3: 0.3 | F3: 2.1 | G3: 1.05 | H3: 2.1 | I3: 1.05 | J3: 3 | K3: 3 | L3: 3 | M3: 3 | N3: YES | O3: PASS | P3: PASS | Q3: NOT APPLICABLE | R3: Basmala Sweidan, Youssef Omara, Zyad Mahrous
A4: Next Sun | B4: 01:00 | C4: 2 | D4: 2 | E4: 0.3 | F4: 2.8 | G4: 1.4 | H4: 2.45 | I4: 1.225 | J4: 4 | K4: 4 | L4: 3 | M4: 4 | N4: YES | O4: PASS | P4: PASS | Q4: NOT APPLICABLE | R4: Aya Elbamby, Basmala Sweidan, Youssef Omara, Zyad Mahrous | S4: Youssef Omara
A5: Next Sun | B5: 01:30 | C5: 2 | D5: 2 | E5: 0.3 | F5: 2.8 | G5: 1.4 | H5: 2.8 | I5: 1.4 | J5: 4 | K5: 4 | L5: 4 | M5: 4 | N5: YES | O5: PASS | P5: PASS | Q5: NOT APPLICABLE | R5: Aya Elbamby, Basmala Sweidan, Youssef Omara, Zyad Mahrous
A6: Next Sun | B6: 02:00 | C6: 2 | D6: 2 | E6: 0.2 | F6: 3.2 | G6: 1.6 | H6: 2.8 | I6: 1.4 | J6: 4 | K6: 4 | L6: 3 | M6: 4 | N6: YES | O6: PASS | P6: PASS | Q6: NOT APPLICABLE | R6: Aya Elbamby, Basmala Sweidan, Youssef Omara, Zyad Mahrous | S6: Zyad Mahrous
A7: Next Sun | B7: 02:30 | C7: 2 | D7: 3 | E7: 0.2 | F7: 3.2 | G7: 1.066667 | H7: 3.2 | I7: 1.066667 | J7: 4 | K7: 4 | L7: 4 | M7: 4 | N7: YES | O7: PASS | P7: PASS | Q7: NOT APPLICABLE | R7: Aya Elbamby, Basmala Sweidan, Youssef Omara, Zyad Mahrous
A8: Next Sun | B8: 03:00 | C8: 2 | D8: 2 | E8: 0 | F8: 5 | G8: 2.5 | H8: 4.5 | I8: 2.25 | J8: 5 | K8: 5 | L8: 4 | M8: 5 | N8: YES | O8: PASS | P8: PASS | Q8: NOT APPLICABLE | R8: Aya Elbamby, Basmala Sweidan, Sharmaine Magtoto, Youssef Omara, Zyad Mahrous | S8: Aya Elbamby
A9: Next Sun | B9: 03:30 | C9: 2 | D9: 2 | E9: 0 | F9: 5 | G9: 2.5 | H9: 4.5 | I9: 2.25 | J9: 5 | K9: 5 | L9: 4 | M9: 5 | N9: YES | O9: PASS | P9: PASS | Q9: NOT APPLICABLE | R9: Aya Elbamby, Basmala Sweidan, Sharmaine Magtoto, Youssef Omara, Zyad Mahrous | S9: Youssef Omara
A10: Next Sun | B10: 04:00 | C10: 2 | D10: 3 | E10: 0 | F10: 6 | G10: 2 | H10: 5 | I10: 1.666667 | J10: 6 | K10: 6 | L10: 5 | M10: 5 | N10: YES | O10: PASS | P10: PASS | Q10: NOT APPLICABLE | R10: Aya Elbamby, Basmala Sweidan, Jojie Lovino, Sharmaine Magtoto, Youssef Omara, Zyad Mahrous | S10: Youssef Omara, Zyad Mahrous
A11: Next Sun | B11: 04:30 | C11: 2 | D11: 2 | E11: 0 | F11: 6 | G11: 3 | H11: 5.5 | I11: 2.75 | J11: 6 | K11: 6 | L11: 5 | M11: 6 | N11: YES | O11: PASS | P11: PASS | Q11: NOT APPLICABLE | R11: Aya Elbamby, Basmala Sweidan, Jojie Lovino, Sharmaine Magtoto, Youssef Omara, Zyad Mahrous | S11: Zyad Mahrous
A12: Next Sun | B12: 05:00 | C12: 2 | D12: 2 | E12: 0 | F12: 8 | G12: 4 | H12: 7 | I12: 3.5 | J12: 8 | K12: 8 | L12: 7 | M12: 7 | N12: YES | O12: PASS | P12: PASS | Q12: NOT APPLICABLE | R12: Aya Elbamby, Basmala Sweidan, Jhonny Mascarenhas, Jojie Lovino, Meraj Shaikh, Sharmaine Magtoto, Youssef Omara, Zyad Mahrous | S12: Basmala Sweidan, Sharmaine Magtoto
A13: Next Sun | B13: 05:30 | C13: 2 | D13: 2 | E13: 0 | F13: 8 | G13: 4 | H13: 7 | I13: 3.5 | J13: 8 | K13: 8 | L13: 7 | M13: 7 | N13: YES | O13: PASS | P13: PASS | Q13: NOT APPLICABLE | R13: Aya Elbamby, Basmala Sweidan, Jhonny Mascarenhas, Jojie Lovino, Meraj Shaikh, Sharmaine Magtoto, Youssef Omara, Zyad Mahrous | S13: Jojie Lovino, Meraj Shaikh
A14: Next Sun | B14: 06:00 | C14: 2 | D14: 2 | E14: 0 | F14: 8 | G14: 4 | H14: 6.5 | I14: 3.25 | J14: 8 | K14: 8 | L14: 6 | M14: 7 | N14: YES | O14: PASS | P14: PASS | Q14: NOT APPLICABLE | R14: Aya Elbamby, Basmala Sweidan, Jhonny Mascarenhas, Jojie Lovino, Meraj Shaikh, Sharmaine Magtoto, Youssef Omara, Zyad Mahrous | S14: Aya Elbamby, Basmala Sweidan
A15: Next Sun | B15: 06:30 | C15: 2 | D15: 2 | E15: 0 | F15: 8 | G15: 4 | H15: 6.5 | I15: 3.25 | J15: 8 | K15: 8 | L15: 6 | M15: 7 | N15: YES | O15: PASS | P15: PASS | Q15: NOT APPLICABLE | R15: Aya Elbamby, Basmala Sweidan, Jhonny Mascarenhas, Jojie Lovino, Meraj Shaikh, Sharmaine Magtoto, Youssef Omara, Zyad Mahrous | S15: Basmala Sweidan, Jhonny Mascarenhas, Youssef Omara
A16: Next Sun | B16: 07:00 | C16: 2 | D16: 3 | E16: 0 | F16: 8 | G16: 2.666667 | H16: 7.5 | I16: 2.5 | J16: 8 | K16: 8 | L16: 7 | M16: 8 | N16: YES | O16: PASS | P16: PASS | Q16: NOT APPLICABLE | R16: Aya Elbamby, Basmala Sweidan, Jhonny Mascarenhas, Jojie Lovino, Meraj Shaikh, Sharmaine Magtoto, Youssef Omara, Zyad Mahrous | S16: Zyad Mahrous
A17: Next Sun | B17: 07:30 | C17: 2 | D17: 2 | E17: 0 | F17: 8 | G17: 4 | H17: 6.5 | I17: 3.25 | J17: 8 | K17: 8 | L17: 6 | M17: 7 | N17: YES | O17: PASS | P17: PASS | Q17: NOT APPLICABLE | R17: Aya Elbamby, Basmala Sweidan, Jhonny Mascarenhas, Jojie Lovino, Meraj Shaikh, Sharmaine Magtoto, Youssef Omara, Zyad Mahrous | S17: Basmala Sweidan, Sharmaine Magtoto

Sheet Canonical Contract
A1: Contract Field | B1: Canonical Value
A2: Engine Version | B2: L6.3.2.8-RC9.2.2-PRODUCTION-HARDENED-RC6
A3: Named Roster Count | B3: 33
A4: Instructed Headcount | B4: 33
A5: Headcount Mismatch Allowed | B5: FALSE
A6: Interval Minutes | B6: 30
A7: Requirement Sheet | B7: FT Wise 30 Min
A8: Shrinkage Sheet | B8: Shrinkage 30 Min
A9: Program Name | B9: Cricut_Voice
A10: Target Ratio | B10: 1
A11: Target Priority Confirmed | B11: TRUE
A12: Configured Floor Ratio | B12: 0.8
A13: Overage Control Enabled | B13: TRUE
A14: Overage Soft Cap | B14: 1.1
A15: Overage Severe Cap | B15: 1.2
A16: Overage Extreme Cap | B16: 1.4
A17: Overage Penalty Weight | B17: 40
A18: Minimum Best Before Target
A19: Minimum Final Before Target
A20: Quality Benchmark Tolerance | B20: 0
A21: Floor Mode | B21: protected
A22: Hard Floor Ratio | B22: Not hard
A23: Hard Floor Source | B23: Protected floor only
A24: Allowed Shift Durations Minutes | B24: 540
A25: Allowed Shift Start Window | B25: Unrestricted
A26: Shift Start Step Minutes | B26: 1
A27: Legal Shift Count | B27: 24
A28: 11H / 3OFF Enabled | B28: FALSE
A29: Blank Requirement Mode | B29: hard_no_current_week_staffing
A30: Blank Requirement Text | B30: No new staffing in blank intervals
A31: Demand Fit Guard Mode | B31: auto
A32: Demand Fit Guard Effective | B32: TRUE
A33: Opening Guard Enabled | B33: FALSE
A34: Opening Minimum | B34: 1
A35: Opening Intervals | B35: 1
A36: Break Window Source | B36: instructions
A37: No-Break Exceptions Allowed | B37: FALSE
A38: Maximum No-Break Exceptions | B38: 0
A39: Whole Week Balance Enabled | B39: TRUE
A40: Whole Week Overage Cap | B40: 1.35
...

Sheet Rest Gap Audit
A1: Associate | B1: From Day | C1: To Day | D1: From Shift | E1: To Shift | F1: Rest Hours | G1: Status
A2: Abdelrahman Abdelghani | B2: Sun | C2: Mon | D2: 16:00 - 01:00 | E2: 16:00 - 01:00 | F2: 15 | G2: PASS
A3: Abdelrahman Abdelghani | B3: Mon | C3: Tue | D3: 16:00 - 01:00 | E3: 16:00 - 01:00 | F3: 15 | G3: PASS
A4: Abdelrahman Abdelghani | B4: Thu | C4: Fri | D4: 16:00 - 01:00 | E4: 17:00 - 02:00 | F4: 16 | G4: PASS
A5: Kamal Aboaly | B5: Tue | C5: Wed | D5: 02:00 - 11:00 | E5: 18:00 - 03:00 | F5: 31 | G5: PASS
A6: Kamal Aboaly | B6: Wed | C6: Thu | D6: 18:00 - 03:00 | E6: 18:00 - 03:00 | F6: 15 | G6: PASS
A7: Kamal Aboaly | B7: Thu | C7: Fri | D7: 18:00 - 03:00 | E7: 17:00 - 02:00 | F7: 14 | G7: PASS
A8: Nadine Abdelrehiem | B8: Sun | C8: Mon | D8: 18:00 - 03:00 | E8: 18:00 - 03:00 | F8: 15 | G8: PASS
A9: Nadine Abdelrehiem | B9: Mon | C9: Tue | D9: 18:00 - 03:00 | E9: 16:00 - 01:00 | F9: 13 | G9: PASS
A10: Nadine Abdelrehiem | B10: Thu | C10: Fri | D10: 18:00 - 03:00 | E10: 17:00 - 02:00 | F10: 14 | G10: PASS
A11: Rowan Amir | B11: Sun | C11: Mon | D11: 16:00 - 01:00 | E11: 16:00 - 01:00 | F11: 15 | G11: PASS
A12: Rowan Amir | B12: Mon | C12: Tue | D12: 16:00 - 01:00 | E12: 16:00 - 01:00 | F12: 15 | G12: PASS
A13: Rowan Amir | B13: Tue | C13: Wed | D13: 16:00 - 01:00 | E13: 16:00 - 01:00 | F13: 15 | G13: PASS
... A114: Abdelrahman Saad | B114: Wed | C114: Thu | D114: 11:00 - 20:00 | E114: 11:00 - 20:00 | F114: 15 | G114: PASS

Sheet Language Skill Audit
A1: Scope | B1: Day | C1: Quarter | D1: Coverage Group | E1: Required Languages | F1: Eligible Source Languages | G1: Hard Minimum | H1: Operational Reserve Target | I1: Before Qualified | J1: After Qualified | K1: After Qualified Reserve | L1: Total After Raw | M1: Nonqualified After Raw | N1: Qualified Associates After | O1: Qualified Associates on Break | P1: Break Caused Reserve Loss | Q1: Status
D2: No active language rules | Q2: PASS

Sheet Language Reserve Summary
A1: Scope | B1: Coverage Group | C1: Required Languages | D1: Eligible Source Languages | E1: Hard Minimum | F1: Operational Reserve Target | G1: Protected Quarters | H1: Gap Quarters | I1: Minimum-Only Quarters | J1: Reserve-Protected Quarters | K1: Break-Caused Reserve Loss Quarters | L1: Minimum After Qualified | M1: Maximum After Qualified
B2: No active language rules | G2: 0 | H2: 0 | I2: 0 | J2: 0 | K2: 0

Sheet Skill Allocation Audit
A1: Day | B1: Quarter | C1: Active Skill Rules | D1: Required Distinct Skill Slots | E1: Matched Distinct Skill Slots | F1: Allocation Gap | G1: Available Associates | H1: Rule Eligibility | I1: Slot Assignment | J1: Status
C2: 0 | D2: 0 | E2: 0 | F2: 0 | G2: 0 | H2: No simultaneous skill minima | J2: PASS

Sheet Whole Week Balance Audit
A1: Day | B1: Previous Time | C1: Current Time | D1: Previous Raw | E1: Current Raw | F1: Raw Change | G1: Allowed Raw Change | H1: Status
A2: Sun | B2: 00:00 | C2: 00:15 | D2: 3 | E2: 3 | F2: 0 | G2: 3 | H2: PASS
A3: Sun | B3: 00:15 | C3: 00:30 | D3: 3 | E3: 3 | F3: 0 | G3: 3 | H3: PASS
A4: Sun | B4: 00:30 | C4: 00:45 | D4: 3 | E4: 3 | F4: 0 | G4: 3 | H4: PASS
A5: Sun | B5: 00:45 | C5: 01:00 | D5: 3 | E5: 3 | F5: 0 | G5: 3 | H5: PASS
A6: Sun | B6: 01:00 | C6: 01:15 | D6: 3 | E6: 4 | F6: 1 | G6: 3 | H6: PASS
A7: Sun | B7: 01:15 | C7: 01:30 | D7: 4 | E7: 4 | F7: 0 | G7: 3 | H7: PASS
A8: Sun | B8: 01:30 | C8: 01:45 | D8: 4 | E8: 4 | F8: 0 | G8: 3 | H8: PASS
A9: Sun | B9: 01:45 | C9: 02:00 | D9: 4 | E9: 3 | F9: 1 | G9: 3 | H9: PASS
A10: Sun | B10: 02:00 | C10: 02:15 | D10: 3 | E10: 4 | F10: 1 | G10: 3 | H10: PASS
A11: Sun | B11: 02:15 | C11: 02:30 | D11: 4 | E11: 4 | F11: 0 | G11: 3 | H11: PASS
A12: Sun | B12: 02:30 | C12: 02:45 | D12: 4 | E12: 4 | F12: 0 | G12: 3 | H12: PASS
A13: Sun | B13: 02:45 | C13: 03:00 | D13: 4 | E13: 5 | F13: 1 | G13: 3 | H13: PASS
... A521: Sat | B521: 01:30 | C521: 01:45 | D521: 13 | E521: 13 | F521: 0 | G521: 3 | H521: PASS

Sheet Employee Quality Audit
A1: Associate | B1: Max Start Swing Minutes | C1: Start Swing Status | D1: Isolated Workdays | E1: Isolated OFF Days | F1: Late Shifts | G1: Overnight Shifts | H1: Weekend Shifts | I1: Different Shifts | J1: Preference Count | K1: Preference Matches | L1: Preference Satisfaction
A2: Abdelrahman Abdelghani | B2: 60 | C2: PASS | D2: 0 | E2: 2 | F2: 0 | G2: 5 | H2: 1 | I2: 2 | J2: 0 | K2: 0 | L2: 0
A3: Kamal Aboaly | B3: 480 | C3: FAIL | D3: 1 | E3: 2 | F3: 4 | G3: 4 | H3: 1 | I3: 3 | J3: 0 | K3: 0 | L3: 0
A4: Nadine Abdelrehiem | B4: 120 | C4: PASS | D4: 0 | E4: 2 | F4: 3 | G4: 5 | H4: 1 | I4: 3 | J4: 0 | K4: 0 | L4: 0
A5: Rowan Amir | B5: 0 | C5: PASS | D5: 1 | E5: 2 | F5: 0 | G5: 5 | H5: 1 | I5: 2 | J5: 0 | K5: 0 | L5: 0
A6: Seif Alatar | B6: 120 | C6: PASS | D6: 0 | E6: 2 | F6: 2 | G6: 5 | H6: 1 | I6: 3 | J6: 0 | K6: 0 | L6: 0
A7: Abdelrahman Ahmed | B7: 120 | C7: PASS | D7: 1 | E7: 2 | F7: 2 | G7: 5 | H7: 1 | I7: 3 | J7: 0 | K7: 0 | L7: 0
A8: Adham Abdelmotaleb | B8: 120 | C8: PASS | D8: 0 | E8: 0 | F8: 4 | G8: 5 | H8: 1 | I8: 2 | J8: 0 | K8: 0 | L8: 0
A9: Ahmed Salouma | B9: 120 | C9: PASS | D9: 0 | E9: 2 | F9: 2 | G9: 5 | H9: 1 | I9: 3 | J9: 0 | K9: 0 | L9: 0
A10: Maram Abdelrahman | B10: 120 | C10: PASS | D10: 0 | E10: 0 | F10: 2 | G10: 5 | H10: 1 | I10: 2 | J10: 0 | K10: 0 | L10: 0
A11: Mariem Mohamed | B11: 0 | C11: PASS | D11: 0 | E11: 0 | F11: 0 | G11: 0 | H11: 0 | I11: 0 | J11: 7 | K11: 7 | L11: 1
A12: Mohamed Elkhouly | B12: 120 | C12: PASS | D12: 1 | E12: 2 | F12: 3 | G12: 5 | H12: 1 | I12: 3 | J12: 0 | K12: 0 | L12: 0
A13: Aya Elbamby | B13: 360 | C13: PASS | D13: 1 | E13: 2 | F13: 4 | G13: 4 | H13: 1 | I13: 3 | J13: 0 | K13: 0 | L13: 0
... A34: Abdelrahman Saad | B34: 0 | C34: PASS | D34: 0 | E34: 0 | F34: 0 | G34: 0 | H34: 1 | I34: 1 | J34: 0 | K34: 0 | L34: 0

Sheet Feasibility Certificate
A1: Metric | B1: Value
A2: Current Headcount | B2: 33
A3: Headcount Needed Including Breaks | B3: 33
A4: Additional Headcount Needed For Breaks | B4: 0
A5: Break Capacity Status | B5: BREAK_CAPACITY_SUFFICIENT
A6: Quarter Slots With No Spare Body | B6: 88
A7: Break Quarters With Nowhere To Go | B7: 0
A8: Headcount Verdict | B8: Headcount is not the constraint: 1031 lossless slots exist for 660 break-quarters. Whether a placement can use only that room also depends on break windows and spacing.
A9: Status | B9: PASS
A10: Target Attainability | B10: NOT_PROVEN_UNREACHABLE
A11: Floor Attainability | B11: NOT_PROVEN_UNREACHABLE
A12: Productive Hours Available | B12: 1272
A13: Target Hours Lower Bound | B13: 970.17896
A14: Floor Hours Lower Bound | B14: 776.14317
A15: Estimated Additional HC For Target | B15: 0
A16: Estimated Additional HC For Floor | B16: 0
A17: Maximum Achievable Target Intervals Upper Bound | B17: 264
A18: Maximum Achievable Floor Intervals Upper Bound | B18: 264

Sheet Language Setup
A1: Language / Skill Setup — Directional Coverage
A2: Language | B2: Coverage Start | C2: Coverage End | D2: Can Cover Languages | E2: Active? | F2: Coverage Group | G2: Minimum Per Interval | H2: Priority / Notes | I2: Cross-skilled? | J2: Coverage Days
A3: English | B3: 0.66666667 | C3: 0.125 | D3: English | E3: Yes | F3: English | G3: 0 | H3: Domestic hours: shifts start 16:00-02:45. | I3: No | J3: All
A4: International | B4: 0 | C4: 0.66666667 | D4: International, English | E4: Yes | F4: International | G4: 0 | H4: International hours: shifts start 00:00-15:45 (fixed requests start 00:00-05:00). | I4: No | J4: All

Sheet Preference
A1: Preference / OFF / Leave Requests
A2: Associate Name | B2: Language | C2: Sun | D2: Mon | E2: Tue | F2: Wed | G2: Thu | H2: Fri | I2: Sat | J2: Notes
A3: Mariem Mohamed | B3: English | C3: Leave | D3: Leave | E3: Leave | F3: Leave | G3: Leave | H3: OFF | I3: OFF
A4: Omar Ali | B4: English | F4: OFF | H4: Leave | I4: OFF

Sheet Instructions
A1: Settings for this schedule
A2: Fill the yellow Value cells. Every cell only accepts what the scheduler can use (pick from the list, or a number inside the allowed range). Blank = engine default.
B4: Instruction | C4: Value | D4: Help
A5: Case Setup
B6: Program Name | C6: Cricut_Voice | D6: Name printed on every output. Any text.
B7: Count of Associates | C7: 33 | D7: People on the Schedule tab. Start Here checks that the roster matches.
B8: Allow Headcount Mismatch | C8: No | D8: Yes only if the roster may differ from the count above on purpose.
B9: Interval Minutes | C9: 30 | D9: Size of one demand row: 15, 30 or 60 minutes.
B10: Requirements Source | C10: FT Wise 30 Min | D10: The demand tab to use. Must match Interval Minutes.
B11: Shrinkage Source | C11: Shrinkage 30 Min | D11: The shrinkage tab to use. Must match Interval Minutes.
A13: How To Run
B14: Run Stage | C14: Full Schedule | D14: Full Schedule = shifts and breaks. Before Breaks Only = shifts only, for a quick review.
B15: Run Depth | C15: Deep | D15: Quick is fastest. Deep and Overnight search longer for a better week.
B16: Shift Consistency Polish | D16: Blank = engine default. Yes = also write a 'more consistent' copy of the week when it keeps coverage. No = skip it.
A18: Coverage
B19: Target | C19: 1 | D19: Coverage goal for every interval. Type 0.9 or 90%.
B20: Target Priority Confirmed | C20: Yes | D20: Set Yes when a 100% target is intended.
B21: Minimum Per Interval | C21: 0.8 | D21: Lowest acceptable coverage in any interval (the floor). Type 0.8 or 80%.
B22: Hard Floor Solver Constraint Enabled | C22: No | D22: Yes = never below the floor (the week may become unsolvable). No = protect it as a priority.
B23: Blank Interval Staffing Rule | C23: No new staffing in blank intervals | D23: What to do in intervals that have no demand.
B24: Coverage Objective Weighting | C24: Interval Count | D24: Interval Count = most intervals at target. Volume Weighted = busy intervals count more (service level).
A26: Shift & OFF
B27: Allowed Shift Durations Hours | C27: 9 | D27: Shift lengths allowed. 10.5 h or more needs Use 11H/3OFF = Yes.
B28: Use 11H/3OFF | C28: No | D28: Yes = long-shift week with three OFF days.
B29: Strict OFF Count | C29: Yes | D29: Yes = exactly two OFF days (three with 11H/3OFF) per person.
B30: Separate OFF Days | C30: Yes | D30: Yes = a person's OFF days may be apart. No = they must be together.
B31: Rest Gap Hours | C31: 12 | D31: Minimum hours between the end of one shift and the start of the next.
B32: Count of Different Shifts Per week | C32: 3 | D32: Most different shifts one person may get in a week (1 to 7).
A34: Requests
B35: Fixed Request Use | C35: Yes | D35: Yes = apply the Fixed Request tab.
B36: Hard OFF Preferences | C36: Yes | D36: Yes = OFF requests on the Preference tab are always granted.
B37: Leave Enabled | C37: Yes | D37: Yes = Leave on the Preference tab is honoured.
B38: Use Preferences | C38: Yes | D38: Yes = try to give people their preferred shifts.
B39: Known Departed Associates | D39: Blank = engine default. Names on last week's tab who have left, separated by ; (Start Here lists any missing).
A41: Opening Guard (click + on the left to open)
B42: Opening Guard Enabled | C42: No | D42: Yes = keep enough people on at the start of each day.
B43: Opening Minimum FTE | C43: 1 | D43: People needed at opening (whole number).
B44: Opening Guard Intervals | C44: 1 | D44: How many opening intervals the guard covers.
A46: Breaks
B47: Short Break Count | C47: 2 | D47: Short breaks per shift.
...

Sheet Candidate Leaderboard
A1: Skeleton Profile | B1: Break Profile | C1: Objective Mode | D1: CP Status | E1: Pattern Width | F1: Exception Count | G1: After Target | H1: After Floor | I1: After Hard Floor | J1: After100 | K1: After90 | L1: After80 | M1: Before Target | N1: Before Floor | O1: Before Hard Floor | P1: Before100 | Q1: Before90 | R1: Before80 | S1: Floor Gaps | T1: Hard Floor Gaps | U1: Next Sunday After Target | V1: Next Sunday After Floor | W1: Next Sunday Floor Gaps | X1: Next Sunday Zero Quarters | Y1: Next Sunday Language Gaps | Z1: Next Sunday Opening Gaps | AA1: Next Sunday Blank Staffed Quarters | AB1: Severe Floor Gaps | AC1: Max Floor Run | AD1: Floor Deficit Sum | AE1: Target Deficit Sum | AF1: Target Losses From Breaks | AG1: Floor Losses From Breaks | AH1: Before Target Overage | AI1: After Target Overage | AJ1: Before Avoidable Overage | AK1: After Avoidable Overage | AL1: Before Severe Overage | AM1: After Severe Overage | AN1: Before Extreme Overage | AO1: After Extreme Overage | AP1: Objective | AQ1: Selected Role | AR1: Selected | AS1: Break Capacity Status | AT1: Break Quarters With Nowhere To Go | AU1: Headcount Needed Including Breaks | AV1: Additional Headcount Needed
A2: target_floor_pareto_master | B2: fully_compliant_target_priority | C2: target_priority | D2: FEASIBLE | E2: 115 | F2: 0 | G2: 245 | H2: 254 | I2: 0 | J2: 245 | K2: 247 | L2: 254 | M2: 247 | N2: 254 | O2: 0 | P2: 247 | Q2: 250 | R2: 254 | S2: 10 | T2: 0 | U2: 16 | V2: 16 | W2: 0 | X2: 0 | Y2: 0 | Z2: 0 | AA2: 0 | AB2: 8 | AC2: 2 | AD2: 3.1676883 | AE2: 6.3157236 | AF2: 2 | AG2: 0 | AH2: 936.9975 | AI2: 647.79377 | AJ2: 877.63722 | AK2: 590.15622 | AL2: 210 | AM2: 186 | AN2: 172 | AO2: 113 | AP2: 1350256644
A3: target_floor_pareto_master | B3: fully_compliant_lexicographic_target | C3: lexicographic_target | D3: FEASIBLE | E3: 115 | F3: 0 | G3: 245 | H3: 254 | I3: 0 | J3: 245 | K3: 247 | L3: 254 | M3: 247 | N3: 254 | O3: 0 | P3: 247 | Q3: 250 | R3: 254 | S3: 10 | T3: 0 | U3: 16 | V3: 16 | W3: 0 | X3: 0 | Y3: 0 | Z3: 0 | AA3: 0 | AB3: 8 | AC3: 2 | AD3: 3.1676883 | AE3: 6.3157236 | AF3: 2 | AG3: 0 | AH3: 936.9975 | AI3: 647.77922 | AJ3: 877.63722 | AK3: 590.14167 | AL3: 210 | AM3: 186 | AN3: 172 | AO3: 113 | AP3: 21079830190 | AQ3: MAX_FLOOR_CANDIDATE | AR3: YES
A4: target_floor_pareto_master | B4: fully_compliant_coverage_rebalance | C4: coverage_rebalance | D4: FEASIBLE | E4: 115 | F4: 0 | G4: 245 | H4: 254 | I4: 0 | J4: 245 | K4: 247 | L4: 254 | M4: 247 | N4: 254 | O4: 0 | P4: 247 | Q4: 250 | R4: 254 | S4: 10 | T4: 0 | U4: 16 | V4: 16 | W4: 0 | X4: 0 | Y4: 0 | Z4: 0 | AA4: 0 | AB4: 8 | AC4: 2 | AD4: 3.1676883 | AE4: 6.3157236 | AF4: 2 | AG4: 0 | AH4: 936.9975 | AI4: 647.77922 | AJ4: 877.63722 | AK4: 590.14167 | AL4: 210 | AM4: 186 | AN4: 172 | AO4: 114 | AP4: 4040616198 | AQ4: MAX_TARGET_CANDIDATE | AR4: YES
A5: target90_restore_champion | B5: fully_compliant_target_priority | C5: target_priority | D5: FEASIBLE | E5: 115 | F5: 0 | G5: 245 | H5: 253 | I5: 0 | J5: 245 | K5: 247 | L5: 253 | M5: 248 | N5: 253 | O5: 0 | P5: 248 | Q5: 251 | R5: 253 | S5: 11 | T5: 0 | U5: 16 | V5: 16 | W5: 0 | X5: 0 | Y5: 0 | Z5: 0 | AA5: 0 | AB5: 10 | AC5: 2 | AD5: 3.6060269 | AE5: 6.7676816 | AF5: 3 | AG5: 0 | AH5: 934.04783 | AI5: 646.52299 | AJ5: 874.56755 | AK5: 591.66415 | AL5: 213 | AM5: 185 | AN5: 174 | AO5: 124 | AP5: 1321966904
A6: target90_restore_champion | B6: fully_compliant_target_priority | C6: target_priority | D6: FEASIBLE | E6: 115 | F6: 0 | G6: 244 | H6: 252 | I6: 0 | J6: 244 | K6: 247 | L6: 252 | M6: 248 | N6: 253 | O6: 0 | P6: 248 | Q6: 251 | R6: 253 | S6: 12 | T6: 0 | U6: 16 | V6: 16 | W6: 0 | X6: 0 | Y6: 0 | Z6: 0 | AA6: 0 | AB6: 11 | AC6: 2 | AD6: 3.622607 | AE6: 6.9804738 | AF6: 4 | AG6: 1 | AH6: 934.04783 | AI6: 645.93028 | AJ6: 874.56755 | AK6: 590.18427 | AL6: 213 | AM6: 187 | AN6: 174 | AO6: 122 | AP6: 1345961958
A7: target90_restore_champion | B7: fully_compliant_target_priority | C7: target_priority | D7: FEASIBLE | E7: 115 | F7: 0 | G7: 244 | H7: 252 | I7: 0 | J7: 244 | K7: 246 | L7: 252 | M7: 248 | N7: 253 | O7: 0 | P7: 248 | Q7: 251 | R7: 253 | S7: 12 | T7: 0 | U7: 16 | V7: 16 | W7: 0 | X7: 0 | Y7: 0 | Z7: 0 | AA7: 0 | AB7: 12 | AC7: 2 | AD7: 4.0610342 | AE7: 7.5658297 | AF7: 4 | AG7: 1 | AH7: 934.04783 | AI7: 655.67394 | AJ7: 874.56755 | AK7: 601.94658 | AL7: 213 | AM7: 172 | AN7: 174 | AO7: 131 | AP7: 2407962302
A8: target90_restore_productive | B8: fully_compliant_target_priority | C8: target_priority | D8: FEASIBLE | E8: 115 | F8: 0 | G8: 242 | H8: 250 | I8: 0 | J8: 242 | K8: 247 | L8: 250 | M8: 245 | N8: 250 | O8: 0 | P8: 245 | Q8: 248 | R8: 250 | S8: 14 | T8: 0 | U8: 16 | V8: 16 | W8: 0 | X8: 0 | Y8: 0 | Z8: 0 | AA8: 0 | AB8: 12 | AC8: 2 | AD8: 3.0804093 | AE8: 6.6005845 | AF8: 3 | AG8: 0 | AH8: 933.02566 | AI8: 643.29275 | AJ8: 873.58606 | AK8: 586.27133 | AL8: 214 | AM8: 195 | AN8: 183 | AO8: 126 | AP8: 1323784250
A9: deterministic_target_baseline | B9: fully_compliant_target_priority | C9: target_priority | D9: FEASIBLE | E9: 115 | F9: 0 | G9: 242 | H9: 249 | I9: 0 | J9: 242 | K9: 242 | L9: 249 | M9: 245 | N9: 249 | O9: 0 | P9: 245 | Q9: 245 | R9: 249 | S9: 15 | T9: 0 | U9: 16 | V9: 16 | W9: 0 | X9: 0 | Y9: 0 | Z9: 0 | AA9: 0 | AB9: 8 | AC9: 2 | AD9: 2.6706864 | AE9: 6.666646 | AF9: 3 | AG9: 0 | AH9: 938.14047 | AI9: 646.72057 | AJ9: 878.61516 | AK9: 589.36344 | AL9: 216 | AM9: 182 | AN9: 170 | AO9: 124 | AP9: 1335594556
A10: deterministic_target_baseline | B10: fully_compliant_target_priority | C10: target_priority | D10: FEASIBLE | E10: 115 | F10: 0 | G10: 242 | H10: 247 | I10: 0 | J10: 242 | K10: 243 | L10: 247 | M10: 245 | N10: 249 | O10: 0 | P10: 245 | Q10: 245 | R10: 249 | S10: 17 | T10: 0 | U10: 16 | V10: 16 | W10: 0 | X10: 0 | Y10: 0 | Z10: 0 | AA10: 0 | AB10: 9 | AC10: 2 | AD10: 3.041466 | AE10: 7.0808072 | AF10: 3 | AG10: 2 | AH10: 938.14047 | AI10: 653.75887 | AJ10: 878.61516 | AK10: 596.82027 | AL10: 216 | AM10: 174 | AN10: 170 | AO10: 126 | AP10: 1867066396
A11: target90_restore_productive | B11: fully_compliant_target_priority | C11: target_priority | D11: FEASIBLE | E11: 115 | F11: 0 | G11: 241 | H11: 247 | I11: 0 | J11: 241 | K11: 245 | L11: 247 | M11: 245 | N11: 250 | O11: 0 | P11: 245 | Q11: 248 | R11: 250 | S11: 17 | T11: 0 | U11: 16 | V11: 16 | W11: 0 | X11: 0 | Y11: 0 | Z11: 0 | AA11: 0 | AB11: 16 | AC11: 2 | AD11: 3.7973126 | AE11: 7.7182055 | AF11: 4 | AG11: 3 | AH11: 933.02566 | AI11: 651.79654 | AJ11: 873.58606 | AK11: 594.12058 | AL11: 214 | AM11: 187 | AN11: 183 | AO11: 126 | AP11: 2047493028
A12: daily_floor_balanced | B12: fully_compliant_target_priority | C12: target_priority | D12: FEASIBLE | E12: 115 | F12: 0 | G12: 240 | H12: 253 | I12: 0 | J12: 240 | K12: 247 | L12: 253 | M12: 243 | N12: 253 | O12: 0 | P12: 243 | Q12: 251 | R12: 253 | S12: 11 | T12: 0 | U12: 16 | V12: 16 | W12: 0 | X12: 0 | Y12: 0 | Z12: 0 | AA12: 0 | AB12: 10 | AC12: 2 | AD12: 2.9848966 | AE12: 6.6399669 | AF12: 3 | AG12: 0 | AH12: 929.18604 | AI12: 642.46635 | AJ12: 871.69917 | AK12: 586.9522 | AL12: 216 | AM12: 188 | AN12: 181 | AO12: 135 | AP12: 1292917518
A13: hard_feasibility_probe | B13: fully_compliant_target_priority | C13: target_priority | D13: FEASIBLE | E13: 24 | F13: 0 | G13: 240 | H13: 249 | I13: 0 | J13: 240 | K13: 242 | L13: 249 | M13: 244 | N13: 249 | O13: 0 | P13: 244 | Q13: 244 | R13: 249 | S13: 15 | T13: 0 | U13: 15 | V13: 16 | W13: 0 | X13: 0 | Y13: 0 | Z13: 0 | AA13: 0 | AB13: 10 | AC13: 2 | AD13: 2.1415527 | AE13: 6.3803589 | AF13: 4 | AG13: 0 | AH13: 931.21419 | AI13: 642.93156 | AJ13: 871.88887 | AK13: 586.4517 | AL13: 219 | AM13: 186 | AN13: 177 | AO13: 127 | AP13: 1383744836
A14: target_floor_pareto_master | B14: fully_compliant_target_priority | C14: target_priority | D14: FEASIBLE | E14: 115 | F14: 0 | G14: 238 | H14: 250 | I14: 0 | J14: 238 | K14: 243 | L14: 250 | M14: 247 | N14: 254 | O14: 0 | P14: 247 | Q14: 250 | R14: 254 | S14: 14 | T14: 0 | U14: 16 | V14: 16 | W14: 0 | X14: 0 | Y14: 0 | Z14: 0 | AA14: 0 | AB14: 10 | AC14: 2 | AD14: 3.4868309 | AE14: 7.4587987 | AF14: 9 | AG14: 4 | AH14: 936.9975 | AI14: 654.5312 | AJ14: 877.63722 | AK14: 599.4968 | AL14: 210 | AM14: 180 | AN14: 172 | AO14: 127 | AP14: 1925801032
A15: aggregate_floor_binding | B15: fully_compliant_coverage_rebalance | C15: coverage_rebalance | D15: FEASIBLE | E15: 115 | F15: 0 | G15: 237 | H15: 253 | I15: 0 | J15: 237 | K15: 244 | L15: 253 | M15: 239 | N15: 256 | O15: 0 | P15: 239 | Q15: 252 | R15: 256 | S15: 11 | T15: 0 | U15: 16 | V15: 16 | W15: 0 | X15: 0 | Y15: 0 | Z15: 0 | AA15: 0 | AB15: 8 | AC15: 2 | AD15: 3.2885786 | AE15: 7.4552492 | AF15: 2 | AG15: 3 | AH15: 942.62365 | AI15: 663.43987 | AJ15: 885.89391 | AK15: 608.29195 | AL15: 209 | AM15: 162 | AN15: 165 | AO15: 125 | AP15: 5690037734
A16: floor_gate_hunter_productive | B16: fully_compliant_coverage_rebalance | C16: coverage_rebalance | D16: FEASIBLE | E16: 115 | F16: 0 | G16: 236 | H16: 254 | I16: 0 | J16: 236 | K16: 249 | L16: 254 | M16: 241 | N16: 255 | O16: 0 | P16: 241 | Q16: 255 | R16: 255 | S16: 10 | T16: 0 | U16: 16 | V16: 16 | W16: 0 | X16: 0 | Y16: 0 | Z16: 0 | AA16: 0 | AB16: 10 | AC16: 2 | AD16: 3.7451515 | AE16: 7.2916429 | AF16: 5 | AG16: 1 | AH16: 936.68814 | AI16: 653.70616 | AJ16: 878.78427 | AK16: 599.15543 | AL16: 215 | AM16: 185 | AN16: 179 | AO16: 127 | AP16: 4687457416
... A26: deterministic_target_baseline | B26: fully_compliant_diagnostic_fallback | C26: diagnostic_zero_exception_fallback | D26: OPTIMAL | E26: 115 | F26: 0 | G26: 215 | H26: 234 | I26: 0 | J26: 215 | K26: 227 | L26: 234 | M26: 245 | N26: 249 | O26: 0 | P26: 245 | Q26: 245 | R26: 249 | S26: 30 | T26: 0 | U26: 15 | V26: 16 | W26: 0 | X26: 0 | Y26: 0 | Z26: 0 | AA26: 0 | AB26: 21 | AC26: 3 | AD26: 5.6697412 | AE26: 13.202673 | AF26: 30 | AG26: 15 | AH26: 938.14047 | AI26: 699.1494 | AJ26: 878.61516 | AK26: 650.22555 | AL26: 216 | AM26: 183 | AN26: 170 | AO26: 139 | AP26: 3198

Sheet Target Tradeoff Audit
A1: Skeleton | B1: Break Profile | C1: Objective Mode | D1: Width | E1: Target Ratio | F1: After Target | G1: After Floor | H1: After100 | I1: After90 | J1: After80 | K1: Floor Loss vs Best | L1: Target Gain vs Floor Anchor | M1: Severe Floor Gaps | N1: Max Floor Run | O1: Maximum Floor Deficit | P1: Tradeoff Cap | Q1: Risk OK | R1: Accepted
A2: hard_feasibility_probe | B2: fully_compliant_target_priority | C2: target_priority | D2: 24 | E2: 1 | F2: 240 | G2: 249 | H2: 240 | I2: 242 | J2: 249 | K2: 5 | L2: 4 | M2: 10 | N2: 2 | O2: 0.29090909 | P2: 1 | Q2: TRUE | R2: TRUE
A3: target90_restore_champion | B3: fully_compliant_target_priority | C3: target_priority | D3: 115 | E3: 1 | F3: 244 | G3: 252 | H3: 244 | I3: 246 | J3: 252 | K3: 2 | L3: 8 | M3: 12 | N3: 2 | O3: 0.54545455 | P3: 1 | Q3: FALSE | R3: FALSE
A4: target_floor_pareto_master | B4: fully_compliant_target_priority | C4: target_priority | D4: 115 | E4: 1 | F4: 238 | G4: 250 | H4: 238 | I4: 243 | J4: 250 | K4: 4 | L4: 2 | M4: 10 | N4: 2 | O4: 0.54545455 | P4: 1 | Q4: FALSE | R4: FALSE
A5: target90_restore_productive | B5: fully_compliant_target_priority | C5: target_priority | D5: 115 | E5: 1 | F5: 241 | G5: 247 | H5: 241 | I5: 245 | J5: 247 | K5: 7 | L5: 5 | M5: 16 | N5: 2 | O5: 0.4 | P5: 1 | Q5: FALSE | R5: FALSE
A6: deterministic_target_baseline | B6: fully_compliant_target_priority | C6: target_priority | D6: 115 | E6: 1 | F6: 242 | G6: 247 | H6: 242 | I6: 243 | J6: 247 | K6: 7 | L6: 6 | M6: 9 | N6: 2 | O6: 0.41481481 | P6: 1 | Q6: FALSE | R6: FALSE
A7: floor_gate_hunter_before | B7: fully_compliant_coverage_rebalance | C7: coverage_rebalance | D7: 115 | E7: 1 | F7: 219 | G7: 251 | H7: 219 | I7: 231 | J7: 251 | K7: 3 | L7: -17 | M7: 8 | N7: 3 | O7: 0.49090909 | P7: 1 | Q7: FALSE | R7: FALSE
A8: release_gate_floor_satisfaction | B8: fully_compliant_quality_convergence | C8: quality_convergence | D8: 115 | E8: 1 | F8: 217 | G8: 247 | H8: 217 | I8: 225 | J8: 247 | K8: 7 | L8: -19 | M8: 6 | N8: 2 | O8: 0.61818182 | P8: 1 | Q8: TRUE | R8: TRUE
A9: release_gate_floor_satisfaction | B9: fully_compliant_floor_protected | C9: floor_protected | D9: 115 | E9: 1 | F9: 217 | G9: 252 | H9: 217 | I9: 231 | J9: 252 | K9: 2 | L9: -19 | M9: 7 | N9: 2 | O9: 0.58181818 | P9: 1 | Q9: TRUE | R9: TRUE
A10: aggregate_floor_binding | B10: fully_compliant_coverage_rebalance | C10: coverage_rebalance | D10: 115 | E10: 1 | F10: 237 | G10: 253 | H10: 237 | I10: 244 | J10: 253 | K10: 1 | L10: 1 | M10: 8 | N10: 2 | O10: 0.61 | P10: 1 | Q10: FALSE | R10: FALSE
A11: aggregate_floor_binding | B11: fully_compliant_quality_convergence | C11: quality_convergence | D11: 115 | E11: 1 | F11: 230 | G11: 253 | H11: 230 | I11: 240 | J11: 253 | K11: 1 | L11: -6 | M11: 9 | N11: 3 | O11: 0.65454545 | P11: 1 | Q11: FALSE | R11: FALSE
A12: aggregate_floor_binding | B12: fully_compliant_floor_protected | C12: floor_protected | D12: 115 | E12: 1 | F12: 235 | G12: 253 | H12: 235 | I12: 242 | J12: 253 | K12: 1 | L12: -1 | M12: 9 | N12: 3 | O12: 0.58181818 | P12: 1 | Q12: FALSE | R12: FALSE
A13: floor_gate_hunter_productive | B13: fully_compliant_coverage_rebalance | C13: coverage_rebalance | D13: 115 | E13: 1 | F13: 236 | G13: 254 | H13: 236 | I13: 249 | J13: 254 | K13: 0 | L13: 0 | M13: 10 | N13: 2 | O13: 0.61 | P13: 1 | Q13: TRUE | R13: TRUE
... A35: target_floor_pareto_master | B35: fully_compliant_coverage_rebalance | C35: coverage_rebalance | D35: 115 | E35: 1 | F35: 245 | G35: 254 | H35: 245 | I35: 247 | J35: 254 | K35: 0 | L35: 0 | M35: 8 | N35: 2 | O35: 0.50909091 | P35: 1 | Q35: TRUE | R35: TRUE

Sheet Feasibility Report
A1: Category | B1: Item | C1: Value / Slack | D1: Details
A2: Capacity | B2: roster_count | C2: 33
A3: Capacity | B3: legal_shift_count | C3: 24
A4: Capacity | B4: interval_minutes | C4: 30
A5: Capacity | B5: active_intervals | C5: 264
A6: Capacity | B6: leave_days | C6: 6
A7: Capacity | B7: estimated_working_shifts | C7: 159
A8: Capacity | B8: productive_hours_available | C8: 1272
A9: Capacity | B9: target_hours_lower_bound | C9: 970.17896
A10: Capacity | B10: floor_hours_lower_bound | C10: 776.14317
A11: Capacity | B11: hard_floor_hours_lower_bound | C11: 0
A12: Capacity | B12: productive_minus_target_lower_bound | C12: 301.82104
A13: Capacity | B13: productive_minus_floor_lower_bound | C13: 495.85683
A14: Capacity | B14: productive_minus_hard_floor_lower_bound | C14: 1272
A15: Directional Capability | B15: english | C15: english | D15: Source associate language can cover these target languages
A16: Directional Capability | B16: international | C16: english, international | D16: Source associate language can cover these target languages

Sheet Blank Interval Audit
A1: Day | B1: Interval | C1: Current-Week Before Raw Min | D1: Current-Week Before Raw Max | E1: Current-Week After Raw Min | F1: Current-Week After Raw Max | G1: Prior Carry-In Raw Min | H1: Prior Carry-In Raw Max | I1: Total After Raw Min | J1: Total After Raw Max | K1: Total After Raw Average | L1: Contract Mode | M1: Rule | N1: Status
C2: 0 | D2: 0 | E2: 0 | F2: 0 | G2: 0 | H2: 0 | I2: 0 | J2: 0 | K2: 0 | L2: hard_no_current_week_staffing | M2: No new staffing in blank intervals | N2: PASS

Sheet Shift Demand Fit Audit
A1: Associate | B1: Day | C1: Shift | D1: Shift Start | E1: Start Contract | F1: Active Minutes | G1: Active Ratio | H1: Max Blank Minutes | I1: Guard Mode | J1: Guard Enabled | K1: Demand Fit Status | L1: Overall Status
A2: Abdelrahman Abdelghani | B2: Sun | C2: 16:00 - 01:00 | D2: 16:00 | E2: PASS | F2: 540 | G2: 1 | H2: 0 | I2: auto | J2: TRUE | K2: PASS | L2: PASS
