Workbook

Sheet Start Here
B1: Weekly schedule input - GDI_REAL28_24_7
B2: Fill the orange tabs each week, check the settings once, and watch the checks below turn green. Cells you fill are pale yellow; every one only accepts values the scheduler can use.
B4: # | C4: Tab | D4: What to do | E4: Quick check
B5: 1 | C5: Instructions | D5: Check the settings (headcount, target, shift lengths, requests). | E5: =IF(OR(Instructions!C7=COUNTA('Schedule'!$D$3:$D$302),Instructions!C8="Yes"),"OK Count of Associates matches the roster","! Count of Associates is "&Instructions!C7&" but the roster has "&COUNTA('Schedule'!$D$3:$D$302))
B6: 2 | C6: Schedule | D6: This week's roster: one row per person, with language. | E6: =IF(COUNTA('Schedule'!$D$3:$D$302)=0,"! Roster is empty",IF(SUMPRODUCT(('Schedule'!$D$3:$D$302<>"")*(COUNTIF('Schedule'!$D$3:$D$302,'Schedule'!$D$3:$D$302)>1))>0,"! "&SUMPRODUCT(('Schedule'!$D$3:$D$302<>"")*(COUNTIF('Schedule'!$D$3:$D$302,'Schedule'!$D$3:$D$302)>1))&" repeated name(s)","OK "&COUNTA('Schedule'!$D$3:$D$302)&" people"))
B7: 3 | C7: FT Wise 60 Min | D7: Demand: required FTE per interval, Sunday to Saturday. | E7: =IF(ISERROR(COUNT(INDIRECT("'"&Instructions!C10&"'!B1:H200"))),"! Requirements Source names no tab",IF(COUNT(INDIRECT("'"&Instructions!C10&"'!B1:H200"))=0,"! No demand entered",IF(COUNTIF(INDIRECT("'"&Instructions!C10&"'!B1:H200"),"<0")>0,"! Negative demand","OK "&COUNT(INDIRECT("'"&Instructions!C10&"'!B1:H200"))&" demand cells")))
B8: 4 | C8: Shrinkage 60 Min | D8: Shrinkage per interval (0.08 = 8%). | E8: =IF(ISERROR(COUNT(INDIRECT("'"&Instructions!C11&"'!B1:H200"))),"! Shrinkage Source names no tab",IF(COUNTIF(INDIRECT("'"&Instructions!C11&"'!B1:H200"),">=1")+COUNTIF(INDIRECT("'"&Instructions!C11&"'!B1:H200"),"<0")>0,"! A value is not between 0% and 99%","OK "&COUNT(INDIRECT("'"&Instructions!C11&"'!B1:H200"))&" shrinkage cells"))
B9: 5 | C9: Preference | D9: OFF, Leave or preferred shift per person and day. | E9: =IF(SUMPRODUCT(('Preference'!$A$3:$A$302<>"")*(COUNTIF('Schedule'!$D$3:$D$302,'Preference'!$A$3:$A$302)=0))=0,"OK every name is on the roster","! "&SUMPRODUCT(('Preference'!$A$3:$A$302<>"")*(COUNTIF('Schedule'!$D$3:$D$302,'Preference'!$A$3:$A$302)=0))&" name(s) not on the roster")
B10: 6 | C10: Fixed Request | D10: Fixed shifts (only used when Fixed Request Use = Yes). | E10: =IF(Instructions!C35<>"Yes","Not used (Fixed Request Use = No)",IF(SUMPRODUCT(('Fixed Request'!$B$3:$B$302<>"")*(COUNTIF('Schedule'!$D$3:$D$302,'Fixed Request'!$B$3:$B$302)=0))=0,"OK every name is on the roster","! "&SUMPRODUCT(('Fixed Request'!$B$3:$B$302<>"")*(COUNTIF('Schedule'!$D$3:$D$302,'Fixed Request'!$B$3:$B$302)=0))&" name(s) not on the roster"))
B11: 7 | C11: Previous week scheduled | D11: Last Saturday's shift per person (for rest rules). | E11: =IF(SUMPRODUCT(('Previous week scheduled'!$B$3:$B$302<>"")*(COUNTIF('Schedule'!$D$3:$D$302,'Previous week scheduled'!$B$3:$B$302)=0)*ISERROR(SEARCH('Previous week scheduled'!$B$3:$B$302,"|"&Instructions!C39&"|")))=0,"OK every name is on the roster or listed as departed","! "&SUMPRODUCT(('Previous week scheduled'!$B$3:$B$302<>"")*(COUNTIF('Schedule'!$D$3:$D$302,'Previous week scheduled'!$B$3:$B$302)=0)*ISERROR(SEARCH('Previous week scheduled'!$B$3:$B$302,"|"&Instructions!C39&"|")))&" name(s) not on the roster: list them in Known Departed Associates if they left")
B13: Colours
C14: Pale yellow cell | D14: You fill this. Dropdowns and limits stop values the scheduler cannot use.
C15: Orange tab | D15: Update every week.
C16: Blue tab | D16: Settings: check when the policy changes.
C17: Grey tab | D17: Reference: shift list, language hours, coverage split.
B19: Good to know
C20: • The quick checks above help while you type. The scheduler re-checks everything on every run and stops with a clear message if anything is wrong - that check is the authority.
C21: • Hidden tabs (engine tuning, lists, the demand tabs for other interval sizes, old notes) are kept, not deleted: right-click any tab > Unhide.
C22: • Changing Interval Minutes? Unhide the matching FT Wise and Shrinkage tabs and pick them in Instructions.
C23: • Outputs: the main schedule, plus optional MAX_TARGET, MAX_FLOOR and MORE_CONSISTENT copies to choose from.

Sheet Instructions
A1: Settings for this schedule
A2: Fill the yellow Value cells. Every cell only accepts what the scheduler can use (pick from the list, or a number inside the allowed range). Blank = engine default.
B4: Instruction | C4: Value | D4: Help
A5: Case Setup
B6: Program Name | C6: GDI_REAL28_24_7 | D6: Name printed on every output. Any text.
B7: Count of Associates | C7: 29 | D7: People on the Schedule tab. Start Here checks that the roster matches.
B8: Allow Headcount Mismatch | C8: No | D8: Yes only if the roster may differ from the count above on purpose.
B9: Interval Minutes | C9: 60 | D9: Size of one demand row: 15, 30 or 60 minutes.
B10: Requirements Source | C10: FT Wise 60 Min | D10: The demand tab to use. Must match Interval Minutes.
B11: Shrinkage Source | C11: Shrinkage 60 Min | D11: The shrinkage tab to use. Must match Interval Minutes.
A13: How To Run
B14: Run Stage | C14: Full Schedule | D14: Full Schedule = shifts and breaks. Before Breaks Only = shifts only, for a quick review.
B15: Run Depth | C15: Deep | D15: Quick is fastest. Deep and Overnight search longer for a better week.
B16: Shift Consistency Polish | D16: Blank = engine default. Yes = also write a 'more consistent' copy of the week when it keeps coverage. No = skip it.
A18: Coverage
B19: Target | C19: 1 | D19: Coverage goal for every interval. Type 0.9 or 90%.
B20: Target Priority Confirmed | C20: Yes | D20: Set Yes when a 100% target is intended.
B21: Minimum Per Interval | C21: 0.8 | D21: Lowest acceptable coverage in any interval (the floor). Type 0.8 or 80%.
B22: Hard Floor Solver Constraint Enabled | C22: No | D22: Yes = never below the floor (the week may become unsolvable). No = protect it as a priority.
B23: Blank Interval Staffing Rule | C23: No new staffing in blank intervals | D23: What to do in intervals that have no demand.
B24: Coverage Objective Weighting | C24: Interval Count | D24: Interval Count = most intervals at target. Volume Weighted = busy intervals count more (service level).
A26: Shift & OFF
B27: Allowed Shift Durations Hours | C27: 9 | D27: Shift lengths allowed. 10.5 h or more needs Use 11H/3OFF = Yes.
B28: Use 11H/3OFF | C28: No | D28: Yes = long-shift week with three OFF days.
B29: Strict OFF Count | C29: Yes | D29: Yes = exactly two OFF days (three with 11H/3OFF) per person.
B30: Separate OFF Days | C30: No | D30: Yes = a person's OFF days may be apart. No = they must be together.
B31: Rest Gap Hours | C31: 12 | D31: Minimum hours between the end of one shift and the start of the next.
B32: Count of Different Shifts Per week | C32: 2 | D32: Most different shifts one person may get in a week (1 to 7).
A34: Requests
B35: Fixed Request Use | C35: No | D35: Yes = apply the Fixed Request tab.
B36: Hard OFF Preferences | C36: Yes | D36: Yes = OFF requests on the Preference tab are always granted.
B37: Leave Enabled | C37: Yes | D37: Yes = Leave on the Preference tab is honoured.
B38: Use Preferences | C38: Yes | D38: Yes = try to give people their preferred shifts.
B39: Known Departed Associates | D39: Blank = engine default. Names on last week's tab who have left, separated by ; (Start Here lists any missing).
A41: Opening Guard (click + on the left to open)
B42: Opening Guard Enabled | C42: No | D42: Yes = keep enough people on at the start of each day.
B43: Opening Minimum FTE | C43: 1 | D43: People needed at opening (whole number).
B44: Opening Guard Intervals | C44: 1 | D44: How many opening intervals the guard covers.
A46: Breaks
B47: Short Break Count | C47: 2 | D47: Short breaks per shift.
...

Sheet Schedule
A1: Schedule — Roster Input
A2: Slot | B2: Emp ID | C2: Email | D2: SF Name | E2: TL | F2: Language | G2: Sun | H2: Mon | I2: Tue | J2: Wed | K2: Thu | L2: Fri | M2: Sat | N2: Roster Notes
A3: 1 | B3: 692853 | C3: Eabdelhadi@Dynamite.ca | D3: Esraa Abdelhadi | F3: UK
A4: 2 | B4: 693322 | C4: seleman@dynamiteconsultants.ca | D4: Seif Eleman | F4: Bilingual
A5: 3 | B5: 692616 | C5: Melsayed@Dynamite.ca | D5: Mohamed Elsayed | F5: UK
A6: 4 | B6: 718383 | C6: mabdelhamid@dynamiteconsultants.ca | D6: Mennatullah Abdelhamid | F6: UK
A7: 5 | B7: 627709 | C7: aali@dynamiteconsultants.ca | D7: Awni Ali | F7: French
A8: 6 | B8: 621364 | C8: jrabeey@dynamiteconsultants.ca | D8: Jana Rabeey | F8: Bilingual
A9: 7 | B9: 678968 | C9: wibrahim@dynamiteconsultants.ca | D9: Wagih Ibrahim | F9: English
A10: 8 | B10: 692724 | C10: Yeltembari@Dynamite.ca | D10: Youssef Eltembari | F10: UK
A11: 9 | B11: 718518 | C11: aahmed1@dynamiteconsultants.ca | D11: Adam Ahmed | F11: UK
A12: 10 | B12: 685912 | C12: jamgad@dynamite.ca | D12: Juliana Amgad | F12: French
A13: 11 | B13: 686682 | C13: mmoustafa@dynamiteconsultants.ca | D13: Mazen Moustafa | F13: English
A14: 12 | B14: 485106 | C14: mhabib@dynamiteconsultants.ca | D14: Mohamed Habib | F14: English
... A30: 28 | B30: 754850 | C30: Rana.Srour@sutherlandglobal.com | D30: Rana Mohamed | F30: Bilingual
B31: 692615 | C31: Salma.Abdelhadi@sutherlandglobal.com | D31: Salma Ahmed | F31: English

Sheet FT Wise 60 Min
A1: FT Wise 60 Min — Full-week requirement input
A2: Interval | B2: Sun | C2: Mon | D2: Tue | E2: Wed | F2: Thu | G2: Fri | H2: Sat
A3: 00:00 | B3: 8 | C3: 9 | D3: 12 | E3: 12 | F3: 12 | G3: 13 | H3: 12
A4: 01:00 | B4: 8 | C4: 9 | D4: 12 | E4: 11 | F4: 11 | G4: 11 | H4: 9
A5: 02:00 | B5: 8 | C5: 8 | D5: 11 | E5: 11 | F5: 10 | G5: 11 | H5: 10
A6: 03:00 | B6: 7 | C6: 7 | D6: 9 | E6: 10 | F6: 11 | G6: 9 | H6: 8
A7: 04:00 | D7: 8 | E7: 8 | F7: 9 | G7: 8 | H7: 7
A8: 05:00 | D8: 6 | E8: 6 | F8: 7 | G8: 7 | H8: 6
A9: 06:00 | D9: 6 | E9: 5 | F9: 6 | G9: 6 | H9: 5
A10: 07:00 | C10: 1 | D10: 1 | E10: 1 | F10: 1 | G10: 1
A11: 08:00 | C11: 1 | D11: 1 | E11: 1 | F11: 1 | G11: 1
A12: 09:00 | C12: 1 | D12: 1 | E12: 1 | F12: 1 | G12: 1
A13: 10:00 | B13: 1 | C13: 1 | D13: 1 | E13: 1 | F13: 1 | G13: 1 | H13: 1
A14: 11:00 | B14: 1 | C14: 1 | D14: 1 | E14: 1 | F14: 1 | G14: 1 | H14: 1
A15: 12:00 | B15: 1 | C15: 1 | D15: 1 | E15: 1 | F15: 1 | G15: 1 | H15: 1
A16: 13:00 | B16: 1 | C16: 1 | D16: 1 | E16: 1 | F16: 1 | G16: 1 | H16: 1
A17: 14:00 | B17: 1 | C17: 1 | D17: 1 | E17: 1 | F17: 1 | G17: 1 | H17: 1
A18: 15:00 | B18: 1 | C18: 1 | D18: 1 | E18: 1 | F18: 1 | G18: 1 | H18: 1
A19: 16:00 | B19: 7 | C19: 5 | D19: 5 | E19: 4 | F19: 4 | G19: 5 | H19: 6
A20: 17:00 | B20: 7 | C20: 5 | D20: 5 | E20: 6 | F20: 5 | G20: 6 | H20: 8
A21: 18:00 | B21: 8 | C21: 6 | D21: 7 | E21: 6 | F21: 6 | G21: 6 | H21: 10
A22: 19:00 | B22: 10 | C22: 7 | D22: 7 | E22: 7 | F22: 7 | G22: 6 | H22: 10
A23: 20:00 | B23: 10 | C23: 7 | D23: 7 | E23: 8 | F23: 7 | G23: 7 | H23: 10
A24: 21:00 | B24: 10 | C24: 7 | D24: 8 | E24: 8 | F24: 8 | G24: 7 | H24: 11
... A26: 23:00 | B26: 9 | C26: 11 | D26: 12 | E26: 13 | F26: 12 | G26: 12 | H26: 9

Sheet Shrinkage 60 Min
A1: Shrinkage 60 Min — Matching shrinkage grid
A2: Interval | B2: Sun | C2: Mon | D2: Tue | E2: Wed | F2: Thu | G2: Fri | H2: Sat
A3: 00:00 | B3: 0.12 | C3: 0.12 | D3: 0.12 | E3: 0.12 | F3: 0.12 | G3: 0.12 | H3: 0.12
A4: 01:00 | B4: 0.12 | C4: 0.12 | D4: 0.12 | E4: 0.12 | F4: 0.12 | G4: 0.12 | H4: 0.12
A5: 02:00 | B5: 0.12 | C5: 0.12 | D5: 0.12 | E5: 0.12 | F5: 0.12 | G5: 0.12 | H5: 0.12
A6: 03:00 | B6: 0.12 | C6: 0.12 | D6: 0.12 | E6: 0.12 | F6: 0.12 | G6: 0.12 | H6: 0.12
A7: 04:00 | D7: 0.12 | E7: 0.12 | F7: 0.12 | G7: 0.12 | H7: 0.12
A8: 05:00 | D8: 0.12 | E8: 0.12 | F8: 0.12 | G8: 0.12 | H8: 0.12
A9: 06:00 | D9: 0.12 | E9: 0.12 | F9: 0.12 | G9: 0.12 | H9: 0.12
A10: 07:00
A11: 08:00
A12: 09:00
A13: 10:00
A14: 11:00
A15: 12:00
A16: 13:00
A17: 14:00
A18: 15:00
A19: 16:00 | B19: 0.12 | C19: 0.12 | D19: 0.12 | E19: 0.12 | F19: 0.12 | G19: 0.12 | H19: 0.12
A20: 17:00 | B20: 0.12 | C20: 0.12 | D20: 0.12 | E20: 0.12 | F20: 0.12 | G20: 0.12 | H20: 0.12
A21: 18:00 | B21: 0.12 | C21: 0.12 | D21: 0.12 | E21: 0.12 | F21: 0.12 | G21: 0.12 | H21: 0.12
A22: 19:00 | B22: 0.12 | C22: 0.12 | D22: 0.12 | E22: 0.12 | F22: 0.12 | G22: 0.12 | H22: 0.12
A23: 20:00 | B23: 0.12 | C23: 0.12 | D23: 0.12 | E23: 0.12 | F23: 0.12 | G23: 0.12 | H23: 0.12
A24: 21:00 | B24: 0.12 | C24: 0.12 | D24: 0.12 | E24: 0.12 | F24: 0.12 | G24: 0.12 | H24: 0.12
A25: 22:00 | B25: 0.12 | C25: 0.12 | D25: 0.12 | E25: 0.12 | F25: 0.12 | G25: 0.12 | H25: 0.12
A26: 23:00 | B26: 0.12 | C26: 0.12 | D26: 0.12 | E26: 0.12 | F26: 0.12 | G26: 0.12 | H26: 0.12

Sheet Preference
A1: Preference / OFF / Leave Requests
A2: Associate Name | B2: Language | C2: Sun | D2: Mon | E2: Tue | F2: Wed | G2: Thu | H2: Fri | I2: Sat | J2: Notes

Sheet Fixed Request
A1: Fixed Shifts / Flexible Nesting
A2: Active? | B2: Associate Name | C2: Nesting Group | D2: Sun | E2: Mon | F2: Tue | G2: Wed | H2: Thu | I2: Fri | J2: Sat | K2: Notes
A3: No | K3: Fixed Request Use = No; no exact/flexible requests supplied for this 28HC test.

Sheet Previous week scheduled
A1: Previous Saturday Schedule — Cyclic Carry-in
A2: Slot | B2: Name | C2: Language | D2: Previous Saturday Shift
A3: 1 | B3: Esraa Abdelhadi | C3: UK | D3: 10:00 - 19:00
A4: 2 | B4: Seif Eleman | C4: Bilingual | D4: 16:00 - 01:00
A5: 3 | B5: Mohamed Elsayed | C5: UK | D5: OFF
A6: 4 | B6: Mennatullah Abdelhamid | C6: UK | D6: OFF
A7: 5 | B7: Awni Ali | C7: French | D7: 19:00 - 04:00
A8: 6 | B8: Jana Rabeey | C8: Bilingual | D8: 16:00 - 01:00
A9: 7 | B9: Wagih Ibrahim | C9: English | D9: 19:00 - 04:00
A10: 8 | B10: Youssef Eltembari | C10: UK | D10: 14:00 - 23:00
A11: 9 | B11: Adam Ahmed | C11: UK | D11: 19:00 - 04:00
A12: 10 | B12: Juliana Amgad | C12: French | D12: 16:00 - 01:00
A13: 11 | B13: Mazen Moustafa | C13: English | D13: OFF
A14: 12 | B14: Mohamed Habib | C14: English | D14: OFF
... A31: 29 | B31: Salma Ahmed | C31: English | D31: OFF

Sheet Language Setup
A1: Language / Skill Setup — Directional Coverage
A2: Language | B2: Coverage Start | C2: Coverage End | D2: Can Cover Languages | E2: Active? | F2: Coverage Group | G2: Minimum Per Interval | H2: Priority / Notes | I2: Cross-skilled? | J2: Coverage Days
A3: UK | B3: 0.29166667 | C3: 02:00 | D3: UK, English | E3: Yes | F3: UK | G3: 1 | H3: Source language covers itself and English. | I3: Yes | J3: All
A4: Bilingual | B4: 16:00 | C4: 07:00 | D4: Bilingual, French, English | E4: Yes | F4: Bilingual/French | G4: 1 | H4: Source language covers itself plus French and English. | I4: Yes | J4: All
A5: French | B5: 16:00 | C5: 07:00 | D5: French | E5: Yes | F5: Bilingual/French | G5: 1 | H5: French only. | I5: No | J5: All
A6: English | B6: 16:00 | C6: 07:00 | D6: English | E6: Yes | F6: English | G6: 0 | H6: No minimum-per-interval language requirement. | I6: No | J6: All

Sheet Coverage Split
A1: Coverage Split - which coverage group is responsible for staffing which hours
A2: Optional. Leave empty and nothing changes. Add a row and that group must field the WHOLE requirement in its window - not the 'Minimum Per Interval' floor from Language Setup, which only guarantees one qualified person is present. Coverage Group must match the Coverage Group column in Language Setup. If two windows overlap, the groups cover those hours TOGETHER against one requirement - their people pool and the higher Coverage Ratio applies; the requirement is never charged twice.
A4: Coverage Group | B4: Start | C4: End | D4: Coverage Ratio | E4: Exclusive? | F4: Active? | G4: Notes
A5: Name from Language Setup's Coverage Group column. | B5: Window opens (e.g. 03:00). | C5: Window closes; may cross midnight (e.g. 16:00). | D5: Blank = the workbook's Minimum Per Interval. 1.0 = full requirement. | E5: Yes = only this group may work these hours at all. | F5: No or blank = row ignored.

Sheet Shift Library
A1: Shift Library — Allowed 9H Shifts Only
A2: Allowed Shift / Status | B2: Start | C2: End | D2: Duration Hours | E2: Type | F2: Notes
A3: OFF | E3: Status | F3: Expected weekly OFF value
A4: Leave | E4: Status | F4: Hard unavailable day
A5: Planned | E5: Status | F5: Previous-Saturday only
A6: 00:00 - 09:00 | B6: 00:00 | C6: 09:00 | D6: 9 | E6: 9H | F6: Allowed because Use 11H/3OFF = No.
A7: 01:00 - 10:00 | B7: 01:00 | C7: 10:00 | D7: 9 | E7: 9H | F7: Allowed because Use 11H/3OFF = No.
A8: 02:00 - 11:00 | B8: 02:00 | C8: 11:00 | D8: 9 | E8: 9H | F8: Allowed because Use 11H/3OFF = No.
A9: 03:00 - 12:00 | B9: 03:00 | C9: 12:00 | D9: 9 | E9: 9H | F9: Allowed because Use 11H/3OFF = No.
A10: 04:00 - 13:00 | B10: 04:00 | C10: 13:00 | D10: 9 | E10: 9H | F10: Allowed because Use 11H/3OFF = No.
A11: 05:00 - 14:00 | B11: 05:00 | C11: 14:00 | D11: 9 | E11: 9H | F11: Allowed because Use 11H/3OFF = No.
A12: 06:00 - 15:00 | B12: 06:00 | C12: 15:00 | D12: 9 | E12: 9H | F12: Allowed because Use 11H/3OFF = No.
A13: 07:00 - 16:00 | B13: 07:00 | C13: 16:00 | D13: 9 | E13: 9H | F13: Allowed because Use 11H/3OFF = No.
A14: 08:00 - 17:00 | B14: 08:00 | C14: 17:00 | D14: 9 | E14: 9H | F14: Allowed because Use 11H/3OFF = No.
A15: 09:00 - 18:00 | B15: 09:00 | C15: 18:00 | D15: 9 | E15: 9H | F15: Allowed because Use 11H/3OFF = No.
A16: 10:00 - 19:00 | B16: 10:00 | C16: 19:00 | D16: 9 | E16: 9H | F16: Allowed because Use 11H/3OFF = No.
A17: 11:00 - 20:00 | B17: 11:00 | C17: 20:00 | D17: 9 | E17: 9H | F17: Allowed because Use 11H/3OFF = No.
... A29: 23:00 - 08:00 | B29: 23:00 | C29: 08:00 | D29: 9 | E29: 9H | F29: Allowed because Use 11H/3OFF = No.

Sheet RC9 Universal Setup
A1: RC9.1 Universal Search-Recovery Production Setup
A2: Control | B2: Value
A3: Purpose | B3: This workbook is the only input contract for the RC9.1 universal engine. It is prepared for a full 24/7 GDI REAL28 weekly case.
A4: Production rule | B4: Program/client name is metadata only; solver behavior is controlled by Instructions, Shift Library, Language Setup, requests, and requirement sheets.
A5: Primary KPI | B5: Target is dynamic; this case explicitly targets 100% per interval with 80% protected floor.
A6: Required output 1 | B6: BEST_BEFORE_BREAKS_SCHEDULE is the review/anchor artifact only.
A7: Required output 2 | B7: BEST_FINAL_AFTER_BREAKS_SCHEDULE is the operational after-break artifact.
A8: Search Recovery | B8: RC9.1 should expand break search across target Pareto skeletons rather than exhaust a single skeleton.
A9: Deep Mode | B9: Default Deep runtime up to 4 hours.
A10: Full Mode | B10: Default Full runtime up to 6 hours for tight 24/7 cases.
A11: Universal Scope | B11: No client-specific production branch is implied by Program Name.
A12: 24/7 Input Contract | B12: 24x7 operating week; blank demand intervals are intentional and governed by Blank Interval Staffing Rule. Do not force blanks to zero.
A14: Workbook completion checklist | B14: Status
... A23: Input Checks reviewed before upload | B23: PASS

Sheet RC9.1 Release Notes
A1: RC9.1 Release Notes — Input-specific choices
A2: Area | B2: Policy | C2: Why it matters | D2: Status | E2: This workbook
A3: Target handling | B3: Workbook Target is primary | C3: Prevents floor-first misoptimization | D3: Active | E3: Target=100%
A4: Stage 2 breaks | B4: Breadth-first across Pareto skeletons | C4: Improves recovery on tight 24/7 cases | D4: Active | E4: Keep default
A5: Joint recovery | B5: Deep 4h / Full 6h | C5: Tight 24/7 needs integrated recovery time | D5: Active | E5: Keep default
A6: Break spacing | B6: 120 preferred, 60 absolute minimum | C6: Prevents false break infeasibility on overnight-heavy 24/7 schedules | D6: Active | E6: 60-min absolute minimum
A7: Blank demand | B7: No new staffing in blank intervals | C7: Avoids invented demand | D7: Active | E7: No blank intervals exist
A8: Language | B8: Directional source -> cover list | C8: Prevents over-expanding UK/Bilingual eligibility | D8: Active | E8: UK + English; Bilingual + French + English

Sheet 00 START HERE
A1: Universal WFM Scheduler — RC9.1 Production Input — GDI REAL28 24/7
A2: Step | B2: Area | C2: What is already prepared
A3: 1 | B3: Instructions | C3: Confirm 60-minute source, Target 100%, Floor 80%, 9H/2OFF, 12h rest, 2 short + 1 lunch break.
A4: 2 | B4: Schedule | C4: 28 associates entered exactly once; Sun-Sat are blank because RC9.1 writes schedules.
A5: 3 | B5: Requirements & Shrinkage | C5: FT Wise 60 Min and Shrinkage 60 Min preserve the supplied hourly demand pattern; intentional blank intervals remain blank.
A6: 4 | B6: Language / Requests | C6: Language Setup is directional; Preference has historical requests; Fixed Request contains active fixed rows and is enabled.
A7: 5 | B7: Cyclic boundary | C7: Previous Saturday is supplied so Sunday carry-in and next-week rest protection are not guessed.
A8: 6 | B8: Validate & Run | C8: Input Checks should show PASS before upload. Use the RC9.1 universal runner, not a client-specific runner.

Sheet FT Wise 15 Min
A1: FT Wise 15 Min — Full-week requirement input
A2: Interval | B2: Sun | C2: Mon | D2: Tue | E2: Wed | F2: Thu | G2: Fri | H2: Sat
A3: 00:00
A4: 00:15
A5: 00:30
A6: 00:45
A7: 01:00
A8: 01:15
A9: 01:30
A10: 01:45
A11: 02:00
A12: 02:15
A13: 02:30
A14: 02:45
... A98: 23:45

Sheet FT Wise 30 Min
A1: FT Wise 30 Min — Full-week requirement input
A2: Interval | B2: Sun | C2: Mon | D2: Tue | E2: Wed | F2: Thu | G2: Fri | H2: Sat
A3: 00:00
A4: 00:30
A5: 01:00
A6: 01:30
A7: 02:00
A8: 02:30
A9: 03:00
A10: 03:30
A11: 04:00
A12: 04:30
A13: 05:00
A14: 05:30
... A50: 23:30

Sheet Shrinkage 15 Min
A1: Shrinkage 15 Min — Matching shrinkage grid
A2: Interval | B2: Sun | C2: Mon | D2: Tue | E2: Wed | F2: Thu | G2: Fri | H2: Sat
A3: 00:00
A4: 00:15
A5: 00:30
A6: 00:45
A7: 01:00
A8: 01:15
A9: 01:30
A10: 01:45
A11: 02:00
A12: 02:15
A13: 02:30
A14: 02:45
... A98: 23:45

Sheet Shrinkage 30 Min
A1: Shrinkage 30 Min — Matching shrinkage grid
A2: Interval | B2: Sun | C2: Mon | D2: Tue | E2: Wed | F2: Thu | G2: Fri | H2: Sat
A3: 00:00
A4: 00:30
A5: 01:00
A6: 01:30
A7: 02:00
A8: 02:30
A9: 03:00
A10: 03:30
A11: 04:00
A12: 04:30
A13: 05:00
A14: 05:30
... A50: 23:30

Sheet Shift Catalog
A1: Shift Catalog — Hourly 9H / optional 11H reference
A2: Shift Label | B2: Start | C2: End | D2: Duration Hours
A3: 00:00 - 09:00 | B3: 00:00 | C3: 09:00 | D3: 9
A4: 01:00 - 10:00 | B4: 01:00 | C4: 10:00 | D4: 9
A5: 02:00 - 11:00 | B5: 02:00 | C5: 11:00 | D5: 9
A6: 03:00 - 12:00 | B6: 03:00 | C6: 12:00 | D6: 9
A7: 04:00 - 13:00 | B7: 04:00 | C7: 13:00 | D7: 9
A8: 05:00 - 14:00 | B8: 05:00 | C8: 14:00 | D8: 9
A9: 06:00 - 15:00 | B9: 06:00 | C9: 15:00 | D9: 9
A10: 07:00 - 16:00 | B10: 07:00 | C10: 16:00 | D10: 9
A11: 08:00 - 17:00 | B11: 08:00 | C11: 17:00 | D11: 9
A12: 09:00 - 18:00 | B12: 09:00 | C12: 18:00 | D12: 9
A13: 10:00 - 19:00 | B13: 10:00 | C13: 19:00 | D13: 9
A14: 11:00 - 20:00 | B14: 11:00 | C14: 20:00 | D14: 9
... A50: 23:00 - 10:00 | B50: 23:00 | C50: 10:00 | D50: 11

Sheet Validation Lists
A1: Lists behind the dropdowns. Add a line to a list to offer it. Do not rename this tab.
A2: Allowed Shift Durations Hours | B2: Day values (OFF, Leave, shifts) | C2: Previous Saturday values
A3: 8 | B3: OFF | C3: OFF
A4: 9 | B4: Leave | C4: Leave
A5: 10 | B5: =IF('Shift Library'!A6="","",'Shift Library'!A6) | C5: Planned
A6: 11 | B6: =IF('Shift Library'!A7="","",'Shift Library'!A7) | C6: =IF('Shift Library'!A6="","",'Shift Library'!A6)
A7: 12 | B7: =IF('Shift Library'!A8="","",'Shift Library'!A8) | C7: =IF('Shift Library'!A7="","",'Shift Library'!A7)
A8: 8, 9 | B8: =IF('Shift Library'!A9="","",'Shift Library'!A9) | C8: =IF('Shift Library'!A8="","",'Shift Library'!A8)
A9: 9, 10 | B9: =IF('Shift Library'!A10="","",'Shift Library'!A10) | C9: =IF('Shift Library'!A9="","",'Shift Library'!A9)
A10: 9, 11 | B10: =IF('Shift Library'!A11="","",'Shift Library'!A11) | C10: =IF('Shift Library'!A10="","",'Shift Library'!A10)
A11: 10, 11 | B11: =IF('Shift Library'!A12="","",'Shift Library'!A12) | C11: =IF('Shift Library'!A11="","",'Shift Library'!A11)
A12: 8, 9, 10 | B12: =IF('Shift Library'!A13="","",'Shift Library'!A13) | C12: =IF('Shift Library'!A12="","",'Shift Library'!A12)
A13: 9, 10, 11 | B13: =IF('Shift Library'!A14="","",'Shift Library'!A14) | C13: =IF('Shift Library'!A13="","",'Shift Library'!A13)
B14: =IF('Shift Library'!A15="","",'Shift Library'!A15) | C14: =IF('Shift Library'!A14="","",'Shift Library'!A14)
B15: =IF('Shift Library'!A16="","",'Shift Library'!A16) | C15: =IF('Shift Library'!A15="","",'Shift Library'!A15)
B16: =IF('Shift Library'!A17="","",'Shift Library'!A17) | C16: =IF('Shift Library'!A16="","",'Shift Library'!A16)
B17: =IF('Shift Library'!A18="","",'Shift Library'!A18) | C17: =IF('Shift Library'!A17="","",'Shift Library'!A17)
B18: =IF('Shift Library'!A19="","",'Shift Library'!A19) | C18: =IF('Shift Library'!A18="","",'Shift Library'!A18)
B19: =IF('Shift Library'!A20="","",'Shift Library'!A20) | C19: =IF('Shift Library'!A19="","",'Shift Library'!A19)
B20: =IF('Shift Library'!A21="","",'Shift Library'!A21) | C20: =IF('Shift Library'!A20="","",'Shift Library'!A20)
B21: =IF('Shift Library'!A22="","",'Shift Library'!A22) | C21: =IF('Shift Library'!A21="","",'Shift Library'!A21)
B22: =IF('Shift Library'!A23="","",'Shift Library'!A23) | C22: =IF('Shift Library'!A22="","",'Shift Library'!A22)
B23: =IF('Shift Library'!A24="","",'Shift Library'!A24) | C23: =IF('Shift Library'!A23="","",'Shift Library'!A23)
B24: =IF('Shift Library'!A25="","",'Shift Library'!A25) | C24: =IF('Shift Library'!A24="","",'Shift Library'!A24)
B25: =IF('Shift Library'!A26="","",'Shift Library'!A26) | C25: =IF('Shift Library'!A25="","",'Shift Library'!A25)
... B68: =IF('Shift Library'!A69="","",'Shift Library'!A69) | C68: =IF('Shift Library'!A68="","",'Shift Library'!A68)
C69: =IF('Shift Library'!A69="","",'Shift Library'!A69)

Sheet Engine Defaults
A1: ADVANCED - engine tuning. Defaults are production-tested.
A2: Change these only with a specific reason. They are not per-schedule business settings; the values here are the ones every released result was measured with.
B4: Instruction | C4: Value | D4: Help
A5: Demand Fit
B6: Demand Fit Guard Enabled | C6: Auto
B7: Demand Fit Minimum Active Minutes | C7: 180
B8: Demand Fit Minimum Active Ratio | C8: 0.45
B9: Demand Fit Maximum Blank Span Minutes | C9: 180
A11: Overage Control
B12: Overage Control Enabled | C12: Yes
B13: Overage Soft Cap | C13: 1.1
B14: Overage Severe Cap | C14: 1.2
B15: Overage Extreme Cap | C15: 1.4
B16: Overage Penalty Weight | C16: 40
A18: Break Concurrency
B19: Maximum Concurrent Break Ratio | C19: 0.3
B20: Maximum Concurrent Breaks | C20: 4
B21: Break Concurrency Gate Mode | C21: Warn
A23: Week Boundary
B24: Next Sunday Balance Enabled | C24: Yes
B25: Next Sunday Overage Cap | C25: 1.3
B26: Next Sunday Maximum Adjacent Raw Change | C26: 3
B27: Next Sunday Balance Gate Mode | C27: Warn
A29: Language / Skill
B30: Language Operational Reserve Enabled | C30: Yes
B31: Language Operational Reserve Extra FTE | C31: 1
B32: Language Reserve Gate Mode | C32: Warn
B33: Qualified Language Break Certificate Enabled | C33: Yes
A35: Whole Week Balance
B36: Whole Week Balance Enabled | C36: Yes
B37: Whole Week Overage Cap | C37: 1.35
A39: Benchmarks
B40: Quality Benchmark Tolerance Intervals | C40: 0

Sheet Input Checks
A1: Input Checks are performed by the engine, not by this sheet.
A3: The previous version of this tab held hardcoded PASS/WARN text. It reported PASS regardless of what the roster, demand or language setup actually contained, so it could not catch the errors it appeared to check for.
A4: The engine runs the real pre-solver contract validation on every run and writes the result to the audit JSON as pre_solver_contract_validation, with a specific code, day and time for each failure. That is the authoritative check. The Start Here tab carries live quick checks while you type.
