Workbook

Sheet 00 START HERE
A1: Universal WFM Scheduler — RC8 Clean Input Template
A2: Business-safe input workbook. Complete the yellow Instructions values and roster/demand sheets; dropdowns prevent common contract typos. Engine tuning stays hidden.
A3: Prepared RC8 example: SAKS_NEW. Client/program text is descriptive only and never branches engine logic.
A4: 5-step setup
A5: 1 | B5: Instructions | C5: Choose interval/source sheets, target/floor, blank-demand policy, shift/OFF rules, and break policy using dropdowns. | E5: Input color guide
A6: 2 | B6: Schedule | C6: Enter each associate once: ID, email, name, TL, and language. Leave Sun–Sat blank. | E6: Yellow | F6: User input / dropdown
A7: 3 | B7: Requirements & Shrinkage | C7: Paste required HC into the selected FT Wise sheet. Closed intervals stay blank. Enter shrinkage in the matching sheet. | E7: Grey | F7: Reference, formula, or engine output area
A8: 4 | B8: Optional Requests | C8: Use Preference, Fixed Request, Language Setup, and Previous week scheduled only when applicable. | E8: Blue | F8: Section header / guidance
A9: 5 | B9: Validate & Run | C9: Open Input Checks. Resolve CHECK/MISSING items, then upload this workbook using the universal Colab runner. | E9: Green | F9: Ready / PASS
E10: Red | F10: Missing or inconsistent input
A12: Fixed engine protections — no manual solver tuning required
A13: • Final production decision is based on after-break coverage; BEST BEFORE remains a protected review artifact and recovery anchor.
A14: • Blank-demand policy is explicit. “No new staffing” is enforced in shift filtering, CP-SAT, repair, and final validation.
A15: • Overnight demand is interpreted cyclically, so 14:00–08:00 is not mistaken for 24/7.
A16: • Language/skill coverage is directional: source language → languages it can cover.
A17: • Rest, OFF/leave/fixed/nesting, opening, Next Sunday, hard floors, and approved exception caps remain authoritative.
A18: • Historical KPI workbooks are comparison references unless provenance matches the current input/contract and final artifact.
E19: Readiness snapshot
E20: Check | F20: Current status | G20: Go to
E21: Instruction sources aligned | F21: ='Input Checks'!B5 | G21: Instructions
E22: Roster ready | F22: ='Input Checks'!B7 | G22: Schedule
E23: Requirements loaded | F23: ='Input Checks'!B10 | G23: FT Wise selected source
E24: Allowed shifts loaded | F24: ='Input Checks'!B11 | G24: Shift Library
E25: Overall readiness | F25: ='Input Checks'!B15 | G25: Input Checks

Sheet SAKS New Test Setup
A1: SAKS New 51HC Production Test - 90% Interval KPI
A2: Pass goal | B2: 100% of active intervals must be >=90%; 80% remains the hard minimum floor. | C2: No fixed shifts or nesting groups are active.
A4: Field | B4: Value | C4: Notes
A5: Source file | B5: SAKS New.xlsx | C5: Uploaded workbook used for Required FTE and Shrinkage grids.
A6: Week dates | B6: 2026-07-12 to 2026-07-18 | C6: From uploaded sheet row 3.
A7: HC | B7: 51 | C7: Set by user.
A8: 11H / 3OFF allowed | B8: Yes | C8: Allowed by user. Engine may still prefer 9H if 100% target needs more weekly productive hours.
A9: Rest minimum | B9: 12 hours | C9: Set by user.
A10: Max shift types / week | B10: 3 | C10: Set by user.
A11: Shrinkage source | B11: Shrinkage 30 Min | C11: Per-interval shrinkage loaded from uploaded workbook.
A12: Positive demand intervals | B12: 252 | C12: Active weekly 30-minute intervals with requirement > 0.
A13: Required productive hours before shrinkage | B13: 1722.95 | C13: Sum(required FTE * 0.5h).
A14: Shrinkage-adjusted hours @ 100% target | B14: 2033.62 | C14: Full target coverage after shrinkage.
A15: Shrinkage-adjusted hours @ 90% quality band | B15: 1830.26 | C15: Desired operational quality band, not the target.
A16: Shrinkage-adjusted hours @ 80% minimum floor | B16: 1626.9 | C16: Hard minimum floor.
A17: Max interval requirement | B17: 27.4 | C17: Peak required FTE before shrinkage.
A18: Average shrinkage | B18: 0.1539 | C18: Across positive intervals with shrinkage values.
A19: Estimated 9H/2OFF net capacity | B19: 2040 | C19: Assumes 9h gross with 1h break = 8 productive hours, 5 working days.
A20: Estimated 11H/3OFF net capacity | B20: 1989 | C20: Assumes 11h gross with 1.25h break = 9.75 productive hours, 4 working days.
A21: 100% diagnostic buffer vs all-9H | B21: 6.38 | C21: Very tight if positive; infeasible by hours if negative.
A22: 100% diagnostic deficit vs all-11H | B22: 44.62 | C22: All-11H is likely insufficient by aggregate hours if positive.
A23: Approx max 11H associates if rest are 9H | B23: 6 | C23: Rough aggregate-hours limit before shape/break constraints.
A24: Target KPI | B24: 90% per active interval | C24: Actual/Required % must be >=90% after breaks and shrinkage.
A25: Desired production band | B25: Same as target: >=90% per active interval | C25: Corrected from earlier 100% target interpretation.
A26: Minimum floor | B26: 80% per active interval | C26: Hard floor; no 70% tolerance.
A27: Fixed/nesting requests | B27: Disabled | C27: Confirmed by user: no fixed shifts/nesting.
A28: Preferences/leaves | B28: None supplied | C28: Generic associate roster used; provide roster/preferences to make final production file exact.
A29: Allowed shift start window | B29: 13:00 - 22:00 | C29: Retained from SAKS template; confirm if starts outside this window are allowed.
A30: Shift start step | B30: 60 minutes | C30: Retained from SAKS template; confirm if half-hour starts should be allowed.
A31: Balance Coverage | B31: Yes | C31: Enabled for shortage/overage balancing validation.
A32: Capacity warning | B32: Tight but more realistic for 90% KPI | C32: 100% full coverage is diagnostic; requested pass target is all active intervals at >=90%.
A33: Overall schedule KPI | B33: 100% of active intervals >=90% | C33: Every active interval should meet or exceed the 90% threshold.
A34: 100% full coverage | B34: Tracked only | C34: Diagnostic metric, not the pass target.

Sheet RC7 Contract Audit
A1: RC7 Contract Audit
A2: Field | B2: Expected | C2: Parsed | D2: Status
A3: roster_count | B3: 50 | C3: 50 | D3: PASS
A4: instructed_headcount | B4: 50 | C4: 50 | D4: PASS
A5: program_name | B5: SAKS | C5: SAKS | D5: PASS
A6: interval_minutes | B6: 30 | C6: 30 | D6: PASS
A7: requirement_sheet | B7: FT Wise 30 Min | C7: FT Wise 30 Min | D7: PASS
A8: shrinkage_sheet | B8: Shrinkage 30 Min | C8: Shrinkage 30 Min | D8: PASS
A9: target_ratio | B9: 0.9 | C9: 0.9 | D9: PASS
A10: floor_ratio | B10: 0.8 | C10: 0.8 | D10: PASS
A11: floor_mode | B11: hard | C11: hard | D11: PASS
A12: target_priority_confirmed | B12: True | C12: True | D12: PASS
A13: allow_no_break_exceptions | B13: False | C13: False | D13: PASS
... A27: Parser warnings | B27: 0 | C27: 0 | D27: PASS
A28: Input SHA-256 before audit sheet | B28: 1625c219aa6cedf97f729542dc964ce0c5b3fc07c0d5ba0eaa1fd79bf54e998e | D28: INFO

Sheet Coverage KPI Rules
A1: Rule | B1: Value | C1: How to evaluate | D1: Notes
A2: Interval KPI threshold | B2: 90% | C2: Actual/Required % >= 90% | D2: This is the main scheduling target per active interval after breaks and shrinkage.
A3: Overall schedule KPI | B3: 100% | C3: 100% of active intervals must be >= 90% | D3: This is what the user means by overall schedule target = 100%.
A4: Hard minimum floor | B4: 80% | C4: Actual/Required % >= 80% | D4: Below 80% is a hard floor issue unless the case is proven infeasible.
A5: 100% full-coverage view | B5: Tracked only | C5: Actual/Required % >= 100% | D5: Useful diagnostic, but not the requested pass target.
A6: 90% KPI gap | B6: Max(0, 0.9*Required - Staffed) | C6: Shortage to the requested target threshold. | D6: Primary shortage metric for this test.
A7: 80% floor gap | B7: Max(0, 0.8*Required - Staffed) | C7: Shortage to the hard minimum floor. | D7: Should be zero or explained by infeasibility.
A8: Priority order | B8: Hard rules > staff integrity > 80% floor > 90% KPI > overage balance | C8: Used to interpret schedule quality. | D8: Do not improve overage balance by creating floor/KPI shortages.
A9: Fixed/nesting | B9: Disabled | C9: No fixed/nesting rows should be active. | D9: This production test uses 51 generic associates with no fixed/nesting lock.

Sheet Schedule
A1: Dynamic Schedule - V10 interval-aware optimized output | G1: Sun | H1: Mon | I1: Tue | J1: Wed | K1: Thu | L1: Fri | M1: Sat
A2: Slot | B2: Emp ID | C2: Email | D2: SF Name | E2: TL | F2: Language | G2: 46215 | H2: 46216 | I2: 46217 | J2: 46218 | K2: 46219 | L2: 46220 | M2: 46221 | N2: OFF | O2: Primary Shift | P2: Shift Types | Q2: Work Hours | R2: Rule Status
A3: 1 | D3: Associate 001 | F3: English
A4: 2 | D4: Associate 002 | F4: English
A5: 3 | D5: Associate 003 | F5: English
A6: 4 | D6: Associate 004 | F6: English
A7: 5 | D7: Associate 005 | F7: English
A8: 6 | D8: Associate 006 | F8: English
A9: 7 | D9: Associate 007 | F9: English
A10: 8 | D10: Associate 008 | F10: English
A11: 9 | D11: Associate 009 | F11: English
A12: 10 | D12: Associate 010 | F12: English
A13: 11 | D13: Associate 011 | F13: English
A14: 12 | D14: Associate 012 | F14: English
... A52: 50 | D52: Associate 050 | F52: English

Sheet FT Wise
B1: Required FTEs | K1: Staffed FTEs - Initial Schedule | AC1: Staffed FTEs After Shrinkage | AU1: Actual / Required % After Shrinkage | BD1: Interval Compliance Win After Shrinkage | BM1: Minimum 80% Check After Shrinkage | BV1: Hard Floor 70% Check After Shrinkage | CF1: Variance After Shrinkage (Actual - Required)
B2: Interval | C2: Sun | D2: Mon | E2: Tue | F2: Wed | G2: Thu | H2: Fri | I2: Sat | K2: Interval | L2: Sun | M2: Mon | N2: Tue | O2: Wed | P2: Thu | Q2: Fri | R2: Sat | AC2: Interval | AD2: Sun | AE2: Mon | AF2: Tue | AG2: Wed | AH2: Thu | AI2: Fri | AJ2: Sat | AU2: Interval | AV2: Sun | AW2: Mon | AX2: Tue | AY2: Wed | AZ2: Thu | BA2: Fri | BB2: Sat | BD2: Interval | BE2: Sun | BF2: Mon | BG2: Tue | BH2: Wed | BI2: Thu | BJ2: Fri | BK2: Sat | BM2: Interval | BN2: Sun | BO2: Mon | BP2: Tue | BQ2: Wed | BR2: Thu | BS2: Fri | BT2: Sat | BV2: Interval | BW2: Sun | BX2: Mon | BY2: Tue | BZ2: Wed | CA2: Thu | CB2: Fri | CC2: Sat | CF2: Interval | CG2: Sun | CH2: Mon | CI2: Tue | CJ2: Wed | CK2: Thu | CL2: Fri | CM2: Sat
B3: Interval | C3: 28-Jun | D3: 29-Jun | E3: 30-Jun | F3: 1-Jul | G3: 2-Jul | H3: 3-Jul | I3: 4-Jul | K3: Interval | L3: 28-Jun | M3: 29-Jun | N3: 30-Jun | O3: 1-Jul | P3: 2-Jul | Q3: 3-Jul | R3: 4-Jul | AC3: Interval | AD3: 28-Jun | AE3: 29-Jun | AF3: 30-Jun | AG3: 1-Jul | AH3: 2-Jul | AI3: 3-Jul | AJ3: 4-Jul | AU3: Interval | AV3: 28-Jun | AW3: 29-Jun | AX3: 30-Jun | AY3: 1-Jul | AZ3: 2-Jul | BA3: 3-Jul | BB3: 4-Jul | BD3: Interval | BE3: 28-Jun | BF3: 29-Jun | BG3: 30-Jun | BH3: 1-Jul | BI3: 2-Jul | BJ3: 3-Jul | BK3: 4-Jul | BM3: Interval | BN3: 28-Jun | BO3: 29-Jun | BP3: 30-Jun | BQ3: 1-Jul | BR3: 2-Jul | BS3: 3-Jul | BT3: 4-Jul | BV3: Interval | BW3: 28-Jun | BX3: 29-Jun | BY3: 30-Jun | BZ3: 1-Jul | CA3: 2-Jul | CB3: 3-Jul | CC3: 4-Jul | CF3: Interval | CG3: 28-Jun | CH3: 29-Jun | CI3: 30-Jun | CJ3: 1-Jul | CK3: 2-Jul | CL3: 3-Jul | CM3: 4-Jul
B4: 00:00 | K4: 00:00 | L4: =IF(C4="","",COUNTIFS('Scheduler Engine'!$N$2:$N$1751,1,'Scheduler Engine'!$L$2:$L$1751,"<="&((0)*24+VALUE(LEFT($K4,2))),'Scheduler Engine'!$M$2:$M$1751,">"&((0)*24+VALUE(LEFT($K4,2))))+COUNTIFS('Previous Engine'!$K$2:$K$251,1,'Previous Engine'!$H$2:$H$251,"<="&VALUE(LEFT($K4,2)),'Previous Engine'!$I$2:$I$251,">"&VALUE(LEFT($K4,2)))) | M4: =IF(D4="","",COUNTIFS('Scheduler Engine'!$N$2:$N$1751,1,'Scheduler Engine'!$L$2:$L$1751,"<="&((1)*24+VALUE(LEFT($K4,2))),'Scheduler Engine'!$M$2:$M$1751,">"&((1)*24+VALUE(LEFT($K4,2))))) | N4: =IF(E4="","",COUNTIFS('Scheduler Engine'!$N$2:$N$1751,1,'Scheduler Engine'!$L$2:$L$1751,"<="&((2)*24+VALUE(LEFT($K4,2))),'Scheduler Engine'!$M$2:$M$1751,">"&((2)*24+VALUE(LEFT($K4,2))))) | O4: =IF(F4="","",COUNTIFS('Scheduler Engine'!$N$2:$N$1751,1,'Scheduler Engine'!$L$2:$L$1751,"<="&((3)*24+VALUE(LEFT($K4,2))),'Scheduler Engine'!$M$2:$M$1751,">"&((3)*24+VALUE(LEFT($K4,2))))) | P4: =IF(G4="","",COUNTIFS('Scheduler Engine'!$N$2:$N$1751,1,'Scheduler Engine'!$L$2:$L$1751,"<="&((4)*24+VALUE(LEFT($K4,2))),'Scheduler Engine'!$M$2:$M$1751,">"&((4)*24+VALUE(LEFT($K4,2))))) | Q4: =IF(H4="","",COUNTIFS('Scheduler Engine'!$N$2:$N$1751,1,'Scheduler Engine'!$L$2:$L$1751,"<="&((5)*24+VALUE(LEFT($K4,2))),'Scheduler Engine'!$M$2:$M$1751,">"&((5)*24+VALUE(LEFT($K4,2))))) | R4: =IF(I4="","",COUNTIFS('Scheduler Engine'!$N$2:$N$1751,1,'Scheduler Engine'!$L$2:$L$1751,"<="&((6)*24+VALUE(LEFT($K4,2))),'Scheduler Engine'!$M$2:$M$1751,">"&((6)*24+VALUE(LEFT($K4,2))))) | AC4: 00:00 | AD4: =IF(C4="","",L4*(1-(IF(IFERROR(INDEX(Instructions!$B:$B,MATCH("Shrinkage Source",Instructions!$A:$A,0)),"Shrinkage Sheet")="Shrinkage Sheet",IFERROR(IF(Shrinkage!B4="-",IF(C4<IFERROR(INDEX(Instructions!$B:$B,MATCH("Shrinkage Threshold FTE",Instructions!$A:$A,0)),10),IFERROR(INDEX(Instructions!$B:$B,MATCH("Shrinkage Less Than 10 FTEs",Instructions!$A:$A,0)),20%),IFERROR(INDEX(Instructions!$B:$B,MATCH("Shrinkage 10 Or More FTEs",Instructions!$A:$A,0)),12%)),Shrinkage!B4),IF(C4<IFERROR(INDEX(Instructions!$B:$B,MATCH("Shrinkage Threshold FTE",Instructions!$A:$A,0)),10),IFERROR(INDEX(Instructions!$B:$B,MATCH("Shrinkage Less Than 10 FTEs",Instructions!$A:$A,0)),20%),IFERROR(INDEX(Instructions!$B:$B,MATCH("Shrinkage 10 Or More FTEs",Instructions!$A:$A,0)),12%))),IF(C4<IFERROR(INDEX(Instructions!$B:$B,MATCH("Shrinkage Threshold FTE",Instructions!$A:$A,0)),10),IFERROR(INDEX(Instructions!$B:$B,MATCH("Shrinkage Less Than 10 FTEs",Instructions!$A:$A,0)),20%),IFERROR(INDEX(Instructions!$B:$B,MATCH("Shrinkage 10 Or More FTEs",Instructions!$A:$A,0)),12%)))))) | AE4: =IF(D4="","",M4*(1-(IF(IFERROR(INDEX(Instructions!$B:$B,MATCH("Shrinkage Source",Instructions!$A:$A,0)),"Shrinkage Sheet")="Shrinkage Sheet",IFERROR(IF(Shrinkage!C4="-",IF(D4<IFERROR(INDEX(Instructions!$B:$B,MATCH("Shrinkage Threshold FTE",Instructions!$A:$A,0)),10),IFERROR(INDEX(Instructions!$B:$B,MATCH("Shrinkage Less Than 10 FTEs",Instructions!$A:$A,0)),20%),IFERROR(INDEX(Instructions!$B:$B,MATCH("Shrinkage 10 Or More FTEs",Instructions!$A:$A,0)),12%)),Shrinkage!C4),IF(D4<IFERROR(INDEX(Instructions!$B:$B,MATCH("Shrinkage Threshold FTE",Instructions!$A:$A,0)),10),IFERROR(INDEX(Instructions!$B:$B,MATCH("Shrinkage Less Than 10 FTEs",Instructions!$A:$A,0)),20%),IFERROR(INDEX(Instructions!$B:$B,MATCH("Shrinkage 10 Or More FTEs",Instructions!$A:$A,0)),12%))),IF(D4<IFERROR(INDEX(Instructions!$B:$B,MATCH("Shrinkage Threshold FTE",Instructions!$A:$A,0)),10),IFERROR(INDEX(Instructions!$B:$B,MATCH("Shrinkage Less Than 10 FTEs",Instructions!$A:$A,0)),20%),IFERROR(INDEX(Instructions!$B:$B,MATCH("Shrinkage 10 Or More FTEs",Instructions!$A:$A,0)),12%)))))) | AF4: =IF(E4="","",N4*(1-(IF(IFERROR(INDEX(Instructions!$B:$B,MATCH("Shrinkage Source",Instructions!$A:$A,0)),"Shrinkage Sheet")="Shrinkage Sheet",IFERROR(IF(Shrinkage!D4="-",IF(E4<IFERROR(INDEX(Instructions!$B:$B,MATCH("Shrinkage Threshold FTE",Instructions!$A:$A,0)),10),IFERROR(INDEX(Instructions!$B:$B,MATCH("Shrinkage Less Than 10 FTEs",Instructions!$A:$A,0)),20%),IFERROR(INDEX(Instructions!$B:$B,MATCH("Shrinkage 10 Or More FTEs",Instructions!$A:$A,0)),12%)),Shrinkage!D4),IF(E4<IFERROR(INDEX(Instructions!$B:$B,MATCH("Shrinkage Threshold FTE",Instructions!$A:$A,0)),10),IFERROR(INDEX(Instructions!$B:$B,MATCH("Shrinkage Less Than 10 FTEs",Instructions!$A:$A,0)),20%),IFERROR(INDEX(Instructions!$B:$B,MATCH("Shrinkage 10 Or More FTEs",Instructions!$A:$A,0)),12%))),IF(E4<IFERROR(INDEX(Instructions!$B:$B,MATCH("Shrinkage Threshold FTE",Instructions!$A:$A,0)),10),IFERROR(INDEX(Instructions!$B:$B,MATCH("Shrinkage Less Than 10 FTEs",Instructions!$A:$A,0)),20%),IFERROR(INDEX(Instructions!$B:$B,MATCH("Shrinkage 10 Or More FTEs",Instructions!$A:$A,0)),12%)))))) | AG4: =IF(F4="","",O4*(1-(IF(IFERROR(INDEX(Instructions!$B:$B,MATCH("Shrinkage Source",Instructions!$A:$A,0)),"Shrinkage Sheet")="Shrinkage Sheet",IFERROR(IF(Shrinkage!E4="-",IF(F4<IFERROR(INDEX(Instructions!$B:$B,MATCH("Shrinkage Threshold FTE",Instructions!$A:$A,0)),10),IFERROR(INDEX(Instructions!$B:$B,MATCH("Shrinkage Less Than 10 FTEs",Instructions!$A:$A,0)),20%),IFERROR(INDEX(Instructions!$B:$B,MATCH("Shrinkage 10 Or More FTEs",Instructions!$A:$A,0)),12%)),Shrinkage!E4),IF(F4<IFERROR(INDEX(Instructions!$B:$B,MATCH("Shrinkage Threshold FTE",Instructions!$A:$A,0)),10),IFERROR(INDEX(Instructions!$B:$B,MATCH("Shrinkage Less Than 10 FTEs",Instructions!$A:$A,0)),20%),IFERROR(INDEX(Instructions!$B:$B,MATCH("Shrinkage 10 Or More FTEs",Instructions!$A:$A,0)),12%))),IF(F4<IFERROR(INDEX(Instructions!$B:$B,MATCH("Shrinkage Threshold FTE",Instructions!$A:$A,0)),10),IFERROR(INDEX(Instructions!$B:$B,MATCH("Shrinkage Less Than 10 FTEs",Instructions!$A:$A,0)),20%),IFERROR(INDEX(Instructions!$B:$B,MATCH("Shrinkage 10 Or More FTEs",Instructions!$A:$A,0)),12%)))))) | AH4: =IF(G4="","",P4*(1-(IF(IFERROR(INDEX(Instructions!$B:$B,MATCH("Shrinkage Source",Instructions!$A:$A,0)),"Shrinkage Sheet")="Shrinkage Sheet",IFERROR(IF(Shrinkage!F4="-",IF(G4<IFERROR(INDEX(Instructions!$B:$B,MATCH("Shrinkage Threshold FTE",Instructions!$A:$A,0)),10),IFERROR(INDEX(Instructions!$B:$B,MATCH("Shrinkage Less Than 10 FTEs",Instructions!$A:$A,0)),20%),IFERROR(INDEX(Instructions!$B:$B,MATCH("Shrinkage 10 Or More FTEs",Instructions!$A:$A,0)),12%)),Shrinkage!F4),IF(G4<IFERROR(INDEX(Instructions!$B:$B,MATCH("Shrinkage Threshold FTE",Instructions!$A:$A,0)),10),IFERROR(INDEX(Instructions!$B:$B,MATCH("Shrinkage Less Than 10 FTEs",Instructions!$A:$A,0)),20%),IFERROR(INDEX(Instructions!$B:$B,MATCH("Shrinkage 10 Or More FTEs",Instructions!$A:$A,0)),12%))),IF(G4<IFERROR(INDEX(Instructions!$B:$B,MATCH("Shrinkage Threshold FTE",Instructions!$A:$A,0)),10),IFERROR(INDEX(Instructions!$B:$B,MATCH("Shrinkage Less Than 10 FTEs",Instructions!$A:$A,0)),20%),IFERROR(INDEX(Instructions!$B:$B,MATCH("Shrinkage 10 Or More FTEs",Instructions!$A:$A,0)),12%)))))) | AI4: =IF(H4="","",Q4*(1-(IF(IFERROR(INDEX(Instructions!$B:$B,MATCH("Shrinkage Source",Instructions!$A:$A,0)),"Shrinkage Sheet")="Shrinkage Sheet",IFERROR(IF(Shrinkage!G4="-",IF(H4<IFERROR(INDEX(Instructions!$B:$B,MATCH("Shrinkage Threshold FTE",Instructions!$A:$A,0)),10),IFERROR(INDEX(Instructions!$B:$B,MATCH("Shrinkage Less Than 10 FTEs",Instructions!$A:$A,0)),20%),IFERROR(INDEX(Instructions!$B:$B,MATCH("Shrinkage 10 Or More FTEs",Instructions!$A:$A,0)),12%)),Shrinkage!G4),IF(H4<IFERROR(INDEX(Instructions!$B:$B,MATCH("Shrinkage Threshold FTE",Instructions!$A:$A,0)),10),IFERROR(INDEX(Instructions!$B:$B,MATCH("Shrinkage Less Than 10 FTEs",Instructions!$A:$A,0)),20%),IFERROR(INDEX(Instructions!$B:$B,MATCH("Shrinkage 10 Or More FTEs",Instructions!$A:$A,0)),12%))),IF(H4<IFERROR(INDEX(Instructions!$B:$B,MATCH("Shrinkage Threshold FTE",Instructions!$A:$A,0)),10),IFERROR(INDEX(Instructions!$B:$B,MATCH("Shrinkage Less Than 10 FTEs",Instructions!$A:$A,0)),20%),IFERROR(INDEX(Instructions!$B:$B,MATCH("Shrinkage 10 Or More FTEs",Instructions!$A:$A,0)),12%)))))) | AJ4: =IF(I4="","",R4*(1-(IF(IFERROR(INDEX(Instructions!$B:$B,MATCH("Shrinkage Source",Instructions!$A:$A,0)),"Shrinkage Sheet")="Shrinkage Sheet",IFERROR(IF(Shrinkage!H4="-",IF(I4<IFERROR(INDEX(Instructions!$B:$B,MATCH("Shrinkage Threshold FTE",Instructions!$A:$A,0)),10),IFERROR(INDEX(Instructions!$B:$B,MATCH("Shrinkage Less Than 10 FTEs",Instructions!$A:$A,0)),20%),IFERROR(INDEX(Instructions!$B:$B,MATCH("Shrinkage 10 Or More FTEs",Instructions!$A:$A,0)),12%)),Shrinkage!H4),IF(I4<IFERROR(INDEX(Instructions!$B:$B,MATCH("Shrinkage Threshold FTE",Instructions!$A:$A,0)),10),IFERROR(INDEX(Instructions!$B:$B,MATCH("Shrinkage Less Than 10 FTEs",Instructions!$A:$A,0)),20%),IFERROR(INDEX(Instructions!$B:$B,MATCH("Shrinkage 10 Or More FTEs",Instructions!$A:$A,0)),12%))),IF(I4<IFERROR(INDEX(Instructions!$B:$B,MATCH("Shrinkage Threshold FTE",Instructions!$A:$A,0)),10),IFERROR(INDEX(Instructions!$B:$B,MATCH("Shrinkage Less Than 10 FTEs",Instructions!$A:$A,0)),20%),IFERROR(INDEX(Instructions!$B:$B,MATCH("Shrinkage 10 Or More FTEs",Instructions!$A:$A,0)),12%)))))) | AU4: 00:00 | AV4: =IFERROR(AD4/C4,"") | AW4: =IFERROR(AE4/D4,"") | AX4: =IFERROR(AF4/E4,"") | AY4: =IFERROR(AG4/F4,"") | AZ4: =IFERROR(AH4/G4,"") | BA4: =IFERROR(AI4/H4,"") | BB4: =IFERROR(AJ4/I4,"") | BD4: 00:00 | BE4: =IF(C4="","",IF(AV4>=Instructions!$B$15,1,0)) | BF4: =IF(D4="","",IF(AW4>=Instructions!$B$15,1,0)) | BG4: =IF(E4="","",IF(AX4>=Instructions!$B$15,1,0)) | BH4: =IF(F4="","",IF(AY4>=Instructions!$B$15,1,0)) | BI4: =IF(G4="","",IF(AZ4>=Instructions!$B$15,1,0)) | BJ4: =IF(H4="","",IF(BA4>=Instructions!$B$15,1,0)) | BK4: =IF(I4="","",IF(BB4>=Instructions!$B$15,1,0)) | BM4: 00:00 | BN4: =IF(C4="","",IF(AV4>=Instructions!$B$16,1,0)) | BO4: =IF(D4="","",IF(AW4>=Instructions!$B$16,1,0)) | BP4: =IF(E4="","",IF(AX4>=Instructions!$B$16,1,0)) | BQ4: =IF(F4="","",IF(AY4>=Instructions!$B$16,1,0)) | BR4: =IF(G4="","",IF(AZ4>=Instructions!$B$16,1,0)) | BS4: =IF(H4="","",IF(BA4>=Instructions!$B$16,1,0)) | BT4: =IF(I4="","",IF(BB4>=Instructions!$B$16,1,0)) | BV4: 00:00 | BW4: =IF(C4="","",IF(ROUND(AV4,6)>=ROUND(Instructions!$B$16-Instructions!$B$17,6),1,0)) | BX4: =IF(D4="","",IF(ROUND(AW4,6)>=ROUND(Instructions!$B$16-Instructions!$B$17,6),1,0)) | BY4: =IF(E4="","",IF(ROUND(AX4,6)>=ROUND(Instructions!$B$16-Instructions!$B$17,6),1,0)) | BZ4: =IF(F4="","",IF(ROUND(AY4,6)>=ROUND(Instructions!$B$16-Instructions!$B$17,6),1,0)) | CA4: =IF(G4="","",IF(ROUND(AZ4,6)>=ROUND(Instructions!$B$16-Instructions!$B$17,6),1,0)) | CB4: =IF(H4="","",IF(ROUND(BA4,6)>=ROUND(Instructions!$B$16-Instructions!$B$17,6),1,0)) | CC4: =IF(I4="","",IF(ROUND(BB4,6)>=ROUND(Instructions!$B$16-Instructions!$B$17,6),1,0)) | CF4: 00:00 | CG4: =IF(C4="","",AD4-C4) | CH4: =IF(D4="","",AE4-D4) | CI4: =IF(E4="","",AF4-E4) | CJ4: =IF(F4="","",AG4-F4) | CK4: =IF(G4="","",AH4-G4) | CL4: =IF(H4="","",AI4-H4) | CM4: =IF(I4="","",AJ4-I4)
B5: 01:00 | K5: 01:00 | L5: =IF(C5="","",COUNTIFS('Scheduler Engine'!$N$2:$N$1751,1,'Scheduler Engine'!$L$2:$L$1751,"<="&((0)*24+VALUE(LEFT($K5,2))),'Scheduler Engine'!$M$2:$M$1751,">"&((0)*24+VALUE(LEFT($K5,2))))+COUNTIFS('Previous Engine'!$K$2:$K$251,1,'Previous Engine'!$H$2:$H$251,"<="&VALUE(LEFT($K5,2)),'Previous Engine'!$I$2:$I$251,">"&VALUE(LEFT($K5,2)))) | M5: =IF(D5="","",COUNTIFS('Scheduler Engine'!$N$2:$N$1751,1,'Scheduler Engine'!$L$2:$L$1751,"<="&((1)*24+VALUE(LEFT($K5,2))),'Scheduler Engine'!$M$2:$M$1751,">"&((1)*24+VALUE(LEFT($K5,2))))) | N5: =IF(E5="","",COUNTIFS('Scheduler Engine'!$N$2:$N$1751,1,'Scheduler Engine'!$L$2:$L$1751,"<="&((2)*24+VALUE(LEFT($K5,2))),'Scheduler Engine'!$M$2:$M$1751,">"&((2)*24+VALUE(LEFT($K5,2))))) | O5: =IF(F5="","",COUNTIFS('Scheduler Engine'!$N$2:$N$1751,1,'Scheduler Engine'!$L$2:$L$1751,"<="&((3)*24+VALUE(LEFT($K5,2))),'Scheduler Engine'!$M$2:$M$1751,">"&((3)*24+VALUE(LEFT($K5,2))))) | P5: =IF(G5="","",COUNTIFS('Scheduler Engine'!$N$2:$N$1751,1,'Scheduler Engine'!$L$2:$L$1751,"<="&((4)*24+VALUE(LEFT($K5,2))),'Scheduler Engine'!$M$2:$M$1751,">"&((4)*24+VALUE(LEFT($K5,2))))) | Q5: =IF(H5="","",COUNTIFS('Scheduler Engine'!$N$2:$N$1751,1,'Scheduler Engine'!$L$2:$L$1751,"<="&((5)*24+VALUE(LEFT($K5,2))),'Scheduler Engine'!$M$2:$M$1751,">"&((5)*24+VALUE(LEFT($K5,2))))) | R5: =IF(I5="","",COUNTIFS('Scheduler Engine'!$N$2:$N$1751,1,'Scheduler Engine'!$L$2:$L$1751,"<="&((6)*24+VALUE(LEFT($K5,2))),'Scheduler Engine'!$M$2:$M$1751,">"&((6)*24+VALUE(LEFT($K5,2))))) | AC5: 01:00 | AD5: =IF(C5="","",L5*(1-(IF(IFERROR(INDEX(Instructions!$B:$B,MATCH("Shrinkage Source",Instructions!$A:$A,0)),"Shrinkage Sheet")="Shrinkage Sheet",IFERROR(IF(Shrinkage!B5="-",IF(C5<IFERROR(INDEX(Instructions!$B:$B,MATCH("Shrinkage Threshold FTE",Instructions!$A:$A,0)),10),IFERROR(INDEX(Instructions!$B:$B,MATCH("Shrinkage Less Than 10 FTEs",Instructions!$A:$A,0)),20%),IFERROR(INDEX(Instructions!$B:$B,MATCH("Shrinkage 10 Or More FTEs",Instructions!$A:$A,0)),12%)),Shrinkage!B5),IF(C5<IFERROR(INDEX(Instructions!$B:$B,MATCH("Shrinkage Threshold FTE",Instructions!$A:$A,0)),10),IFERROR(INDEX(Instructions!$B:$B,MATCH("Shrinkage Less Than 10 FTEs",Instructions!$A:$A,0)),20%),IFERROR(INDEX(Instructions!$B:$B,MATCH("Shrinkage 10 Or More FTEs",Instructions!$A:$A,0)),12%))),IF(C5<IFERROR(INDEX(Instructions!$B:$B,MATCH("Shrinkage Threshold FTE",Instructions!$A:$A,0)),10),IFERROR(INDEX(Instructions!$B:$B,MATCH("Shrinkage Less Than 10 FTEs",Instructions!$A:$A,0)),20%),IFERROR(INDEX(Instructions!$B:$B,MATCH("Shrinkage 10 Or More FTEs",Instructions!$A:$A,0)),12%)))))) | AE5: =IF(D5="","",M5*(1-(IF(IFERROR(INDEX(Instructions!$B:$B,MATCH("Shrinkage Source",Instructions!$A:$A,0)),"Shrinkage Sheet")="Shrinkage Sheet",IFERROR(IF(Shrinkage!C5="-",IF(D5<IFERROR(INDEX(Instructions!$B:$B,MATCH("Shrinkage Threshold FTE",Instructions!$A:$A,0)),10),IFERROR(INDEX(Instructions!$B:$B,MATCH("Shrinkage Less Than 10 FTEs",Instructions!$A:$A,0)),20%),IFERROR(INDEX(Instructions!$B:$B,MATCH("Shrinkage 10 Or More FTEs",Instructions!$A:$A,0)),12%)),Shrinkage!C5),IF(D5<IFERROR(INDEX(Instructions!$B:$B,MATCH("Shrinkage Threshold FTE",Instructions!$A:$A,0)),10),IFERROR(INDEX(Instructions!$B:$B,MATCH("Shrinkage Less Than 10 FTEs",Instructions!$A:$A,0)),20%),IFERROR(INDEX(Instructions!$B:$B,MATCH("Shrinkage 10 Or More FTEs",Instructions!$A:$A,0)),12%))),IF(D5<IFERROR(INDEX(Instructions!$B:$B,MATCH("Shrinkage Threshold FTE",Instructions!$A:$A,0)),10),IFERROR(INDEX(Instructions!$B:$B,MATCH("Shrinkage Less Than 10 FTEs",Instructions!$A:$A,0)),20%),IFERROR(INDEX(Instructions!$B:$B,MATCH("Shrinkage 10 Or More FTEs",Instructions!$A:$A,0)),12%)))))) | AF5: =IF(E5="","",N5*(1-(IF(IFERROR(INDEX(Instructions!$B:$B,MATCH("Shrinkage Source",Instructions!$A:$A,0)),"Shrinkage Sheet")="Shrinkage Sheet",IFERROR(IF(Shrinkage!D5="-",IF(E5<IFERROR(INDEX(Instructions!$B:$B,MATCH("Shrinkage Threshold FTE",Instructions!$A:$A,0)),10),IFERROR(INDEX(Instructions!$B:$B,MATCH("Shrinkage Less Than 10 FTEs",Instructions!$A:$A,0)),20%),IFERROR(INDEX(Instructions!$B:$B,MATCH("Shrinkage 10 Or More FTEs",Instructions!$A:$A,0)),12%)),Shrinkage!D5),IF(E5<IFERROR(INDEX(Instructions!$B:$B,MATCH("Shrinkage Threshold FTE",Instructions!$A:$A,0)),10),IFERROR(INDEX(Instructions!$B:$B,MATCH("Shrinkage Less Than 10 FTEs",Instructions!$A:$A,0)),20%),IFERROR(INDEX(Instructions!$B:$B,MATCH("Shrinkage 10 Or More FTEs",Instructions!$A:$A,0)),12%))),IF(E5<IFERROR(INDEX(Instructions!$B:$B,MATCH("Shrinkage Threshold FTE",Instructions!$A:$A,0)),10),IFERROR(INDEX(Instructions!$B:$B,MATCH("Shrinkage Less Than 10 FTEs",Instructions!$A:$A,0)),20%),IFERROR(INDEX(Instructions!$B:$B,MATCH("Shrinkage 10 Or More FTEs",Instructions!$A:$A,0)),12%)))))) | AG5: =IF(F5="","",O5*(1-(IF(IFERROR(INDEX(Instructions!$B:$B,MATCH("Shrinkage Source",Instructions!$A:$A,0)),"Shrinkage Sheet")="Shrinkage Sheet",IFERROR(IF(Shrinkage!E5="-",IF(F5<IFERROR(INDEX(Instructions!$B:$B,MATCH("Shrinkage Threshold FTE",Instructions!$A:$A,0)),10),IFERROR(INDEX(Instructions!$B:$B,MATCH("Shrinkage Less Than 10 FTEs",Instructions!$A:$A,0)),20%),IFERROR(INDEX(Instructions!$B:$B,MATCH("Shrinkage 10 Or More FTEs",Instructions!$A:$A,0)),12%)),Shrinkage!E5),IF(F5<IFERROR(INDEX(Instructions!$B:$B,MATCH("Shrinkage Threshold FTE",Instructions!$A:$A,0)),10),IFERROR(INDEX(Instructions!$B:$B,MATCH("Shrinkage Less Than 10 FTEs",Instructions!$A:$A,0)),20%),IFERROR(INDEX(Instructions!$B:$B,MATCH("Shrinkage 10 Or More FTEs",Instructions!$A:$A,0)),12%))),IF(F5<IFERROR(INDEX(Instructions!$B:$B,MATCH("Shrinkage Threshold FTE",Instructions!$A:$A,0)),10),IFERROR(INDEX(Instructions!$B:$B,MATCH("Shrinkage Less Than 10 FTEs",Instructions!$A:$A,0)),20%),IFERROR(INDEX(Instructions!$B:$B,MATCH("Shrinkage 10 Or More FTEs",Instructions!$A:$A,0)),12%)))))) | AH5: =IF(G5="","",P5*(1-(IF(IFERROR(INDEX(Instructions!$B:$B,MATCH("Shrinkage Source",Instructions!$A:$A,0)),"Shrinkage Sheet")="Shrinkage Sheet",IFERROR(IF(Shrinkage!F5="-",IF(G5<IFERROR(INDEX(Instructions!$B:$B,MATCH("Shrinkage Threshold FTE",Instructions!$A:$A,0)),10),IFERROR(INDEX(Instructions!$B:$B,MATCH("Shrinkage Less Than 10 FTEs",Instructions!$A:$A,0)),20%),IFERROR(INDEX(Instructions!$B:$B,MATCH("Shrinkage 10 Or More FTEs",Instructions!$A:$A,0)),12%)),Shrinkage!F5),IF(G5<IFERROR(INDEX(Instructions!$B:$B,MATCH("Shrinkage Threshold FTE",Instructions!$A:$A,0)),10),IFERROR(INDEX(Instructions!$B:$B,MATCH("Shrinkage Less Than 10 FTEs",Instructions!$A:$A,0)),20%),IFERROR(INDEX(Instructions!$B:$B,MATCH("Shrinkage 10 Or More FTEs",Instructions!$A:$A,0)),12%))),IF(G5<IFERROR(INDEX(Instructions!$B:$B,MATCH("Shrinkage Threshold FTE",Instructions!$A:$A,0)),10),IFERROR(INDEX(Instructions!$B:$B,MATCH("Shrinkage Less Than 10 FTEs",Instructions!$A:$A,0)),20%),IFERROR(INDEX(Instructions!$B:$B,MATCH("Shrinkage 10 Or More FTEs",Instructions!$A:$A,0)),12%)))))) | AI5: =IF(H5="","",Q5*(1-(IF(IFERROR(INDEX(Instructions!$B:$B,MATCH("Shrinkage Source",Instructions!$A:$A,0)),"Shrinkage Sheet")="Shrinkage Sheet",IFERROR(IF(Shrinkage!G5="-",IF(H5<IFERROR(INDEX(Instructions!$B:$B,MATCH("Shrinkage Threshold FTE",Instructions!$A:$A,0)),10),IFERROR(INDEX(Instructions!$B:$B,MATCH("Shrinkage Less Than 10 FTEs",Instructions!$A:$A,0)),20%),IFERROR(INDEX(Instructions!$B:$B,MATCH("Shrinkage 10 Or More FTEs",Instructions!$A:$A,0)),12%)),Shrinkage!G5),IF(H5<IFERROR(INDEX(Instructions!$B:$B,MATCH("Shrinkage Threshold FTE",Instructions!$A:$A,0)),10),IFERROR(INDEX(Instructions!$B:$B,MATCH("Shrinkage Less Than 10 FTEs",Instructions!$A:$A,0)),20%),IFERROR(INDEX(Instructions!$B:$B,MATCH("Shrinkage 10 Or More FTEs",Instructions!$A:$A,0)),12%))),IF(H5<IFERROR(INDEX(Instructions!$B:$B,MATCH("Shrinkage Threshold FTE",Instructions!$A:$A,0)),10),IFERROR(INDEX(Instructions!$B:$B,MATCH("Shrinkage Less Than 10 FTEs",Instructions!$A:$A,0)),20%),IFERROR(INDEX(Instructions!$B:$B,MATCH("Shrinkage 10 Or More FTEs",Instructions!$A:$A,0)),12%)))))) | AJ5: =IF(I5="","",R5*(1-(IF(IFERROR(INDEX(Instructions!$B:$B,MATCH("Shrinkage Source",Instructions!$A:$A,0)),"Shrinkage Sheet")="Shrinkage Sheet",IFERROR(IF(Shrinkage!H5="-",IF(I5<IFERROR(INDEX(Instructions!$B:$B,MATCH("Shrinkage Threshold FTE",Instructions!$A:$A,0)),10),IFERROR(INDEX(Instructions!$B:$B,MATCH("Shrinkage Less Than 10 FTEs",Instructions!$A:$A,0)),20%),IFERROR(INDEX(Instructions!$B:$B,MATCH("Shrinkage 10 Or More FTEs",Instructions!$A:$A,0)),12%)),Shrinkage!H5),IF(I5<IFERROR(INDEX(Instructions!$B:$B,MATCH("Shrinkage Threshold FTE",Instructions!$A:$A,0)),10),IFERROR(INDEX(Instructions!$B:$B,MATCH("Shrinkage Less Than 10 FTEs",Instructions!$A:$A,0)),20%),IFERROR(INDEX(Instructions!$B:$B,MATCH("Shrinkage 10 Or More FTEs",Instructions!$A:$A,0)),12%))),IF(I5<IFERROR(INDEX(Instructions!$B:$B,MATCH("Shrinkage Threshold FTE",Instructions!$A:$A,0)),10),IFERROR(INDEX(Instructions!$B:$B,MATCH("Shrinkage Less Than 10 FTEs",Instructions!$A:$A,0)),20%),IFERROR(INDEX(Instructions!$B:$B,MATCH("Shrinkage 10 Or More FTEs",Instructions!$A:$A,0)),12%)))))) | AU5: 01:00 | AV5: =IFERROR(AD5/C5,"") | AW5: =IFERROR(AE5/D5,"") | AX5: =IFERROR(AF5/E5,"") | AY5: =IFERROR(AG5/F5,"") | AZ5: =IFERROR(AH5/G5,"") | BA5: =IFERROR(AI5/H5,"") | BB5: =IFERROR(AJ5/I5,"") | BD5: 01:00 | BE5: =IF(C5="","",IF(AV5>=Instructions!$B$15,1,0)) | BF5: =IF(D5="","",IF(AW5>=Instructions!$B$15,1,0)) | BG5: =IF(E5="","",IF(AX5>=Instructions!$B$15,1,0)) | BH5: =IF(F5="","",IF(AY5>=Instructions!$B$15,1,0)) | BI5: =IF(G5="","",IF(AZ5>=Instructions!$B$15,1,0)) | BJ5: =IF(H5="","",IF(BA5>=Instructions!$B$15,1,0)) | BK5: =IF(I5="","",IF(BB5>=Instructions!$B$15,1,0)) | BM5: 01:00 | BN5: =IF(C5="","",IF(AV5>=Instructions!$B$16,1,0)) | BO5: =IF(D5="","",IF(AW5>=Instructions!$B$16,1,0)) | BP5: =IF(E5="","",IF(AX5>=Instructions!$B$16,1,0)) | BQ5: =IF(F5="","",IF(AY5>=Instructions!$B$16,1,0)) | BR5: =IF(G5="","",IF(AZ5>=Instructions!$B$16,1,0)) | BS5: =IF(H5="","",IF(BA5>=Instructions!$B$16,1,0)) | BT5: =IF(I5="","",IF(BB5>=Instructions!$B$16,1,0)) | BV5: 01:00 | BW5: =IF(C5="","",IF(ROUND(AV5,6)>=ROUND(Instructions!$B$16-Instructions!$B$17,6),1,0)) | BX5: =IF(D5="","",IF(ROUND(AW5,6)>=ROUND(Instructions!$B$16-Instructions!$B$17,6),1,0)) | BY5: =IF(E5="","",IF(ROUND(AX5,6)>=ROUND(Instructions!$B$16-Instructions!$B$17,6),1,0)) | BZ5: =IF(F5="","",IF(ROUND(AY5,6)>=ROUND(Instructions!$B$16-Instructions!$B$17,6),1,0)) | CA5: =IF(G5="","",IF(ROUND(AZ5,6)>=ROUND(Instructions!$B$16-Instructions!$B$17,6),1,0)) | CB5: =IF(H5="","",IF(ROUND(BA5,6)>=ROUND(Instructions!$B$16-Instructions!$B$17,6),1,0)) | CC5: =IF(I5="","",IF(ROUND(BB5,6)>=ROUND(Instructions!$B$16-Instructions!$B$17,6),1,0)) | CF5: 01:00 | CG5: =IF(C5="","",AD5-C5) | CH5: =IF(D5="","",AE5-D5) | CI5: =IF(E5="","",AF5-E5) | CJ5: =IF(F5="","",AG5-F5) | CK5: =IF(G5="","",AH5-G5) | CL5: =IF(H5="","",AI5-H5) | CM5: =IF(I5="","",AJ5-I5)
B6: 02:00 | K6: 02:00 | L6: =IF(C6="","",COUNTIFS('Scheduler Engine'!$N$2:$N$1751,1,'Scheduler Engine'!$L$2:$L$1751,"<="&((0)*24+VALUE(LEFT($K6,2))),'Scheduler Engine'!$M$2:$M$1751,">"&((0)*24+VALUE(LEFT($K6,2))))+COUNTIFS('Previous Engine'!$K$2:$K$251,1,'Previous Engine'!$H$2:$H$251,"<="&VALUE(LEFT($K6,2)),'Previous Engine'!$I$2:$I$251,">"&VALUE(LEFT($K6,2)))) | M6: =IF(D6="","",COUNTIFS('Scheduler Engine'!$N$2:$N$1751,1,'Scheduler Engine'!$L$2:$L$1751,"<="&((1)*24+VALUE(LEFT($K6,2))),'Scheduler Engine'!$M$2:$M$1751,">"&((1)*24+VALUE(LEFT($K6,2))))) | N6: =IF(E6="","",COUNTIFS('Scheduler Engine'!$N$2:$N$1751,1,'Scheduler Engine'!$L$2:$L$1751,"<="&((2)*24+VALUE(LEFT($K6,2))),'Scheduler Engine'!$M$2:$M$1751,">"&((2)*24+VALUE(LEFT($K6,2))))) | O6: =IF(F6="","",COUNTIFS('Scheduler Engine'!$N$2:$N$1751,1,'Scheduler Engine'!$L$2:$L$1751,"<="&((3)*24+VALUE(LEFT($K6,2))),'Scheduler Engine'!$M$2:$M$1751,">"&((3)*24+VALUE(LEFT($K6,2))))) | P6: =IF(G6="","",COUNTIFS('Scheduler Engine'!$N$2:$N$1751,1,'Scheduler Engine'!$L$2:$L$1751,"<="&((4)*24+VALUE(LEFT($K6,2))),'Scheduler Engine'!$M$2:$M$1751,">"&((4)*24+VALUE(LEFT($K6,2))))) | Q6: =IF(H6="","",COUNTIFS('Scheduler Engine'!$N$2:$N$1751,1,'Scheduler Engine'!$L$2:$L$1751,"<="&((5)*24+VALUE(LEFT($K6,2))),'Scheduler Engine'!$M$2:$M$1751,">"&((5)*24+VALUE(LEFT($K6,2))))) | R6: =IF(I6="","",COUNTIFS('Scheduler Engine'!$N$2:$N$1751,1,'Scheduler Engine'!$L$2:$L$1751,"<="&((6)*24+VALUE(LEFT($K6,2))),'Scheduler Engine'!$M$2:$M$1751,">"&((6)*24+VALUE(LEFT($K6,2))))) | AC6: 02:00 | AD6: =IF(C6="","",L6*(1-(IF(IFERROR(INDEX(Instructions!$B:$B,MATCH("Shrinkage Source",Instructions!$A:$A,0)),"Shrinkage Sheet")="Shrinkage Sheet",IFERROR(IF(Shrinkage!B6="-",IF(C6<IFERROR(INDEX(Instructions!$B:$B,MATCH("Shrinkage Threshold FTE",Instructions!$A:$A,0)),10),IFERROR(INDEX(Instructions!$B:$B,MATCH("Shrinkage Less Than 10 FTEs",Instructions!$A:$A,0)),20%),IFERROR(INDEX(Instructions!$B:$B,MATCH("Shrinkage 10 Or More FTEs",Instructions!$A:$A,0)),12%)),Shrinkage!B6),IF(C6<IFERROR(INDEX(Instructions!$B:$B,MATCH("Shrinkage Threshold FTE",Instructions!$A:$A,0)),10),IFERROR(INDEX(Instructions!$B:$B,MATCH("Shrinkage Less Than 10 FTEs",Instructions!$A:$A,0)),20%),IFERROR(INDEX(Instructions!$B:$B,MATCH("Shrinkage 10 Or More FTEs",Instructions!$A:$A,0)),12%))),IF(C6<IFERROR(INDEX(Instructions!$B:$B,MATCH("Shrinkage Threshold FTE",Instructions!$A:$A,0)),10),IFERROR(INDEX(Instructions!$B:$B,MATCH("Shrinkage Less Than 10 FTEs",Instructions!$A:$A,0)),20%),IFERROR(INDEX(Instructions!$B:$B,MATCH("Shrinkage 10 Or More FTEs",Instructions!$A:$A,0)),12%)))))) | AE6: =IF(D6="","",M6*(1-(IF(IFERROR(INDEX(Instructions!$B:$B,MATCH("Shrinkage Source",Instructions!$A:$A,0)),"Shrinkage Sheet")="Shrinkage Sheet",IFERROR(IF(Shrinkage!C6="-",IF(D6<IFERROR(INDEX(Instructions!$B:$B,MATCH("Shrinkage Threshold FTE",Instructions!$A:$A,0)),10),IFERROR(INDEX(Instructions!$B:$B,MATCH("Shrinkage Less Than 10 FTEs",Instructions!$A:$A,0)),20%),IFERROR(INDEX(Instructions!$B:$B,MATCH("Shrinkage 10 Or More FTEs",Instructions!$A:$A,0)),12%)),Shrinkage!C6),IF(D6<IFERROR(INDEX(Instructions!$B:$B,MATCH("Shrinkage Threshold FTE",Instructions!$A:$A,0)),10),IFERROR(INDEX(Instructions!$B:$B,MATCH("Shrinkage Less Than 10 FTEs",Instructions!$A:$A,0)),20%),IFERROR(INDEX(Instructions!$B:$B,MATCH("Shrinkage 10 Or More FTEs",Instructions!$A:$A,0)),12%))),IF(D6<IFERROR(INDEX(Instructions!$B:$B,MATCH("Shrinkage Threshold FTE",Instructions!$A:$A,0)),10),IFERROR(INDEX(Instructions!$B:$B,MATCH("Shrinkage Less Than 10 FTEs",Instructions!$A:$A,0)),20%),IFERROR(INDEX(Instructions!$B:$B,MATCH("Shrinkage 10 Or More FTEs",Instructions!$A:$A,0)),12%)))))) | AF6: =IF(E6="","",N6*(1-(IF(IFERROR(INDEX(Instructions!$B:$B,MATCH("Shrinkage Source",Instructions!$A:$A,0)),"Shrinkage Sheet")="Shrinkage Sheet",IFERROR(IF(Shrinkage!D6="-",IF(E6<IFERROR(INDEX(Instructions!$B:$B,MATCH("Shrinkage Threshold FTE",Instructions!$A:$A,0)),10),IFERROR(INDEX(Instructions!$B:$B,MATCH("Shrinkage Less Than 10 FTEs",Instructions!$A:$A,0)),20%),IFERROR(INDEX(Instructions!$B:$B,MATCH("Shrinkage 10 Or More FTEs",Instructions!$A:$A,0)),12%)),Shrinkage!D6),IF(E6<IFERROR(INDEX(Instructions!$B:$B,MATCH("Shrinkage Threshold FTE",Instructions!$A:$A,0)),10),IFERROR(INDEX(Instructions!$B:$B,MATCH("Shrinkage Less Than 10 FTEs",Instructions!$A:$A,0)),20%),IFERROR(INDEX(Instructions!$B:$B,MATCH("Shrinkage 10 Or More FTEs",Instructions!$A:$A,0)),12%))),IF(E6<IFERROR(INDEX(Instructions!$B:$B,MATCH("Shrinkage Threshold FTE",Instructions!$A:$A,0)),10),IFERROR(INDEX(Instructions!$B:$B,MATCH("Shrinkage Less Than 10 FTEs",Instructions!$A:$A,0)),20%),IFERROR(INDEX(Instructions!$B:$B,MATCH("Shrinkage 10 Or More FTEs",Instructions!$A:$A,0)),12%)))))) | AG6: =IF(F6="","",O6*(1-(IF(IFERROR(INDEX(Instructions!$B:$B,MATCH("Shrinkage Source",Instructions!$A:$A,0)),"Shrinkage Sheet")="Shrinkage Sheet",IFERROR(IF(Shrinkage!E6="-",IF(F6<IFERROR(INDEX(Instructions!$B:$B,MATCH("Shrinkage Threshold FTE",Instructions!$A:$A,0)),10),IFERROR(INDEX(Instructions!$B:$B,MATCH("Shrinkage Less Than 10 FTEs",Instructions!$A:$A,0)),20%),IFERROR(INDEX(Instructions!$B:$B,MATCH("Shrinkage 10 Or More FTEs",Instructions!$A:$A,0)),12%)),Shrinkage!E6),IF(F6<IFERROR(INDEX(Instructions!$B:$B,MATCH("Shrinkage Threshold FTE",Instructions!$A:$A,0)),10),IFERROR(INDEX(Instructions!$B:$B,MATCH("Shrinkage Less Than 10 FTEs",Instructions!$A:$A,0)),20%),IFERROR(INDEX(Instructions!$B:$B,MATCH("Shrinkage 10 Or More FTEs",Instructions!$A:$A,0)),12%))),IF(F6<IFERROR(INDEX(Instructions!$B:$B,MATCH("Shrinkage Threshold FTE",Instructions!$A:$A,0)),10),IFERROR(INDEX(Instructions!$B:$B,MATCH("Shrinkage Less Than 10 FTEs",Instructions!$A:$A,0)),20%),IFERROR(INDEX(Instructions!$B:$B,MATCH("Shrinkage 10 Or More FTEs",Instructions!$A:$A,0)),12%)))))) | AH6: =IF(G6="","",P6*(1-(IF(IFERROR(INDEX(Instructions!$B:$B,MATCH("Shrinkage Source",Instructions!$A:$A,0)),"Shrinkage Sheet")="Shrinkage Sheet",IFERROR(IF(Shrinkage!F6="-",IF(G6<IFERROR(INDEX(Instructions!$B:$B,MATCH("Shrinkage Threshold FTE",Instructions!$A:$A,0)),10),IFERROR(INDEX(Instructions!$B:$B,MATCH("Shrinkage Less Than 10 FTEs",Instructions!$A:$A,0)),20%),IFERROR(INDEX(Instructions!$B:$B,MATCH("Shrinkage 10 Or More FTEs",Instructions!$A:$A,0)),12%)),Shrinkage!F6),IF(G6<IFERROR(INDEX(Instructions!$B:$B,MATCH("Shrinkage Threshold FTE",Instructions!$A:$A,0)),10),IFERROR(INDEX(Instructions!$B:$B,MATCH("Shrinkage Less Than 10 FTEs",Instructions!$A:$A,0)),20%),IFERROR(INDEX(Instructions!$B:$B,MATCH("Shrinkage 10 Or More FTEs",Instructions!$A:$A,0)),12%))),IF(G6<IFERROR(INDEX(Instructions!$B:$B,MATCH("Shrinkage Threshold FTE",Instructions!$A:$A,0)),10),IFERROR(INDEX(Instructions!$B:$B,MATCH("Shrinkage Less Than 10 FTEs",Instructions!$A:$A,0)),20%),IFERROR(INDEX(Instructions!$B:$B,MATCH("Shrinkage 10 Or More FTEs",Instructions!$A:$A,0)),12%)))))) | AI6: =IF(H6="","",Q6*(1-(IF(IFERROR(INDEX(Instructions!$B:$B,MATCH("Shrinkage Source",Instructions!$A:$A,0)),"Shrinkage Sheet")="Shrinkage Sheet",IFERROR(IF(Shrinkage!G6="-",IF(H6<IFERROR(INDEX(Instructions!$B:$B,MATCH("Shrinkage Threshold FTE",Instructions!$A:$A,0)),10),IFERROR(INDEX(Instructions!$B:$B,MATCH("Shrinkage Less Than 10 FTEs",Instructions!$A:$A,0)),20%),IFERROR(INDEX(Instructions!$B:$B,MATCH("Shrinkage 10 Or More FTEs",Instructions!$A:$A,0)),12%)),Shrinkage!G6),IF(H6<IFERROR(INDEX(Instructions!$B:$B,MATCH("Shrinkage Threshold FTE",Instructions!$A:$A,0)),10),IFERROR(INDEX(Instructions!$B:$B,MATCH("Shrinkage Less Than 10 FTEs",Instructions!$A:$A,0)),20%),IFERROR(INDEX(Instructions!$B:$B,MATCH("Shrinkage 10 Or More FTEs",Instructions!$A:$A,0)),12%))),IF(H6<IFERROR(INDEX(Instructions!$B:$B,MATCH("Shrinkage Threshold FTE",Instructions!$A:$A,0)),10),IFERROR(INDEX(Instructions!$B:$B,MATCH("Shrinkage Less Than 10 FTEs",Instructions!$A:$A,0)),20%),IFERROR(INDEX(Instructions!$B:$B,MATCH("Shrinkage 10 Or More FTEs",Instructions!$A:$A,0)),12%)))))) | AJ6: =IF(I6="","",R6*(1-(IF(IFERROR(INDEX(Instructions!$B:$B,MATCH("Shrinkage Source",Instructions!$A:$A,0)),"Shrinkage Sheet")="Shrinkage Sheet",IFERROR(IF(Shrinkage!H6="-",IF(I6<IFERROR(INDEX(Instructions!$B:$B,MATCH("Shrinkage Threshold FTE",Instructions!$A:$A,0)),10),IFERROR(INDEX(Instructions!$B:$B,MATCH("Shrinkage Less Than 10 FTEs",Instructions!$A:$A,0)),20%),IFERROR(INDEX(Instructions!$B:$B,MATCH("Shrinkage 10 Or More FTEs",Instructions!$A:$A,0)),12%)),Shrinkage!H6),IF(I6<IFERROR(INDEX(Instructions!$B:$B,MATCH("Shrinkage Threshold FTE",Instructions!$A:$A,0)),10),IFERROR(INDEX(Instructions!$B:$B,MATCH("Shrinkage Less Than 10 FTEs",Instructions!$A:$A,0)),20%),IFERROR(INDEX(Instructions!$B:$B,MATCH("Shrinkage 10 Or More FTEs",Instructions!$A:$A,0)),12%))),IF(I6<IFERROR(INDEX(Instructions!$B:$B,MATCH("Shrinkage Threshold FTE",Instructions!$A:$A,0)),10),IFERROR(INDEX(Instructions!$B:$B,MATCH("Shrinkage Less Than 10 FTEs",Instructions!$A:$A,0)),20%),IFERROR(INDEX(Instructions!$B:$B,MATCH("Shrinkage 10 Or More FTEs",Instructions!$A:$A,0)),12%)))))) | AU6: 02:00 | AV6: =IFERROR(AD6/C6,"") | AW6: =IFERROR(AE6/D6,"") | AX6: =IFERROR(AF6/E6,"") | AY6: =IFERROR(AG6/F6,"") | AZ6: =IFERROR(AH6/G6,"") | BA6: =IFERROR(AI6/H6,"") | BB6: =IFERROR(AJ6/I6,"") | BD6: 02:00 | BE6: =IF(C6="","",IF(AV6>=Instructions!$B$15,1,0)) | BF6: =IF(D6="","",IF(AW6>=Instructions!$B$15,1,0)) | BG6: =IF(E6="","",IF(AX6>=Instructions!$B$15,1,0)) | BH6: =IF(F6="","",IF(AY6>=Instructions!$B$15,1,0)) | BI6: =IF(G6="","",IF(AZ6>=Instructions!$B$15,1,0)) | BJ6: =IF(H6="","",IF(BA6>=Instructions!$B$15,1,0)) | BK6: =IF(I6="","",IF(BB6>=Instructions!$B$15,1,0)) | BM6: 02:00 | BN6: =IF(C6="","",IF(AV6>=Instructions!$B$16,1,0)) | BO6: =IF(D6="","",IF(AW6>=Instructions!$B$16,1,0)) | BP6: =IF(E6="","",IF(AX6>=Instructions!$B$16,1,0)) | BQ6: =IF(F6="","",IF(AY6>=Instructions!$B$16,1,0)) | BR6: =IF(G6="","",IF(AZ6>=Instructions!$B$16,1,0)) | BS6: =IF(H6="","",IF(BA6>=Instructions!$B$16,1,0)) | BT6: =IF(I6="","",IF(BB6>=Instructions!$B$16,1,0)) | BV6: 02:00 | BW6: =IF(C6="","",IF(ROUND(AV6,6)>=ROUND(Instructions!$B$16-Instructions!$B$17,6),1,0)) | BX6: =IF(D6="","",IF(ROUND(AW6,6)>=ROUND(Instructions!$B$16-Instructions!$B$17,6),1,0)) | BY6: =IF(E6="","",IF(ROUND(AX6,6)>=ROUND(Instructions!$B$16-Instructions!$B$17,6),1,0)) | BZ6: =IF(F6="","",IF(ROUND(AY6,6)>=ROUND(Instructions!$B$16-Instructions!$B$17,6),1,0)) | CA6: =IF(G6="","",IF(ROUND(AZ6,6)>=ROUND(Instructions!$B$16-Instructions!$B$17,6),1,0)) | CB6: =IF(H6="","",IF(ROUND(BA6,6)>=ROUND(Instructions!$B$16-Instructions!$B$17,6),1,0)) | CC6: =IF(I6="","",IF(ROUND(BB6,6)>=ROUND(Instructions!$B$16-Instructions!$B$17,6),1,0)) | CF6: 02:00 | CG6: =IF(C6="","",AD6-C6) | CH6: =IF(D6="","",AE6-D6) | CI6: =IF(E6="","",AF6-E6) | CJ6: =IF(F6="","",AG6-F6) | CK6: =IF(G6="","",AH6-G6) | CL6: =IF(H6="","",AI6-H6) | CM6: =IF(I6="","",AJ6-I6)
B7: 03:00 | K7: 03:00 | L7: =IF(C7="","",COUNTIFS('Scheduler Engine'!$N$2:$N$1751,1,'Scheduler Engine'!$L$2:$L$1751,"<="&((0)*24+VALUE(LEFT($K7,2))),'Scheduler Engine'!$M$2:$M$1751,">"&((0)*24+VALUE(LEFT($K7,2))))+COUNTIFS('Previous Engine'!$K$2:$K$251,1,'Previous Engine'!$H$2:$H$251,"<="&VALUE(LEFT($K7,2)),'Previous Engine'!$I$2:$I$251,">"&VALUE(LEFT($K7,2)))) | M7: =IF(D7="","",COUNTIFS('Scheduler Engine'!$N$2:$N$1751,1,'Scheduler Engine'!$L$2:$L$1751,"<="&((1)*24+VALUE(LEFT($K7,2))),'Scheduler Engine'!$M$2:$M$1751,">"&((1)*24+VALUE(LEFT($K7,2))))) | N7: =IF(E7="","",COUNTIFS('Scheduler Engine'!$N$2:$N$1751,1,'Scheduler Engine'!$L$2:$L$1751,"<="&((2)*24+VALUE(LEFT($K7,2))),'Scheduler Engine'!$M$2:$M$1751,">"&((2)*24+VALUE(LEFT($K7,2))))) | O7: =IF(F7="","",COUNTIFS('Scheduler Engine'!$N$2:$N$1751,1,'Scheduler Engine'!$L$2:$L$1751,"<="&((3)*24+VALUE(LEFT($K7,2))),'Scheduler Engine'!$M$2:$M$1751,">"&((3)*24+VALUE(LEFT($K7,2))))) | P7: =IF(G7="","",COUNTIFS('Scheduler Engine'!$N$2:$N$1751,1,'Scheduler Engine'!$L$2:$L$1751,"<="&((4)*24+VALUE(LEFT($K7,2))),'Scheduler Engine'!$M$2:$M$1751,">"&((4)*24+VALUE(LEFT($K7,2))))) | Q7: =IF(H7="","",COUNTIFS('Scheduler Engine'!$N$2:$N$1751,1,'Scheduler Engine'!$L$2:$L$1751,"<="&((5)*24+VALUE(LEFT($K7,2))),'Scheduler Engine'!$M$2:$M$1751,">"&((5)*24+VALUE(LEFT($K7,2))))) | R7: =IF(I7="","",COUNTIFS('Scheduler Engine'!$N$2:$N$1751,1,'Scheduler Engine'!$L$2:$L$1751,"<="&((6)*24+VALUE(LEFT($K7,2))),'Scheduler Engine'!$M$2:$M$1751,">"&((6)*24+VALUE(LEFT($K7,2))))) | AC7: 03:00 | AD7: =IF(C7="","",L7*(1-(IF(IFERROR(INDEX(Instructions!$B:$B,MATCH("Shrinkage Source",Instructions!$A:$A,0)),"Shrinkage Sheet")="Shrinkage Sheet",IFERROR(IF(Shrinkage!B7="-",IF(C7<IFERROR(INDEX(Instructions!$B:$B,MATCH("Shrinkage Threshold FTE",Instructions!$A:$A,0)),10),IFERROR(INDEX(Instructions!$B:$B,MATCH("Shrinkage Less Than 10 FTEs",Instructions!$A:$A,0)),20%),IFERROR(INDEX(Instructions!$B:$B,MATCH("Shrinkage 10 Or More FTEs",Instructions!$A:$A,0)),12%)),Shrinkage!B7),IF(C7<IFERROR(INDEX(Instructions!$B:$B,MATCH("Shrinkage Threshold FTE",Instructions!$A:$A,0)),10),IFERROR(INDEX(Instructions!$B:$B,MATCH("Shrinkage Less Than 10 FTEs",Instructions!$A:$A,0)),20%),IFERROR(INDEX(Instructions!$B:$B,MATCH("Shrinkage 10 Or More FTEs",Instructions!$A:$A,0)),12%))),IF(C7<IFERROR(INDEX(Instructions!$B:$B,MATCH("Shrinkage Threshold FTE",Instructions!$A:$A,0)),10),IFERROR(INDEX(Instructions!$B:$B,MATCH("Shrinkage Less Than 10 FTEs",Instructions!$A:$A,0)),20%),IFERROR(INDEX(Instructions!$B:$B,MATCH("Shrinkage 10 Or More FTEs",Instructions!$A:$A,0)),12%)))))) | AE7: =IF(D7="","",M7*(1-(IF(IFERROR(INDEX(Instructions!$B:$B,MATCH("Shrinkage Source",Instructions!$A:$A,0)),"Shrinkage Sheet")="Shrinkage Sheet",IFERROR(IF(Shrinkage!C7="-",IF(D7<IFERROR(INDEX(Instructions!$B:$B,MATCH("Shrinkage Threshold FTE",Instructions!$A:$A,0)),10),IFERROR(INDEX(Instructions!$B:$B,MATCH("Shrinkage Less Than 10 FTEs",Instructions!$A:$A,0)),20%),IFERROR(INDEX(Instructions!$B:$B,MATCH("Shrinkage 10 Or More FTEs",Instructions!$A:$A,0)),12%)),Shrinkage!C7),IF(D7<IFERROR(INDEX(Instructions!$B:$B,MATCH("Shrinkage Threshold FTE",Instructions!$A:$A,0)),10),IFERROR(INDEX(Instructions!$B:$B,MATCH("Shrinkage Less Than 10 FTEs",Instructions!$A:$A,0)),20%),IFERROR(INDEX(Instructions!$B:$B,MATCH("Shrinkage 10 Or More FTEs",Instructions!$A:$A,0)),12%))),IF(D7<IFERROR(INDEX(Instructions!$B:$B,MATCH("Shrinkage Threshold FTE",Instructions!$A:$A,0)),10),IFERROR(INDEX(Instructions!$B:$B,MATCH("Shrinkage Less Than 10 FTEs",Instructions!$A:$A,0)),20%),IFERROR(INDEX(Instructions!$B:$B,MATCH("Shrinkage 10 Or More FTEs",Instructions!$A:$A,0)),12%)))))) | AF7: =IF(E7="","",N7*(1-(IF(IFERROR(INDEX(Instructions!$B:$B,MATCH("Shrinkage Source",Instructions!$A:$A,0)),"Shrinkage Sheet")="Shrinkage Sheet",IFERROR(IF(Shrinkage!D7="-",IF(E7<IFERROR(INDEX(Instructions!$B:$B,MATCH("Shrinkage Threshold FTE",Instructions!$A:$A,0)),10),IFERROR(INDEX(Instructions!$B:$B,MATCH("Shrinkage Less Than 10 FTEs",Instructions!$A:$A,0)),20%),IFERROR(INDEX(Instructions!$B:$B,MATCH("Shrinkage 10 Or More FTEs",Instructions!$A:$A,0)),12%)),Shrinkage!D7),IF(E7<IFERROR(INDEX(Instructions!$B:$B,MATCH("Shrinkage Threshold FTE",Instructions!$A:$A,0)),10),IFERROR(INDEX(Instructions!$B:$B,MATCH("Shrinkage Less Than 10 FTEs",Instructions!$A:$A,0)),20%),IFERROR(INDEX(Instructions!$B:$B,MATCH("Shrinkage 10 Or More FTEs",Instructions!$A:$A,0)),12%))),IF(E7<IFERROR(INDEX(Instructions!$B:$B,MATCH("Shrinkage Threshold FTE",Instructions!$A:$A,0)),10),IFERROR(INDEX(Instructions!$B:$B,MATCH("Shrinkage Less Than 10 FTEs",Instructions!$A:$A,0)),20%),IFERROR(INDEX(Instructions!$B:$B,MATCH("Shrinkage 10 Or More FTEs",Instructions!$A:$A,0)),12%)))))) | AG7: =IF(F7="","",O7*(1-(IF(IFERROR(INDEX(Instructions!$B:$B,MATCH("Shrinkage Source",Instructions!$A:$A,0)),"Shrinkage Sheet")="Shrinkage Sheet",IFERROR(IF(Shrinkage!E7="-",IF(F7<IFERROR(INDEX(Instructions!$B:$B,MATCH("Shrinkage Threshold FTE",Instructions!$A:$A,0)),10),IFERROR(INDEX(Instructions!$B:$B,MATCH("Shrinkage Less Than 10 FTEs",Instructions!$A:$A,0)),20%),IFERROR(INDEX(Instructions!$B:$B,MATCH("Shrinkage 10 Or More FTEs",Instructions!$A:$A,0)),12%)),Shrinkage!E7),IF(F7<IFERROR(INDEX(Instructions!$B:$B,MATCH("Shrinkage Threshold FTE",Instructions!$A:$A,0)),10),IFERROR(INDEX(Instructions!$B:$B,MATCH("Shrinkage Less Than 10 FTEs",Instructions!$A:$A,0)),20%),IFERROR(INDEX(Instructions!$B:$B,MATCH("Shrinkage 10 Or More FTEs",Instructions!$A:$A,0)),12%))),IF(F7<IFERROR(INDEX(Instructions!$B:$B,MATCH("Shrinkage Threshold FTE",Instructions!$A:$A,0)),10),IFERROR(INDEX(Instructions!$B:$B,MATCH("Shrinkage Less Than 10 FTEs",Instructions!$A:$A,0)),20%),IFERROR(INDEX(Instructions!$B:$B,MATCH("Shrinkage 10 Or More FTEs",Instructions!$A:$A,0)),12%)))))) | AH7: =IF(G7="","",P7*(1-(IF(IFERROR(INDEX(Instructions!$B:$B,MATCH("Shrinkage Source",Instructions!$A:$A,0)),"Shrinkage Sheet")="Shrinkage Sheet",IFERROR(IF(Shrinkage!F7="-",IF(G7<IFERROR(INDEX(Instructions!$B:$B,MATCH("Shrinkage Threshold FTE",Instructions!$A:$A,0)),10),IFERROR(INDEX(Instructions!$B:$B,MATCH("Shrinkage Less Than 10 FTEs",Instructions!$A:$A,0)),20%),IFERROR(INDEX(Instructions!$B:$B,MATCH("Shrinkage 10 Or More FTEs",Instructions!$A:$A,0)),12%)),Shrinkage!F7),IF(G7<IFERROR(INDEX(Instructions!$B:$B,MATCH("Shrinkage Threshold FTE",Instructions!$A:$A,0)),10),IFERROR(INDEX(Instructions!$B:$B,MATCH("Shrinkage Less Than 10 FTEs",Instructions!$A:$A,0)),20%),IFERROR(INDEX(Instructions!$B:$B,MATCH("Shrinkage 10 Or More FTEs",Instructions!$A:$A,0)),12%))),IF(G7<IFERROR(INDEX(Instructions!$B:$B,MATCH("Shrinkage Threshold FTE",Instructions!$A:$A,0)),10),IFERROR(INDEX(Instructions!$B:$B,MATCH("Shrinkage Less Than 10 FTEs",Instructions!$A:$A,0)),20%),IFERROR(INDEX(Instructions!$B:$B,MATCH("Shrinkage 10 Or More FTEs",Instructions!$A:$A,0)),12%)))))) | AI7: =IF(H7="","",Q7*(1-(IF(IFERROR(INDEX(Instructions!$B:$B,MATCH("Shrinkage Source",Instructions!$A:$A,0)),"Shrinkage Sheet")="Shrinkage Sheet",IFERROR(IF(Shrinkage!G7="-",IF(H7<IFERROR(INDEX(Instructions!$B:$B,MATCH("Shrinkage Threshold FTE",Instructions!$A:$A,0)),10),IFERROR(INDEX(Instructions!$B:$B,MATCH("Shrinkage Less Than 10 FTEs",Instructions!$A:$A,0)),20%),IFERROR(INDEX(Instructions!$B:$B,MATCH("Shrinkage 10 Or More FTEs",Instructions!$A:$A,0)),12%)),Shrinkage!G7),IF(H7<IFERROR(INDEX(Instructions!$B:$B,MATCH("Shrinkage Threshold FTE",Instructions!$A:$A,0)),10),IFERROR(INDEX(Instructions!$B:$B,MATCH("Shrinkage Less Than 10 FTEs",Instructions!$A:$A,0)),20%),IFERROR(INDEX(Instructions!$B:$B,MATCH("Shrinkage 10 Or More FTEs",Instructions!$A:$A,0)),12%))),IF(H7<IFERROR(INDEX(Instructions!$B:$B,MATCH("Shrinkage Threshold FTE",Instructions!$A:$A,0)),10),IFERROR(INDEX(Instructions!$B:$B,MATCH("Shrinkage Less Than 10 FTEs",Instructions!$A:$A,0)),20%),IFERROR(INDEX(Instructions!$B:$B,MATCH("Shrinkage 10 Or More FTEs",Instructions!$A:$A,0)),12%)))))) | AJ7: =IF(I7="","",R7*(1-(IF(IFERROR(INDEX(Instructions!$B:$B,MATCH("Shrinkage Source",Instructions!$A:$A,0)),"Shrinkage Sheet")="Shrinkage Sheet",IFERROR(IF(Shrinkage!H7="-",IF(I7<IFERROR(INDEX(Instructions!$B:$B,MATCH("Shrinkage Threshold FTE",Instructions!$A:$A,0)),10),IFERROR(INDEX(Instructions!$B:$B,MATCH("Shrinkage Less Than 10 FTEs",Instructions!$A:$A,0)),20%),IFERROR(INDEX(Instructions!$B:$B,MATCH("Shrinkage 10 Or More FTEs",Instructions!$A:$A,0)),12%)),Shrinkage!H7),IF(I7<IFERROR(INDEX(Instructions!$B:$B,MATCH("Shrinkage Threshold FTE",Instructions!$A:$A,0)),10),IFERROR(INDEX(Instructions!$B:$B,MATCH("Shrinkage Less Than 10 FTEs",Instructions!$A:$A,0)),20%),IFERROR(INDEX(Instructions!$B:$B,MATCH("Shrinkage 10 Or More FTEs",Instructions!$A:$A,0)),12%))),IF(I7<IFERROR(INDEX(Instructions!$B:$B,MATCH("Shrinkage Threshold FTE",Instructions!$A:$A,0)),10),IFERROR(INDEX(Instructions!$B:$B,MATCH("Shrinkage Less Than 10 FTEs",Instructions!$A:$A,0)),20%),IFERROR(INDEX(Instructions!$B:$B,MATCH("Shrinkage 10 Or More FTEs",Instructions!$A:$A,0)),12%)))))) | AU7: 03:00 | AV7: =IFERROR(AD7/C7,"") | AW7: =IFERROR(AE7/D7,"") | AX7: =IFERROR(AF7/E7,"") | AY7: =IFERROR(AG7/F7,"") | AZ7: =IFERROR(AH7/G7,"") | BA7: =IFERROR(AI7/H7,"") | BB7: =IFERROR(AJ7/I7,"") | BD7: 03:00 | BE7: =IF(C7="","",IF(AV7>=Instructions!$B$15,1,0)) | BF7: =IF(D7="","",IF(AW7>=Instructions!$B$15,1,0)) | BG7: =IF(E7="","",IF(AX7>=Instructions!$B$15,1,0)) | BH7: =IF(F7="","",IF(AY7>=Instructions!$B$15,1,0)) | BI7: =IF(G7="","",IF(AZ7>=Instructions!$B$15,1,0)) | BJ7: =IF(H7="","",IF(BA7>=Instructions!$B$15,1,0)) | BK7: =IF(I7="","",IF(BB7>=Instructions!$B$15,1,0)) | BM7: 03:00 | BN7: =IF(C7="","",IF(AV7>=Instructions!$B$16,1,0)) | BO7: =IF(D7="","",IF(AW7>=Instructions!$B$16,1,0)) | BP7: =IF(E7="","",IF(AX7>=Instructions!$B$16,1,0)) | BQ7: =IF(F7="","",IF(AY7>=Instructions!$B$16,1,0)) | BR7: =IF(G7="","",IF(AZ7>=Instructions!$B$16,1,0)) | BS7: =IF(H7="","",IF(BA7>=Instructions!$B$16,1,0)) | BT7: =IF(I7="","",IF(BB7>=Instructions!$B$16,1,0)) | BV7: 03:00 | BW7: =IF(C7="","",IF(ROUND(AV7,6)>=ROUND(Instructions!$B$16-Instructions!$B$17,6),1,0)) | BX7: =IF(D7="","",IF(ROUND(AW7,6)>=ROUND(Instructions!$B$16-Instructions!$B$17,6),1,0)) | BY7: =IF(E7="","",IF(ROUND(AX7,6)>=ROUND(Instructions!$B$16-Instructions!$B$17,6),1,0)) | BZ7: =IF(F7="","",IF(ROUND(AY7,6)>=ROUND(Instructions!$B$16-Instructions!$B$17,6),1,0)) | CA7: =IF(G7="","",IF(ROUND(AZ7,6)>=ROUND(Instructions!$B$16-Instructions!$B$17,6),1,0)) | CB7: =IF(H7="","",IF(ROUND(BA7,6)>=ROUND(Instructions!$B$16-Instructions!$B$17,6),1,0)) | CC7: =IF(I7="","",IF(ROUND(BB7,6)>=ROUND(Instructions!$B$16-Instructions!$B$17,6),1,0)) | CF7: 03:00 | CG7: =IF(C7="","",AD7-C7) | CH7: =IF(D7="","",AE7-D7) | CI7: =IF(E7="","",AF7-E7) | CJ7: =IF(F7="","",AG7-F7) | CK7: =IF(G7="","",AH7-G7) | CL7: =IF(H7="","",AI7-H7) | CM7: =IF(I7="","",AJ7-I7)
